Workbook

Sheet Start Here
A1: START HERE
A2: Built for Derek Smith, September 2026. Read this page once, then live on 'Dashboard' and 'Deal Log'.
A4: COLOUR CODE — the same convention professional financial models use
B5: BLUE text | C5: A hardcoded input. This is yours to change.
B6: YELLOW fill | C6: An assumption you MUST confirm. Either you did not give me the number, or it changes the answer materially.
B7: BLACK text | C7: A formula. Do not type over it.
B8: GREEN text | C8: A link pulling from another sheet.
B9: GREEN fill | C9: A key output.
B10: RED fill | C10: A warning or a number you should not like.
A12: HOW TO USE IT
B13: Once, this week | C13: Go through 'Inputs' top to bottom and fix every YELLOW cell. Until then, treat the outputs as directional, not precise.
B14: Every deal | C14: Add one row to 'Deal Log'. Date, client, loan amount, the company's bps, status. Your commission calculates itself. DELETE THE THREE EXAMPLE ROWS FIRST.
B15: Every commission check | C15: Open 'Allocation Engine', type the gross amount into the blue cell, and follow the waterfall it gives you.
B16: Every month | C16: Update 'Marketing ROI' with spend, leads and closings. Glance at 'Dashboard'.
B17: Every quarter | C17: Re-read 'Goals'. If the GAP row is negative, something has to give - a date, a target, or your closing volume.
B18: The two toggles that change everything | C18: On 'Inputs': 'Is the draw RECOVERABLE?' and 'Tax status'. Flip them and watch the whole workbook move. That is the point of the model.
A20: WHAT I ASSUMED (because it was not in your notes)
B21: Assumption 1 | C21: Auto insurance $165/mo, phone $60/mo, groceries/dining $400/mo, personal $250/mo, car maintenance $90/mo - all placeholders, all yellow on 'Inputs'.
B22: Assumption 2 | C22: Auto loan APR 7.49% - you gave the balance and payment but not the rate. The payoff schedule depends on it.
B23: Assumption 3 | C23: HYSA rate 4.00% and credit limit $5,000 - both unknown, both material (one decides the certificate question, the other your utilization).
B24: Assumption 4 | C24: Health insurance $0 - assumed you are on a parent's plan. You age off at 26, which is roughly a year away. Budget $350-500/mo from then.
B25: Assumption 5 | C25: Gym treated as 24 charges/year (mid-month + month-end), matching how you described it.
B26: Assumption 6 | C26: Ring budget $12,000 and target home price $400,000 - pure placeholders.
B27: Assumption 7 | C27: Federal 12% / Maine 5.5% effective rates - rough. A CPA should confirm before you rely on the quarterly numbers.
B29: Not advice | C29: This is a planning model built from the figures you gave me, not tax, legal or investment advice. Confirm your comp structure with the owner, your tax status with a CPA, and current loan-program guidelines before acting on the housing section.

Sheet Dashboard
A1: COMMAND CENTER — Derek Smith | Baxter Mortgage | NMLS 2810853
A2: ="Model date: "&TEXT(Inputs!C7,"mmmm d, yyyy")&" | Comp structure: "&IF(Inputs!C17="Yes","RECOVERABLE draw","NON-RECOVERABLE draw ("&Inputs!C18&")")&" | Tax status: "&Inputs!C20&" | Scenario: "&Inputs!C98
B4: THE FIVE NUMBERS THAT MATTER
B5: Cash in checking today | C5: =Inputs!C51 | E5: Monthly cash burn | F5: ='Monthly Budget'!C32 | H5: Emergency fund target | I5: =Accounts!$C$5
B6: Bills due in the next 7 days | C6: =Inputs!C65+Inputs!C28 | E6: Draw income / month | F6: =Inputs!C23 | H6: Months of runway you have now | I6: =IFERROR((Inputs!C53+Inputs!C51)/'Monthly Budget'!C32,0)
B7: Total saved & invested | C7: =Accounts!AC9 | E7: Gap the draw does NOT cover | F7: ='Monthly Budget'!C34 | H7: Roth at 65 if you start now | I7: =Retirement!G6
B8: Net worth (liquid, less car) | C8: =Accounts!AE9 | E8: Loans/mo to break even | F8: ='Monthly Budget'!C37 | H8: Max home price (draw only) | I8: ='Home Purchase'!D28
B9: Advance balance owed | C9: ='Cash Flow'!$E$4 | E9: Loans/mo to bank $3,000 | F9: =Break-Even!E28 | H9: Annual tax to reserve | I9: ='Tax Reserve'!C18
B11: TOP PRIORITIES RIGHT NOW
B12: 1. Get the comp agreement in writing: recoverable or not, W-2 or 1099. Everything downstream depends on those two answers.
B13: 2. Build the checking cushion to $2,000 before funding anything else. You are at $395.40 with $865.84 due inside a week.
B14: 3. Open the Roth IRA and the separate ring/travel savings account. Both are $0 today because neither exists yet.
B15: 4. Start a mileage log today. At 12,000 miles a year it is worth roughly $8,400 in deductions if you are 1099 - far more than the fuel costs you.
B16: 5. Check your HYSA rate against the certificate's 3.687%. If savings pays more, stop the auto-roll.

Sheet Inputs
A1: CONTROL PANEL — every number in this workbook traces back to this sheet
A2: Edit BLUE cells only. YELLOW = you must confirm this number. Everything else is a formula.
A4: 1. WHO / WHEN (the clock the whole model runs on)
B5: Name | C5: Derek Smith
B6: Current age | C6: 25 | D6: years
B7: MODEL DATE ("today" for every calculation) | C7: 46275 | D7: date | E7: Hardcoded on purpose so results are reproducible. Change it when you refresh the model.
B8: Date you started at Baxter | C8: 46112 | D8: date
B9: Date of your FIRST draw | C9: 46112 | D9: date | E9: Per Derek: first draw landed 3/31/26, the day you started.
B10: Draws received to date | C10: 11 | D10: checks | E10: Confirmed against your 11 actual pay dates (3/31 through 8/28). Next draw: 9/15/26.
A11: 2. COMPENSATION (the two structures you asked me to model)
B12: Draw per pay period | C12: 1231.58 | D12: $ | E12: Your bi-weekly draw.
B13: Draw pay day #1 of each month | C13: 15 | D13: day of mo | E13: Draw #1 is the 15th. Draw #2 is the LAST DAY of the month (handled automatically). Verified against your actual dates: 3/31, 4/15, 4/30, 5/15, 5/29, 6/15, 6/30, 7/16, 7/30, 8/14, 8/28.
B14: Shift a weekend payday back to Friday? | C14: Yes | D14: Yes/No | E14: Your 5/29 and 8/14 draws both moved off a weekend. Payroll also drifts a day either way now and then (7/16, 7/30) - noise, not a rule, so your 11 past dates are entered as actuals in column R of 'Draw Recovery'.
B15: YOUR commission | C15: 0.0075 | D15: of loan amt | E15: 75 bps. Fixed to you regardless of what the company charges.
B16: Company standard fee | C16: 0.0275 | D16: of loan amt | E16: 275 bps standard; drops to 200 or 150 to win a deal. Your 75 bps does not change.
B17: Is the draw RECOVERABLE? | C17: Yes | D17: Yes/No | E17: *** CONFIRM IN WRITING WITH THE OWNER. *** Recoverable = an advance you repay out of commissions. Non-recoverable = yours to keep. This single word is worth $13,547 today.
B18: How commission pays alongside the draw | C18: Recapture | D18: mode | E18: Recapture = commission first repays the draw balance (normal for recoverable). GreaterOf = you get the larger of draw or commission (normal for non-recoverable). Stacked = draw + full commission.
B19: How marketing is funded | C19: Self-funded | D19: mode | E19: Self-funded = out of your pocket. Recoverable = owner advances it, you repay from commissions. CompanyPaid = owner eats it (non-recoverable).
B20: Tax status | C20: 1099 | D20: W-2 / 1099 | E20: *** CONFIRM. *** 1099 = you owe ~30% and every mile/marketing dollar is deductible. W-2 = taxes withheld, almost nothing deductible. Worth thousands either way.
B21: Draws per year | C21: 24 | D21: checks/yr | E21: *** CORRECTED - A REAL FINDING. *** 24 draws/yr, not 26. Your own dates prove it: 3/31, 4/15, 4/30, 5/15, 5/29, 6/15, 6/30, 7/16, 7/30, 8/14, 8/28 = mid-month + month-end = SEMI-MONTHLY. True bi-weekly would have paid 12 checks by today, not 11. Annualized: $29,557.92, NOT $32,021.08. Budgeting on 26 checks overstates your floor by $2,463.16/yr.
B22: Annualized draw (the floor) | C22: =C12*C21 | D22: $/yr
B23: Draw per month (average) | C23: =C22/12 | D23: $/mo | E23: Average. Actual months vary: two months a year carry three checks.
B24: Draw dollars received to date | C24: =C12*C10 | D24: $ | E24: This is the number at risk if the draw is recoverable.
B25: Draws SCHEDULED by the model date | C25: =COUNTIFS('Draw Recovery'!$B$9:$B$116,"<="&C7) | D25: checks | E25: Counted straight off the pay calendar on 'Draw Recovery'.
B26: = Variance vs. your count | C26: =C25-C10 | D26: checks | E26: Reconciles to zero against the 11 actual dates in column R of 'Draw Recovery'. Next draw: 9/15/26.
A27: 3. FIXED MONTHLY OBLIGATIONS (contractual - these hit whether you close a loan or not)
B28: Car payment | C28: 475.69 | D28: $/mo
B29: ...due on day of month | C29: 14 | D29: day
B30: Gym membership (per charge) | C30: 31.99 | D30: $/charge
B31: ...charges per month | C31: 2 | D31: x/mo | E31: Semi-monthly (mid-month + last day) = 24 charges/yr = $767.76. Same cadence as your draw - you use 'bi-weekly' to mean twice a month, which is how this model reads it throughout.
B32: Amazon Prime | C32: 15 | D32: $/mo
B33: ...due on day of month | C33: 1 | D33: day
B34: Marketing spend | C34: 1000 | D34: $/mo | E34: Your target. Tracked against closed loans on 'Marketing ROI'.
B35: Auto insurance | C35: 165 | D35: $/mo | E35: YOU DID NOT LIST THIS. Your lender requires full coverage on a $25k loan, so it exists. Maine average for a 25-yr-old male, full coverage. Replace with your actual premium.
B36: Phone | C36: 60 | D36: $/mo | E36: NOT LISTED. Placeholder - replace with actual (or $0 if on a family plan).
B37: Health insurance | C37: 0 | D37: $/mo | E37: NOT LISTED. $0 only if you are on a parent's plan - you can stay until age 26, which for you ends within ~1 year. Budget $350-500/mo starting then. THIS IS A CLIFF.
B38: Other fixed (subscriptions, etc.) | C38: 0 | D38: $/mo
A39: 4. VARIABLE / DRIVER-BASED SPENDING
B40: Business + personal miles driven | C40: 1000 | D40: mi/mo | E40: Your estimate. Also drives your mileage tax deduction - log them.
B41: Gas price | C41: 4.1 | D41: $/gal
...

Sheet Deal Log
A1: DEAL LOG — log every transaction here. This sheet feeds the entire workbook.
A2: Enter columns A-F, I, J, M, N (blue). Green columns calculate themselves. Your 75 bps is paid on the loan amount regardless of the company's fee.
A3: TOTALS (Funded only): | B3: Funded count -> | C3: =COUNTIFS($I$8:$I$257,"Funded") | D3: =SUMIFS(D8:D257,$I$8:$I$257,"Funded") | G3: =SUMIFS(G8:G257,$I$8:$I$257,"Funded") | H3: =SUMIFS(H8:H257,$I$8:$I$257,"Funded") | J3: Weighted pipeline -> | K3: =SUMIFS(K8:K257,$I$8:$I$257,"Funded")+SUMIFS(K8:K257,$I$8:$I$257,"Locked")+SUMIFS(K8:K257,$I$8:$I$257,"Pre-App")
A5: !! ROWS 8-10 ARE EXAMPLES so you can see the model working end-to-end. DELETE THEM before you trust a single number. !!
A6: Examples still in the file: | D6: =COUNTIFS($C$8:$C$257,"EXAMPLE*")
A7: Date Funded | B7: Client / Deal | C7: Loan Type | D7: Loan Amount | E7: Co. bps | F7: My bps | G7: MY COMMISSION | H7: Company Revenue | I7: Status | J7: Prob. % | K7: Weighted to Me | L7: Month Key | M7: Referral Source | N7: Notes
A8: 46164 | B8: Sample - Hartley purchase | C8: EXAMPLE - Conv 30yr | D8: 312000 | E8: 0.0275 | F8: =IF($A8="","",Inputs!$C$15) | G8: =IF($A8="","",$D8*$F8) | H8: =IF($A8="","",$D8*$E8) | I8: Funded | J8: 1 | K8: =IF($A8="","",$G8*$J8) | L8: =IF($A8="","",EOMONTH($A8,0)) | M8: Realtor - J. Poulin | N8: Delete this row
A9: 46213 | B9: Sample - Nadeau refi | C9: EXAMPLE - FHA Streamline | D9: 244500 | E9: 0.02 | F9: =IF($A9="","",Inputs!$C$15) | G9: =IF($A9="","",$D9*$F9) | H9: =IF($A9="","",$D9*$E9) | I9: Funded | J9: 1 | K9: =IF($A9="","",$G9*$J9) | L9: =IF($A9="","",EOMONTH($A9,0)) | M9: Past client | N9: Rate cut to 200 bps to win it - your 75 bps did not change
A10: 46310 | B10: Sample - Belanger purchase | C10: EXAMPLE - MaineHousing FHL | D10: 288000 | E10: 0.015 | F10: =IF($A10="","",Inputs!$C$15) | G10: =IF($A10="","",$D10*$F10) | H10: =IF($A10="","",$D10*$E10) | I10: Locked | J10: 0.85 | K10: =IF($A10="","",$G10*$J10) | L10: =IF($A10="","",EOMONTH($A10,0)) | M10: Realtor - K. Dube | N10: Delete this row
F11: =IF($A11="","",Inputs!$C$15) | G11: =IF($A11="","",$D11*$F11) | H11: =IF($A11="","",$D11*$E11) | K11: =IF($A11="","",$G11*$J11) | L11: =IF($A11="","",EOMONTH($A11,0))
F12: =IF($A12="","",Inputs!$C$15) | G12: =IF($A12="","",$D12*$F12) | H12: =IF($A12="","",$D12*$E12) | K12: =IF($A12="","",$G12*$J12) | L12: =IF($A12="","",EOMONTH($A12,0))
F13: =IF($A13="","",Inputs!$C$15) | G13: =IF($A13="","",$D13*$F13) | H13: =IF($A13="","",$D13*$E13) | K13: =IF($A13="","",$G13*$J13) | L13: =IF($A13="","",EOMONTH($A13,0))
F14: =IF($A14="","",Inputs!$C$15) | G14: =IF($A14="","",$D14*$F14) | H14: =IF($A14="","",$D14*$E14) | K14: =IF($A14="","",$G14*$J14) | L14: =IF($A14="","",EOMONTH($A14,0))
F15: =IF($A15="","",Inputs!$C$15) | G15: =IF($A15="","",$D15*$F15) | H15: =IF($A15="","",$D15*$E15) | K15: =IF($A15="","",$G15*$J15) | L15: =IF($A15="","",EOMONTH($A15,0))
F16: =IF($A16="","",Inputs!$C$15) | G16: =IF($A16="","",$D16*$F16) | H16: =IF($A16="","",$D16*$E16) | K16: =IF($A16="","",$G16*$J16) | L16: =IF($A16="","",EOMONTH($A16,0))
F17: =IF($A17="","",Inputs!$C$15) | G17: =IF($A17="","",$D17*$F17) | H17: =IF($A17="","",$D17*$E17) | K17: =IF($A17="","",$G17*$J17) | L17: =IF($A17="","",EOMONTH($A17,0))
F18: =IF($A18="","",Inputs!$C$15) | G18: =IF($A18="","",$D18*$F18) | H18: =IF($A18="","",$D18*$E18) | K18: =IF($A18="","",$G18*$J18) | L18: =IF($A18="","",EOMONTH($A18,0))
F19: =IF($A19="","",Inputs!$C$15) | G19: =IF($A19="","",$D19*$F19) | H19: =IF($A19="","",$D19*$E19) | K19: =IF($A19="","",$G19*$J19) | L19: =IF($A19="","",EOMONTH($A19,0))
F20: =IF($A20="","",Inputs!$C$15) | G20: =IF($A20="","",$D20*$F20) | H20: =IF($A20="","",$D20*$E20) | K20: =IF($A20="","",$G20*$J20) | L20: =IF($A20="","",EOMONTH($A20,0))
F21: =IF($A21="","",Inputs!$C$15) | G21: =IF($A21="","",$D21*$F21) | H21: =IF($A21="","",$D21*$E21) | K21: =IF($A21="","",$G21*$J21) | L21: =IF($A21="","",EOMONTH($A21,0))
F22: =IF($A22="","",Inputs!$C$15) | G22: =IF($A22="","",$D22*$F22) | H22: =IF($A22="","",$D22*$E22) | K22: =IF($A22="","",$G22*$J22) | L22: =IF($A22="","",EOMONTH($A22,0))
... F257: =IF($A257="","",Inputs!$C$15) | G257: =IF($A257="","",$D257*$F257) | H257: =IF($A257="","",$D257*$E257) | K257: =IF($A257="","",$G257*$J257) | L257: =IF($A257="","",EOMONTH($A257,0))

Sheet Draw Recovery
A1: DRAW RECOVERY ENGINE — what you actually take home under each comp structure
A2: Every SEMI-MONTHLY pay period (15th + month-end) from your first draw forward. Column R holds your 11 real dates; clear one and the formula takes over. The three NET CASH columns (M, N, O) are the whole point: same deals, three very different outcomes.
A4: Advance balance owed TODAY (recoverable case): | F4: =INDEX($L$9:$L$116,MATCH(Inputs!$C$7,$B$9:$B$116,1)) | G4: <- if the draw is recoverable, this is what you owe the owner before you earn a dollar of your own.
A5: Month you break even (advance hits zero): | F5: =IFERROR(INDEX($B$9:$B$116,MATCH(0,$L$9:$L$116,0)),"Not within 3 yrs") | G5: <- drive this earlier by logging more funded deals, or by getting the draw reclassified as non-recoverable.
A8: # | B8: Pay Date | C8: Month | D8: Draw Advanced | E8: Marketing Advanced | F8: Total Advanced | G8: Cumulative Advanced | H8: Commission Earned | I8: Cumulative Commission | J8: Opening Advance Bal | K8: Recapture Applied | L8: Closing Advance Bal | M8: NET CASH Recoverable | N8: NET CASH Greater-Of | O8: NET CASH Stacked | P8: ACTIVE (per toggle) | Q8: Paid? | R8: ACTUAL date (override)
A9: 1 | B9: =IF(R9="",Inputs!$C$9,R9) | C9: =EOMONTH(B9,0) | D9: =Inputs!$C$12 | E9: =IF(Inputs!$C$19="Recoverable",Inputs!$C$34*12/Inputs!$C$21,0) | F9: =D9+E9 | G9: =F9 | H9: =SUMIFS('Deal Log'!$G$8:$G$257,'Deal Log'!$A$8:$A$257,">"&0,'Deal Log'!$A$8:$A$257,"<="&B9,'Deal Log'!$I$8:$I$257,"Funded") | I9: =H9 | J9: =0 | K9: =MIN(J9+F9,H9) | L9: =MAX(0,J9+F9-H9) | M9: =D9+MAX(0,H9-(J9+F9)) | N9: =MAX(D9,H9) | O9: =D9+H9 | P9: =IF(Inputs!$C$17="Yes",M9,IF(Inputs!$C$18="Stacked",O9,N9)) | Q9: =IF(B9<=Inputs!$C$7,"paid","future") | R9: 46112
A10: 2 | B10: =IF(R10="",IF(DAY(B9)<=20,(EOMONTH(B9,0)-IF(Inputs!$C$14="Yes",MAX(0,WEEKDAY(EOMONTH(B9,0),2)-5),0)),(DATE(YEAR(B9),MONTH(B9)+1,Inputs!$C$13)-IF(Inputs!$C$14="Yes",MAX(0,WEEKDAY(DATE(YEAR(B9),MONTH(B9)+1,Inputs!$C$13),2)-5),0))),R10) | C10: =EOMONTH(B10,0) | D10: =Inputs!$C$12 | E10: =IF(Inputs!$C$19="Recoverable",Inputs!$C$34*12/Inputs!$C$21,0) | F10: =D10+E10 | G10: =G9+F10 | H10: =SUMIFS('Deal Log'!$G$8:$G$257,'Deal Log'!$A$8:$A$257,">"&B9,'Deal Log'!$A$8:$A$257,"<="&B10,'Deal Log'!$I$8:$I$257,"Funded") | I10: =I9+H10 | J10: =L9 | K10: =MIN(J10+F10,H10) | L10: =MAX(0,J10+F10-H10) | M10: =D10+MAX(0,H10-(J10+F10)) | N10: =MAX(D10,H10) | O10: =D10+H10 | P10: =IF(Inputs!$C$17="Yes",M10,IF(Inputs!$C$18="Stacked",O10,N10)) | Q10: =IF(B10<=Inputs!$C$7,"paid","future") | R10: 46127
A11: 3 | B11: =IF(R11="",IF(DAY(B10)<=20,(EOMONTH(B10,0)-IF(Inputs!$C$14="Yes",MAX(0,WEEKDAY(EOMONTH(B10,0),2)-5),0)),(DATE(YEAR(B10),MONTH(B10)+1,Inputs!$C$13)-IF(Inputs!$C$14="Yes",MAX(0,WEEKDAY(DATE(YEAR(B10),MONTH(B10)+1,Inputs!$C$13),2)-5),0))),R11) | C11: =EOMONTH(B11,0) | D11: =Inputs!$C$12 | E11: =IF(Inputs!$C$19="Recoverable",Inputs!$C$34*12/Inputs!$C$21,0) | F11: =D11+E11 | G11: =G10+F11 | H11: =SUMIFS('Deal Log'!$G$8:$G$257,'Deal Log'!$A$8:$A$257,">"&B10,'Deal Log'!$A$8:$A$257,"<="&B11,'Deal Log'!$I$8:$I$257,"Funded") | I11: =I10+H11 | J11: =L10 | K11: =MIN(J11+F11,H11) | L11: =MAX(0,J11+F11-H11) | M11: =D11+MAX(0,H11-(J11+F11)) | N11: =MAX(D11,H11) | O11: =D11+H11 | P11: =IF(Inputs!$C$17="Yes",M11,IF(Inputs!$C$18="Stacked",O11,N11)) | Q11: =IF(B11<=Inputs!$C$7,"paid","future") | R11: 46142
A12: 4 | B12: =IF(R12="",IF(DAY(B11)<=20,(EOMONTH(B11,0)-IF(Inputs!$C$14="Yes",MAX(0,WEEKDAY(EOMONTH(B11,0),2)-5),0)),(DATE(YEAR(B11),MONTH(B11)+1,Inputs!$C$13)-IF(Inputs!$C$14="Yes",MAX(0,WEEKDAY(DATE(YEAR(B11),MONTH(B11)+1,Inputs!$C$13),2)-5),0))),R12) | C12: =EOMONTH(B12,0) | D12: =Inputs!$C$12 | E12: =IF(Inputs!$C$19="Recoverable",Inputs!$C$34*12/Inputs!$C$21,0) | F12: =D12+E12 | G12: =G11+F12 | H12: =SUMIFS('Deal Log'!$G$8:$G$257,'Deal Log'!$A$8:$A$257,">"&B11,'Deal Log'!$A$8:$A$257,"<="&B12,'Deal Log'!$I$8:$I$257,"Funded") | I12: =I11+H12 | J12: =L11 | K12: =MIN(J12+F12,H12) | L12: =MAX(0,J12+F12-H12) | M12: =D12+MAX(0,H12-(J12+F12)) | N12: =MAX(D12,H12) | O12: =D12+H12 | P12: =IF(Inputs!$C$17="Yes",M12,IF(Inputs!$C$18="Stacked",O12,N12)) | Q12: =IF(B12<=Inputs!$C$7,"paid","future") | R12: 46157
A13: 5 | B13: =IF(R13="",IF(DAY(B12)<=20,(EOMONTH(B12,0)-IF(Inputs!$C$14="Yes",MAX(0,WEEKDAY(EOMONTH(B12,0),2)-5),0)),(DATE(YEAR(B12),MONTH(B12)+1,Inputs!$C$13)-IF(Inputs!$C$14="Yes",MAX(0,WEEKDAY(DATE(YEAR(B12),MONTH(B12)+1,Inputs!$C$13),2)-5),0))),R13) | C13: =EOMONTH(B13,0) | D13: =Inputs!$C$12 | E13: =IF(Inputs!$C$19="Recoverable",Inputs!$C$34*12/Inputs!$C$21,0) | F13: =D13+E13 | G13: =G12+F13 | H13: =SUMIFS('Deal Log'!$G$8:$G$257,'Deal Log'!$A$8:$A$257,">"&B12,'Deal Log'!$A$8:$A$257,"<="&B13,'Deal Log'!$I$8:$I$257,"Funded") | I13: =I12+H13 | J13: =L12 | K13: =MIN(J13+F13,H13) | L13: =MAX(0,J13+F13-H13) | M13: =D13+MAX(0,H13-(J13+F13)) | N13: =MAX(D13,H13) | O13: =D13+H13 | P13: =IF(Inputs!$C$17="Yes",M13,IF(Inputs!$C$18="Stacked",O13,N13)) | Q13: =IF(B13<=Inputs!$C$7,"paid","future") | R13: 46171
A14: 6 | B14: =IF(R14="",IF(DAY(B13)<=20,(EOMONTH(B13,0)-IF(Inputs!$C$14="Yes",MAX(0,WEEKDAY(EOMONTH(B13,0),2)-5),0)),(DATE(YEAR(B13),MONTH(B13)+1,Inputs!$C$13)-IF(Inputs!$C$14="Yes",MAX(0,WEEKDAY(DATE(YEAR(B13),MONTH(B13)+1,Inputs!$C$13),2)-5),0))),R14) | C14: =EOMONTH(B14,0) | D14: =Inputs!$C$12 | E14: =IF(Inputs!$C$19="Recoverable",Inputs!$C$34*12/Inputs!$C$21,0) | F14: =D14+E14 | G14: =G13+F14 | H14: =SUMIFS('Deal Log'!$G$8:$G$257,'Deal Log'!$A$8:$A$257,">"&B13,'Deal Log'!$A$8:$A$257,"<="&B14,'Deal Log'!$I$8:$I$257,"Funded") | I14: =I13+H14 | J14: =L13 | K14: =MIN(J14+F14,H14) | L14: =MAX(0,J14+F14-H14) | M14: =D14+MAX(0,H14-(J14+F14)) | N14: =MAX(D14,H14) | O14: =D14+H14 | P14: =IF(Inputs!$C$17="Yes",M14,IF(Inputs!$C$18="Stacked",O14,N14)) | Q14: =IF(B14<=Inputs!$C$7,"paid","future") | R14: 46188
A15: 7 | B15: =IF(R15="",IF(DAY(B14)<=20,(EOMONTH(B14,0)-IF(Inputs!$C$14="Yes",MAX(0,WEEKDAY(EOMONTH(B14,0),2)-5),0)),(DATE(YEAR(B14),MONTH(B14)+1,Inputs!$C$13)-IF(Inputs!$C$14="Yes",MAX(0,WEEKDAY(DATE(YEAR(B14),MONTH(B14)+1,Inputs!$C$13),2)-5),0))),R15) | C15: =EOMONTH(B15,0) | D15: =Inputs!$C$12 | E15: =IF(Inputs!$C$19="Recoverable",Inputs!$C$34*12/Inputs!$C$21,0) | F15: =D15+E15 | G15: =G14+F15 | H15: =SUMIFS('Deal Log'!$G$8:$G$257,'Deal Log'!$A$8:$A$257,">"&B14,'Deal Log'!$A$8:$A$257,"<="&B15,'Deal Log'!$I$8:$I$257,"Funded") | I15: =I14+H15 | J15: =L14 | K15: =MIN(J15+F15,H15) | L15: =MAX(0,J15+F15-H15) | M15: =D15+MAX(0,H15-(J15+F15)) | N15: =MAX(D15,H15) | O15: =D15+H15 | P15: =IF(Inputs!$C$17="Yes",M15,IF(Inputs!$C$18="Stacked",O15,N15)) | Q15: =IF(B15<=Inputs!$C$7,"paid","future") | R15: 46203
A16: 8 | B16: =IF(R16="",IF(DAY(B15)<=20,(EOMONTH(B15,0)-IF(Inputs!$C$14="Yes",MAX(0,WEEKDAY(EOMONTH(B15,0),2)-5),0)),(DATE(YEAR(B15),MONTH(B15)+1,Inputs!$C$13)-IF(Inputs!$C$14="Yes",MAX(0,WEEKDAY(DATE(YEAR(B15),MONTH(B15)+1,Inputs!$C$13),2)-5),0))),R16) | C16: =EOMONTH(B16,0) | D16: =Inputs!$C$12 | E16: =IF(Inputs!$C$19="Recoverable",Inputs!$C$34*12/Inputs!$C$21,0) | F16: =D16+E16 | G16: =G15+F16 | H16: =SUMIFS('Deal Log'!$G$8:$G$257,'Deal Log'!$A$8:$A$257,">"&B15,'Deal Log'!$A$8:$A$257,"<="&B16,'Deal Log'!$I$8:$I$257,"Funded") | I16: =I15+H16 | J16: =L15 | K16: =MIN(J16+F16,H16) | L16: =MAX(0,J16+F16-H16) | M16: =D16+MAX(0,H16-(J16+F16)) | N16: =MAX(D16,H16) | O16: =D16+H16 | P16: =IF(Inputs!$C$17="Yes",M16,IF(Inputs!$C$18="Stacked",O16,N16)) | Q16: =IF(B16<=Inputs!$C$7,"paid","future") | R16: 46219
A17: 9 | B17: =IF(R17="",IF(DAY(B16)<=20,(EOMONTH(B16,0)-IF(Inputs!$C$14="Yes",MAX(0,WEEKDAY(EOMONTH(B16,0),2)-5),0)),(DATE(YEAR(B16),MONTH(B16)+1,Inputs!$C$13)-IF(Inputs!$C$14="Yes",MAX(0,WEEKDAY(DATE(YEAR(B16),MONTH(B16)+1,Inputs!$C$13),2)-5),0))),R17) | C17: =EOMONTH(B17,0) | D17: =Inputs!$C$12 | E17: =IF(Inputs!$C$19="Recoverable",Inputs!$C$34*12/Inputs!$C$21,0) | F17: =D17+E17 | G17: =G16+F17 | H17: =SUMIFS('Deal Log'!$G$8:$G$257,'Deal Log'!$A$8:$A$257,">"&B16,'Deal Log'!$A$8:$A$257,"<="&B17,'Deal Log'!$I$8:$I$257,"Funded") | I17: =I16+H17 | J17: =L16 | K17: =MIN(J17+F17,H17) | L17: =MAX(0,J17+F17-H17) | M17: =D17+MAX(0,H17-(J17+F17)) | N17: =MAX(D17,H17) | O17: =D17+H17 | P17: =IF(Inputs!$C$17="Yes",M17,IF(Inputs!$C$18="Stacked",O17,N17)) | Q17: =IF(B17<=Inputs!$C$7,"paid","future") | R17: 46233
A18: 10 | B18: =IF(R18="",IF(DAY(B17)<=20,(EOMONTH(B17,0)-IF(Inputs!$C$14="Yes",MAX(0,WEEKDAY(EOMONTH(B17,0),2)-5),0)),(DATE(YEAR(B17),MONTH(B17)+1,Inputs!$C$13)-IF(Inputs!$C$14="Yes",MAX(0,WEEKDAY(DATE(YEAR(B17),MONTH(B17)+1,Inputs!$C$13),2)-5),0))),R18) | C18: =EOMONTH(B18,0) | D18: =Inputs!$C$12 | E18: =IF(Inputs!$C$19="Recoverable",Inputs!$C$34*12/Inputs!$C$21,0) | F18: =D18+E18 | G18: =G17+F18 | H18: =SUMIFS('Deal Log'!$G$8:$G$257,'Deal Log'!$A$8:$A$257,">"&B17,'Deal Log'!$A$8:$A$257,"<="&B18,'Deal Log'!$I$8:$I$257,"Funded") | I18: =I17+H18 | J18: =L17 | K18: =MIN(J18+F18,H18) | L18: =MAX(0,J18+F18-H18) | M18: =D18+MAX(0,H18-(J18+F18)) | N18: =MAX(D18,H18) | O18: =D18+H18 | P18: =IF(Inputs!$C$17="Yes",M18,IF(Inputs!$C$18="Stacked",O18,N18)) | Q18: =IF(B18<=Inputs!$C$7,"paid","future") | R18: 46248
A19: 11 | B19: =IF(R19="",IF(DAY(B18)<=20,(EOMONTH(B18,0)-IF(Inputs!$C$14="Yes",MAX(0,WEEKDAY(EOMONTH(B18,0),2)-5),0)),(DATE(YEAR(B18),MONTH(B18)+1,Inputs!$C$13)-IF(Inputs!$C$14="Yes",MAX(0,WEEKDAY(DATE(YEAR(B18),MONTH(B18)+1,Inputs!$C$13),2)-5),0))),R19) | C19: =EOMONTH(B19,0) | D19: =Inputs!$C$12 | E19: =IF(Inputs!$C$19="Recoverable",Inputs!$C$34*12/Inputs!$C$21,0) | F19: =D19+E19 | G19: =G18+F19 | H19: =SUMIFS('Deal Log'!$G$8:$G$257,'Deal Log'!$A$8:$A$257,">"&B18,'Deal Log'!$A$8:$A$257,"<="&B19,'Deal Log'!$I$8:$I$257,"Funded") | I19: =I18+H19 | J19: =L18 | K19: =MIN(J19+F19,H19) | L19: =MAX(0,J19+F19-H19) | M19: =D19+MAX(0,H19-(J19+F19)) | N19: =MAX(D19,H19) | O19: =D19+H19 | P19: =IF(Inputs!$C$17="Yes",M19,IF(Inputs!$C$18="Stacked",O19,N19)) | Q19: =IF(B19<=Inputs!$C$7,"paid","future") | R19: 46262
A20: 12 | B20: =IF(R20="",IF(DAY(B19)<=20,(EOMONTH(B19,0)-IF(Inputs!$C$14="Yes",MAX(0,WEEKDAY(EOMONTH(B19,0),2)-5),0)),(DATE(YEAR(B19),MONTH(B19)+1,Inputs!$C$13)-IF(Inputs!$C$14="Yes",MAX(0,WEEKDAY(DATE(YEAR(B19),MONTH(B19)+1,Inputs!$C$13),2)-5),0))),R20) | C20: =EOMONTH(B20,0) | D20: =Inputs!$C$12 | E20: =IF(Inputs!$C$19="Recoverable",Inputs!$C$34*12/Inputs!$C$21,0) | F20: =D20+E20 | G20: =G19+F20 | H20: =SUMIFS('Deal Log'!$G$8:$G$257,'Deal Log'!$A$8:$A$257,">"&B19,'Deal Log'!$A$8:$A$257,"<="&B20,'Deal Log'!$I$8:$I$257,"Funded") | I20: =I19+H20 | J20: =L19 | K20: =MIN(J20+F20,H20) | L20: =MAX(0,J20+F20-H20) | M20: =D20+MAX(0,H20-(J20+F20)) | N20: =MAX(D20,H20) | O20: =D20+H20 | P20: =IF(Inputs!$C$17="Yes",M20,IF(Inputs!$C$18="Stacked",O20,N20)) | Q20: =IF(B20<=Inputs!$C$7,"paid","future")
A21: 13 | B21: =IF(R21="",IF(DAY(B20)<=20,(EOMONTH(B20,0)-IF(Inputs!$C$14="Yes",MAX(0,WEEKDAY(EOMONTH(B20,0),2)-5),0)),(DATE(YEAR(B20),MONTH(B20)+1,Inputs!$C$13)-IF(Inputs!$C$14="Yes",MAX(0,WEEKDAY(DATE(YEAR(B20),MONTH(B20)+1,Inputs!$C$13),2)-5),0))),R21) | C21: =EOMONTH(B21,0) | D21: =Inputs!$C$12 | E21: =IF(Inputs!$C$19="Recoverable",Inputs!$C$34*12/Inputs!$C$21,0) | F21: =D21+E21 | G21: =G20+F21 | H21: =SUMIFS('Deal Log'!$G$8:$G$257,'Deal Log'!$A$8:$A$257,">"&B20,'Deal Log'!$A$8:$A$257,"<="&B21,'Deal Log'!$I$8:$I$257,"Funded") | I21: =I20+H21 | J21: =L20 | K21: =MIN(J21+F21,H21) | L21: =MAX(0,J21+F21-H21) | M21: =D21+MAX(0,H21-(J21+F21)) | N21: =MAX(D21,H21) | O21: =D21+H21 | P21: =IF(Inputs!$C$17="Yes",M21,IF(Inputs!$C$18="Stacked",O21,N21)) | Q21: =IF(B21<=Inputs!$C$7,"paid","future")
A22: 14 | B22: =IF(R22="",IF(DAY(B21)<=20,(EOMONTH(B21,0)-IF(Inputs!$C$14="Yes",MAX(0,WEEKDAY(EOMONTH(B21,0),2)-5),0)),(DATE(YEAR(B21),MONTH(B21)+1,Inputs!$C$13)-IF(Inputs!$C$14="Yes",MAX(0,WEEKDAY(DATE(YEAR(B21),MONTH(B21)+1,Inputs!$C$13),2)-5),0))),R22) | C22: =EOMONTH(B22,0) | D22: =Inputs!$C$12 | E22: =IF(Inputs!$C$19="Recoverable",Inputs!$C$34*12/Inputs!$C$21,0) | F22: =D22+E22 | G22: =G21+F22 | H22: =SUMIFS('Deal Log'!$G$8:$G$257,'Deal Log'!$A$8:$A$257,">"&B21,'Deal Log'!$A$8:$A$257,"<="&B22,'Deal Log'!$I$8:$I$257,"Funded") | I22: =I21+H22 | J22: =L21 | K22: =MIN(J22+F22,H22) | L22: =MAX(0,J22+F22-H22) | M22: =D22+MAX(0,H22-(J22+F22)) | N22: =MAX(D22,H22) | O22: =D22+H22 | P22: =IF(Inputs!$C$17="Yes",M22,IF(Inputs!$C$18="Stacked",O22,N22)) | Q22: =IF(B22<=Inputs!$C$7,"paid","future")
A23: 15 | B23: =IF(R23="",IF(DAY(B22)<=20,(EOMONTH(B22,0)-IF(Inputs!$C$14="Yes",MAX(0,WEEKDAY(EOMONTH(B22,0),2)-5),0)),(DATE(YEAR(B22),MONTH(B22)+1,Inputs!$C$13)-IF(Inputs!$C$14="Yes",MAX(0,WEEKDAY(DATE(YEAR(B22),MONTH(B22)+1,Inputs!$C$13),2)-5),0))),R23) | C23: =EOMONTH(B23,0) | D23: =Inputs!$C$12 | E23: =IF(Inputs!$C$19="Recoverable",Inputs!$C$34*12/Inputs!$C$21,0) | F23: =D23+E23 | G23: =G22+F23 | H23: =SUMIFS('Deal Log'!$G$8:$G$257,'Deal Log'!$A$8:$A$257,">"&B22,'Deal Log'!$A$8:$A$257,"<="&B23,'Deal Log'!$I$8:$I$257,"Funded") | I23: =I22+H23 | J23: =L22 | K23: =MIN(J23+F23,H23) | L23: =MAX(0,J23+F23-H23) | M23: =D23+MAX(0,H23-(J23+F23)) | N23: =MAX(D23,H23) | O23: =D23+H23 | P23: =IF(Inputs!$C$17="Yes",M23,IF(Inputs!$C$18="Stacked",O23,N23)) | Q23: =IF(B23<=Inputs!$C$7,"paid","future")
A24: 16 | B24: =IF(R24="",IF(DAY(B23)<=20,(EOMONTH(B23,0)-IF(Inputs!$C$14="Yes",MAX(0,WEEKDAY(EOMONTH(B23,0),2)-5),0)),(DATE(YEAR(B23),MONTH(B23)+1,Inputs!$C$13)-IF(Inputs!$C$14="Yes",MAX(0,WEEKDAY(DATE(YEAR(B23),MONTH(B23)+1,Inputs!$C$13),2)-5),0))),R24) | C24: =EOMONTH(B24,0) | D24: =Inputs!$C$12 | E24: =IF(Inputs!$C$19="Recoverable",Inputs!$C$34*12/Inputs!$C$21,0) | F24: =D24+E24 | G24: =G23+F24 | H24: =SUMIFS('Deal Log'!$G$8:$G$257,'Deal Log'!$A$8:$A$257,">"&B23,'Deal Log'!$A$8:$A$257,"<="&B24,'Deal Log'!$I$8:$I$257,"Funded") | I24: =I23+H24 | J24: =L23 | K24: =MIN(J24+F24,H24) | L24: =MAX(0,J24+F24-H24) | M24: =D24+MAX(0,H24-(J24+F24)) | N24: =MAX(D24,H24) | O24: =D24+H24 | P24: =IF(Inputs!$C$17="Yes",M24,IF(Inputs!$C$18="Stacked",O24,N24)) | Q24: =IF(B24<=Inputs!$C$7,"paid","future")
A25: 17 | B25: =IF(R25="",IF(DAY(B24)<=20,(EOMONTH(B24,0)-IF(Inputs!$C$14="Yes",MAX(0,WEEKDAY(EOMONTH(B24,0),2)-5),0)),(DATE(YEAR(B24),MONTH(B24)+1,Inputs!$C$13)-IF(Inputs!$C$14="Yes",MAX(0,WEEKDAY(DATE(YEAR(B24),MONTH(B24)+1,Inputs!$C$13),2)-5),0))),R25) | C25: =EOMONTH(B25,0) | D25: =Inputs!$C$12 | E25: =IF(Inputs!$C$19="Recoverable",Inputs!$C$34*12/Inputs!$C$21,0) | F25: =D25+E25 | G25: =G24+F25 | H25: =SUMIFS('Deal Log'!$G$8:$G$257,'Deal Log'!$A$8:$A$257,">"&B24,'Deal Log'!$A$8:$A$257,"<="&B25,'Deal Log'!$I$8:$I$257,"Funded") | I25: =I24+H25 | J25: =L24 | K25: =MIN(J25+F25,H25) | L25: =MAX(0,J25+F25-H25) | M25: =D25+MAX(0,H25-(J25+F25)) | N25: =MAX(D25,H25) | O25: =D25+H25 | P25: =IF(Inputs!$C$17="Yes",M25,IF(Inputs!$C$18="Stacked",O25,N25)) | Q25: =IF(B25<=Inputs!$C$7,"paid","future")
A26: 18 | B26: =IF(R26="",IF(DAY(B25)<=20,(EOMONTH(B25,0)-IF(Inputs!$C$14="Yes",MAX(0,WEEKDAY(EOMONTH(B25,0),2)-5),0)),(DATE(YEAR(B25),MONTH(B25)+1,Inputs!$C$13)-IF(Inputs!$C$14="Yes",MAX(0,WEEKDAY(DATE(YEAR(B25),MONTH(B25)+1,Inputs!$C$13),2)-5),0))),R26) | C26: =EOMONTH(B26,0) | D26: =Inputs!$C$12 | E26: =IF(Inputs!$C$19="Recoverable",Inputs!$C$34*12/Inputs!$C$21,0) | F26: =D26+E26 | G26: =G25+F26 | H26: =SUMIFS('Deal Log'!$G$8:$G$257,'Deal Log'!$A$8:$A$257,">"&B25,'Deal Log'!$A$8:$A$257,"<="&B26,'Deal Log'!$I$8:$I$257,"Funded") | I26: =I25+H26 | J26: =L25 | K26: =MIN(J26+F26,H26) | L26: =MAX(0,J26+F26-H26) | M26: =D26+MAX(0,H26-(J26+F26)) | N26: =MAX(D26,H26) | O26: =D26+H26 | P26: =IF(Inputs!$C$17="Yes",M26,IF(Inputs!$C$18="Stacked",O26,N26)) | Q26: =IF(B26<=Inputs!$C$7,"paid","future")
A27: 19 | B27: =IF(R27="",IF(DAY(B26)<=20,(EOMONTH(B26,0)-IF(Inputs!$C$14="Yes",MAX(0,WEEKDAY(EOMONTH(B26,0),2)-5),0)),(DATE(YEAR(B26),MONTH(B26)+1,Inputs!$C$13)-IF(Inputs!$C$14="Yes",MAX(0,WEEKDAY(DATE(YEAR(B26),MONTH(B26)+1,Inputs!$C$13),2)-5),0))),R27) | C27: =EOMONTH(B27,0) | D27: =Inputs!$C$12 | E27: =IF(Inputs!$C$19="Recoverable",Inputs!$C$34*12/Inputs!$C$21,0) | F27: =D27+E27 | G27: =G26+F27 | H27: =SUMIFS('Deal Log'!$G$8:$G$257,'Deal Log'!$A$8:$A$257,">"&B26,'Deal Log'!$A$8:$A$257,"<="&B27,'Deal Log'!$I$8:$I$257,"Funded") | I27: =I26+H27 | J27: =L26 | K27: =MIN(J27+F27,H27) | L27: =MAX(0,J27+F27-H27) | M27: =D27+MAX(0,H27-(J27+F27)) | N27: =MAX(D27,H27) | O27: =D27+H27 | P27: =IF(Inputs!$C$17="Yes",M27,IF(Inputs!$C$18="Stacked",O27,N27)) | Q27: =IF(B27<=Inputs!$C$7,"paid","future")
A28: 20 | B28: =IF(R28="",IF(DAY(B27)<=20,(EOMONTH(B27,0)-IF(Inputs!$C$14="Yes",MAX(0,WEEKDAY(EOMONTH(B27,0),2)-5),0)),(DATE(YEAR(B27),MONTH(B27)+1,Inputs!$C$13)-IF(Inputs!$C$14="Yes",MAX(0,WEEKDAY(DATE(YEAR(B27),MONTH(B27)+1,Inputs!$C$13),2)-5),0))),R28) | C28: =EOMONTH(B28,0) | D28: =Inputs!$C$12 | E28: =IF(Inputs!$C$19="Recoverable",Inputs!$C$34*12/Inputs!$C$21,0) | F28: =D28+E28 | G28: =G27+F28 | H28: =SUMIFS('Deal Log'!$G$8:$G$257,'Deal Log'!$A$8:$A$257,">"&B27,'Deal Log'!$A$8:$A$257,"<="&B28,'Deal Log'!$I$8:$I$257,"Funded") | I28: =I27+H28 | J28: =L27 | K28: =MIN(J28+F28,H28) | L28: =MAX(0,J28+F28-H28) | M28: =D28+MAX(0,H28-(J28+F28)) | N28: =MAX(D28,H28) | O28: =D28+H28 | P28: =IF(Inputs!$C$17="Yes",M28,IF(Inputs!$C$18="Stacked",O28,N28)) | Q28: =IF(B28<=Inputs!$C$7,"paid","future")
A29: 21 | B29: =IF(R29="",IF(DAY(B28)<=20,(EOMONTH(B28,0)-IF(Inputs!$C$14="Yes",MAX(0,WEEKDAY(EOMONTH(B28,0),2)-5),0)),(DATE(YEAR(B28),MONTH(B28)+1,Inputs!$C$13)-IF(Inputs!$C$14="Yes",MAX(0,WEEKDAY(DATE(YEAR(B28),MONTH(B28)+1,Inputs!$C$13),2)-5),0))),R29) | C29: =EOMONTH(B29,0) | D29: =Inputs!$C$12 | E29: =IF(Inputs!$C$19="Recoverable",Inputs!$C$34*12/Inputs!$C$21,0) | F29: =D29+E29 | G29: =G28+F29 | H29: =SUMIFS('Deal Log'!$G$8:$G$257,'Deal Log'!$A$8:$A$257,">"&B28,'Deal Log'!$A$8:$A$257,"<="&B29,'Deal Log'!$I$8:$I$257,"Funded") | I29: =I28+H29 | J29: =L28 | K29: =MIN(J29+F29,H29) | L29: =MAX(0,J29+F29-H29) | M29: =D29+MAX(0,H29-(J29+F29)) | N29: =MAX(D29,H29) | O29: =D29+H29 | P29: =IF(Inputs!$C$17="Yes",M29,IF(Inputs!$C$18="Stacked",O29,N29)) | Q29: =IF(B29<=Inputs!$C$7,"paid","future")
A30: 22 | B30: =IF(R30="",IF(DAY(B29)<=20,(EOMONTH(B29,0)-IF(Inputs!$C$14="Yes",MAX(0,WEEKDAY(EOMONTH(B29,0),2)-5),0)),(DATE(YEAR(B29),MONTH(B29)+1,Inputs!$C$13)-IF(Inputs!$C$14="Yes",MAX(0,WEEKDAY(DATE(YEAR(B29),MONTH(B29)+1,Inputs!$C$13),2)-5),0))),R30) | C30: =EOMONTH(B30,0) | D30: =Inputs!$C$12 | E30: =IF(Inputs!$C$19="Recoverable",Inputs!$C$34*12/Inputs!$C$21,0) | F30: =D30+E30 | G30: =G29+F30 | H30: =SUMIFS('Deal Log'!$G$8:$G$257,'Deal Log'!$A$8:$A$257,">"&B29,'Deal Log'!$A$8:$A$257,"<="&B30,'Deal Log'!$I$8:$I$257,"Funded") | I30: =I29+H30 | J30: =L29 | K30: =MIN(J30+F30,H30) | L30: =MAX(0,J30+F30-H30) | M30: =D30+MAX(0,H30-(J30+F30)) | N30: =MAX(D30,H30) | O30: =D30+H30 | P30: =IF(Inputs!$C$17="Yes",M30,IF(Inputs!$C$18="Stacked",O30,N30)) | Q30: =IF(B30<=Inputs!$C$7,"paid","future")
A31: 23 | B31: =IF(R31="",IF(DAY(B30)<=20,(EOMONTH(B30,0)-IF(Inputs!$C$14="Yes",MAX(0,WEEKDAY(EOMONTH(B30,0),2)-5),0)),(DATE(YEAR(B30),MONTH(B30)+1,Inputs!$C$13)-IF(Inputs!$C$14="Yes",MAX(0,WEEKDAY(DATE(YEAR(B30),MONTH(B30)+1,Inputs!$C$13),2)-5),0))),R31) | C31: =EOMONTH(B31,0) | D31: =Inputs!$C$12 | E31: =IF(Inputs!$C$19="Recoverable",Inputs!$C$34*12/Inputs!$C$21,0) | F31: =D31+E31 | G31: =G30+F31 | H31: =SUMIFS('Deal Log'!$G$8:$G$257,'Deal Log'!$A$8:$A$257,">"&B30,'Deal Log'!$A$8:$A$257,"<="&B31,'Deal Log'!$I$8:$I$257,"Funded") | I31: =I30+H31 | J31: =L30 | K31: =MIN(J31+F31,H31) | L31: =MAX(0,J31+F31-H31) | M31: =D31+MAX(0,H31-(J31+F31)) | N31: =MAX(D31,H31) | O31: =D31+H31 | P31: =IF(Inputs!$C$17="Yes",M31,IF(Inputs!$C$18="Stacked",O31,N31)) | Q31: =IF(B31<=Inputs!$C$7,"paid","future")
... A116: 108 | B116: =IF(R116="",IF(DAY(B115)<=20,(EOMONTH(B115,0)-IF(Inputs!$C$14="Yes",MAX(0,WEEKDAY(EOMONTH(B115,0),2)-5),0)),(DATE(YEAR(B115),MONTH(B115)+1,Inputs!$C$13)-IF(Inputs!$C$14="Yes",MAX(0,WEEKDAY(DATE(YEAR(B115),MONTH(B115)+1,Inputs!$C$13),2)-5),0))),R116) | C116: =EOMONTH(B116,0) | D116: =Inputs!$C$12 | E116: =IF(Inputs!$C$19="Recoverable",Inputs!$C$34*12/Inputs!$C$21,0) | F116: =D116+E116 | G116: =G115+F116 | H116: =SUMIFS('Deal Log'!$G$8:$G$257,'Deal Log'!$A$8:$A$257,">"&B115,'Deal Log'!$A$8:$A$257,"<="&B116,'Deal Log'!$I$8:$I$257,"Funded") | I116: =I115+H116 | J116: =L115 | K116: =MIN(J116+F116,H116) | L116: =MAX(0,J116+F116-H116) | M116: =D116+MAX(0,H116-(J116+F116)) | N116: =MAX(D116,H116) | O116: =D116+H116 | P116: =IF(Inputs!$C$17="Yes",M116,IF(Inputs!$C$18="Stacked",O116,N116)) | Q116: =IF(B116<=Inputs!$C$7,"paid","future")
B117: 3-YEAR TOTALS | D117: =SUM(D$9:D$116) | E117: =SUM(E$9:E$116) | F117: =SUM(F$9:F$116) | H117: =SUM(H$9:H$116) | M117: =SUM(M$9:M$116) | N117: =SUM(N$9:N$116) | O117: =SUM(O$9:O$116) | P117: =SUM(P$9:P$116)
B119: Cost of the wrong comp structure over 3 years (Stacked minus Recoverable): | M119: =O117-M117

Sheet Break-Even
A1: BREAK-EVEN & PROFIT — how much do you have to close to actually get paid?
A2: Four comp structures, side by side, on identical costs. Column C is the structure your Inputs toggles are set to.
A5: A. THE COST STACK (per month)
B6: Component | C6: Amount | H6: What it means
B7: Fixed obligations | C7: ='Monthly Budget'!C14 | H7: Pulled straight from 'Monthly Budget'. Change spending there, not here.
B8: Variable / lifestyle | C8: ='Monthly Budget'!C23
B9: Marketing (if self-funded) | C9: ='Monthly Budget'!C27
B10: =CASH BURN before tax | C10: =SUM(C7:C9)
A12: B. BREAK-EVEN VOLUME UNDER EACH COMP STRUCTURE
B13: Metric | C13: ACTIVE (your toggles) | D13: Recoverable draw | E13: Non-recov Greater-Of | F13: Non-recov Stacked | H13: Notes
B14: Draw income counted toward your bills | C14: =IF(Inputs!$C$17="Yes",D14,IF(Inputs!$C$18="Stacked",F14,E14)) | D14: =Inputs!$C$23 | E14: =Inputs!$C$23 | F14: =Inputs!$C$23 | H14: Under every structure you receive the draw in cash each month.
B15: Does commission ADD to the draw? | C15: =IF(Inputs!$C$17="Yes",D15,IF(Inputs!$C$18="Stacked",F15,E15)) | D15: ="No - repays advance first" | E15: ="No - you get the greater" | F15: ="Yes - fully additive" | H15: This single row is why the structures diverge.
B16: Advance balance to clear first | C16: =IF(Inputs!$C$17="Yes",D16,IF(Inputs!$C$18="Stacked",F16,E16)) | D16: =Inputs!$C$24 | E16: =0 | F16: =0 | H16: 11 draws x $1,231.58 already taken. Only the recoverable structure claws this back.
B17: Monthly commission needed to COVER YOUR LIFE | C17: =IF(Inputs!$C$17="Yes",D17,IF(Inputs!$C$18="Stacked",F17,E17)) | D17: =MAX(0,C10-Inputs!$C$23)+Inputs!$C$23 | E17: =MAX(0,C10) | F17: =MAX(0,C10-Inputs!$C$23) | H17: Recoverable is brutal: every commission dollar first repays the draw, so to net your burn you must earn the burn PLUS replace the draw you are repaying.
B18: = LOAN VOLUME needed / month | C18: =IF(Inputs!$C$17="Yes",D18,IF(Inputs!$C$18="Stacked",F18,E18)) | D18: =D17/Inputs!$C$15 | E18: =E17/Inputs!$C$15 | F18: =F17/Inputs!$C$15 | H18: At 75 bps.
B19: = LOANS / month at your average size | C19: =IF(Inputs!$C$17="Yes",D19,IF(Inputs!$C$18="Stacked",F19,E19)) | D19: =IFERROR(D18/Inputs!$C$94,0) | E19: =IFERROR(E18/Inputs!$C$94,0) | F19: =IFERROR(F18/Inputs!$C$94,0) | H19: The number that actually matters day to day.
B20: Volume to CLEAR THE ADVANCE within 12 months | C20: =IF(Inputs!$C$17="Yes",D20,IF(Inputs!$C$18="Stacked",F20,E20)) | D20: =(Inputs!$C$23+Inputs!$C$24/12+IF(Inputs!$C$19="Recoverable",Inputs!$C$34,0))/Inputs!$C$15 | E20: =0 | F20: =0 | H20: Recoverable only: you must out-earn the NEW draw accruing each month AND chip at the $13,547 already owed.
B21: = loans / month to clear it in 12 months | C21: =IF(Inputs!$C$17="Yes",D21,IF(Inputs!$C$18="Stacked",F21,E21)) | D21: =IFERROR(D20/Inputs!$C$94,0) | E21: =0 | F21: =0
A23: C. PROFIT LADDER (non-recoverable / Greater-Of basis - your realistic target structure)
B24: If you want to bank this much per month... | C24: Commission needed | D24: Loan volume needed | E24: Loans/mo needed | F24: Annual volume | H24: Reality check
B25: $0 / mo surplus — Just break even - bills paid, nothing saved | C25: =C10+0 | D25: =C25/Inputs!$C$15 | E25: =IFERROR(D25/Inputs!$C$94,0) | F25: =D25*12 | H25: Read column E. That is your monthly closing target - the only number worth taping to your monitor.
B26: $500 / mo surplus — Bare-minimum saving | C26: =C10+500 | D26: =C26/Inputs!$C$15 | E26: =IFERROR(D26/Inputs!$C$94,0) | F26: =D26*12
B27: $1,500 / mo surplus — Roth IRA maxed + real progress on the ring | C27: =C10+1500 | D27: =C27/Inputs!$C$15 | E27: =IFERROR(D27/Inputs!$C$94,0) | F27: =D27*12
B28: $3,000 / mo surplus — Ring in 2 yrs AND house down payment on track | C28: =C10+3000 | D28: =C28/Inputs!$C$15 | E28: =IFERROR(D28/Inputs!$C$94,0) | F28: =D28*12
B29: $5,000 / mo surplus — Top-producer pace | C29: =C10+5000 | D29: =C29/Inputs!$C$15 | E29: =IFERROR(D29/Inputs!$C$94,0) | F29: =D29*12
A32: D. SENSITIVITY — ANNUAL net cash to you (Greater-Of basis, after tax reserve, after all living costs)
B34: Avg loan size \ Loans per month | C34: 1 | D34: 2 | E34: 3 | F34: 4 | G34: 5
B35: 200000 | C35: =(MAX(Inputs!$C$23,$B35*1*Inputs!$C$15)-IF(Inputs!$C$20="1099",MAX(Inputs!$C$23,$B35*1*Inputs!$C$15)*Inputs!$C$74,0)-$C$10)*12 | D35: =(MAX(Inputs!$C$23,$B35*2*Inputs!$C$15)-IF(Inputs!$C$20="1099",MAX(Inputs!$C$23,$B35*2*Inputs!$C$15)*Inputs!$C$74,0)-$C$10)*12 | E35: =(MAX(Inputs!$C$23,$B35*3*Inputs!$C$15)-IF(Inputs!$C$20="1099",MAX(Inputs!$C$23,$B35*3*Inputs!$C$15)*Inputs!$C$74,0)-$C$10)*12 | F35: =(MAX(Inputs!$C$23,$B35*4*Inputs!$C$15)-IF(Inputs!$C$20="1099",MAX(Inputs!$C$23,$B35*4*Inputs!$C$15)*Inputs!$C$74,0)-$C$10)*12 | G35: =(MAX(Inputs!$C$23,$B35*5*Inputs!$C$15)-IF(Inputs!$C$20="1099",MAX(Inputs!$C$23,$B35*5*Inputs!$C$15)*Inputs!$C$74,0)-$C$10)*12
B36: 250000 | C36: =(MAX(Inputs!$C$23,$B36*1*Inputs!$C$15)-IF(Inputs!$C$20="1099",MAX(Inputs!$C$23,$B36*1*Inputs!$C$15)*Inputs!$C$74,0)-$C$10)*12 | D36: =(MAX(Inputs!$C$23,$B36*2*Inputs!$C$15)-IF(Inputs!$C$20="1099",MAX(Inputs!$C$23,$B36*2*Inputs!$C$15)*Inputs!$C$74,0)-$C$10)*12 | E36: =(MAX(Inputs!$C$23,$B36*3*Inputs!$C$15)-IF(Inputs!$C$20="1099",MAX(Inputs!$C$23,$B36*3*Inputs!$C$15)*Inputs!$C$74,0)-$C$10)*12 | F36: =(MAX(Inputs!$C$23,$B36*4*Inputs!$C$15)-IF(Inputs!$C$20="1099",MAX(Inputs!$C$23,$B36*4*Inputs!$C$15)*Inputs!$C$74,0)-$C$10)*12 | G36: =(MAX(Inputs!$C$23,$B36*5*Inputs!$C$15)-IF(Inputs!$C$20="1099",MAX(Inputs!$C$23,$B36*5*Inputs!$C$15)*Inputs!$C$74,0)-$C$10)*12
B37: 300000 | C37: =(MAX(Inputs!$C$23,$B37*1*Inputs!$C$15)-IF(Inputs!$C$20="1099",MAX(Inputs!$C$23,$B37*1*Inputs!$C$15)*Inputs!$C$74,0)-$C$10)*12 | D37: =(MAX(Inputs!$C$23,$B37*2*Inputs!$C$15)-IF(Inputs!$C$20="1099",MAX(Inputs!$C$23,$B37*2*Inputs!$C$15)*Inputs!$C$74,0)-$C$10)*12 | E37: =(MAX(Inputs!$C$23,$B37*3*Inputs!$C$15)-IF(Inputs!$C$20="1099",MAX(Inputs!$C$23,$B37*3*Inputs!$C$15)*Inputs!$C$74,0)-$C$10)*12 | F37: =(MAX(Inputs!$C$23,$B37*4*Inputs!$C$15)-IF(Inputs!$C$20="1099",MAX(Inputs!$C$23,$B37*4*Inputs!$C$15)*Inputs!$C$74,0)-$C$10)*12 | G37: =(MAX(Inputs!$C$23,$B37*5*Inputs!$C$15)-IF(Inputs!$C$20="1099",MAX(Inputs!$C$23,$B37*5*Inputs!$C$15)*Inputs!$C$74,0)-$C$10)*12
B38: 350000 | C38: =(MAX(Inputs!$C$23,$B38*1*Inputs!$C$15)-IF(Inputs!$C$20="1099",MAX(Inputs!$C$23,$B38*1*Inputs!$C$15)*Inputs!$C$74,0)-$C$10)*12 | D38: =(MAX(Inputs!$C$23,$B38*2*Inputs!$C$15)-IF(Inputs!$C$20="1099",MAX(Inputs!$C$23,$B38*2*Inputs!$C$15)*Inputs!$C$74,0)-$C$10)*12 | E38: =(MAX(Inputs!$C$23,$B38*3*Inputs!$C$15)-IF(Inputs!$C$20="1099",MAX(Inputs!$C$23,$B38*3*Inputs!$C$15)*Inputs!$C$74,0)-$C$10)*12 | F38: =(MAX(Inputs!$C$23,$B38*4*Inputs!$C$15)-IF(Inputs!$C$20="1099",MAX(Inputs!$C$23,$B38*4*Inputs!$C$15)*Inputs!$C$74,0)-$C$10)*12 | G38: =(MAX(Inputs!$C$23,$B38*5*Inputs!$C$15)-IF(Inputs!$C$20="1099",MAX(Inputs!$C$23,$B38*5*Inputs!$C$15)*Inputs!$C$74,0)-$C$10)*12
B39: 400000 | C39: =(MAX(Inputs!$C$23,$B39*1*Inputs!$C$15)-IF(Inputs!$C$20="1099",MAX(Inputs!$C$23,$B39*1*Inputs!$C$15)*Inputs!$C$74,0)-$C$10)*12 | D39: =(MAX(Inputs!$C$23,$B39*2*Inputs!$C$15)-IF(Inputs!$C$20="1099",MAX(Inputs!$C$23,$B39*2*Inputs!$C$15)*Inputs!$C$74,0)-$C$10)*12 | E39: =(MAX(Inputs!$C$23,$B39*3*Inputs!$C$15)-IF(Inputs!$C$20="1099",MAX(Inputs!$C$23,$B39*3*Inputs!$C$15)*Inputs!$C$74,0)-$C$10)*12 | F39: =(MAX(Inputs!$C$23,$B39*4*Inputs!$C$15)-IF(Inputs!$C$20="1099",MAX(Inputs!$C$23,$B39*4*Inputs!$C$15)*Inputs!$C$74,0)-$C$10)*12 | G39: =(MAX(Inputs!$C$23,$B39*5*Inputs!$C$15)-IF(Inputs!$C$20="1099",MAX(Inputs!$C$23,$B39*5*Inputs!$C$15)*Inputs!$C$74,0)-$C$10)*12
B40: 500000 | C40: =(MAX(Inputs!$C$23,$B40*1*Inputs!$C$15)-IF(Inputs!$C$20="1099",MAX(Inputs!$C$23,$B40*1*Inputs!$C$15)*Inputs!$C$74,0)-$C$10)*12 | D40: =(MAX(Inputs!$C$23,$B40*2*Inputs!$C$15)-IF(Inputs!$C$20="1099",MAX(Inputs!$C$23,$B40*2*Inputs!$C$15)*Inputs!$C$74,0)-$C$10)*12 | E40: =(MAX(Inputs!$C$23,$B40*3*Inputs!$C$15)-IF(Inputs!$C$20="1099",MAX(Inputs!$C$23,$B40*3*Inputs!$C$15)*Inputs!$C$74,0)-$C$10)*12 | F40: =(MAX(Inputs!$C$23,$B40*4*Inputs!$C$15)-IF(Inputs!$C$20="1099",MAX(Inputs!$C$23,$B40*4*Inputs!$C$15)*Inputs!$C$74,0)-$C$10)*12 | G40: =(MAX(Inputs!$C$23,$B40*5*Inputs!$C$15)-IF(Inputs!$C$20="1099",MAX(Inputs!$C$23,$B40*5*Inputs!$C$15)*Inputs!$C$74,0)-$C$10)*12
B42: Green = you are building wealth. Red = you are going backwards and living on the draw.

Sheet Monthly Budget
A1: MONTHLY BUDGET — what it costs to be you, every month
A2: Every amount is pulled from Inputs. To change a number, change it there. Yellow rows are costs you did not list and must confirm.
A5: A. FIXED OBLIGATIONS (contractual - they hit whether you close a loan or not)
B6: Line item | C6: Per month | D6: Per year | E6: Due day | F6: Type | G6: Notes
B7: Auto loan payment | C7: =Inputs!$C$28 | D7: =C7*12 | E7: ==Inputs!$C$29 | F7: Fixed | G7: Balance $25,092.02. Amortization and payoff on 'Car Loan'.
B8: Auto insurance | C8: =Inputs!$C$35 | D8: =C8*12 | E8: ="varies" | F8: Fixed | G8: NOT LISTED BY YOU - estimated. Your lienholder requires full coverage, so this bill exists.
B9: Gym membership | C9: =Inputs!$C$30*Inputs!$C$31 | D9: =C9*12 | E9: ="14 & EOM" | F9: Fixed | G9: $31.99 x 2/mo, same cadence as your draw.
B10: Amazon Prime | C10: =Inputs!$C$32 | D10: =C10*12 | E10: ==Inputs!$C$33 | F10: Fixed | G10: Annual plan is ~$139/yr = $11.58/mo. Switching saves $41/yr.
B11: Phone | C11: =Inputs!$C$36 | D11: =C11*12 | E11: ="varies" | F11: Fixed | G11: NOT LISTED - confirm or set to 0 if on a family plan.
B12: Health insurance | C12: =Inputs!$C$37 | D12: =C12*12 | E12: ="varies" | F12: Fixed | G12: NOT LISTED. $0 only while on a parent's plan. You age off at 26 - budget $350-500/mo from then. Plan for it now.
B13: Other fixed | C13: =Inputs!$C$38 | D13: =C13*12 | E13: ="varies" | F13: Fixed | G13: Streaming, storage, anything recurring you have not listed.
B14: TOTAL FIXED | C14: =SUM(C7:C13) | D14: =C14*12
A16: B. VARIABLE / DRIVER-BASED (scale with how hard you work)
B17: Line item | C17: Per month | D17: Per year | E17: Driver | F17: Type | G17: Notes
B18: Fuel | C18: =Inputs!$C$43 | D18: =C18*12 | E18: ="1,000 mi @ 19mpg" | F18: Variable | G18: 1,000 mi/mo at $4.10 and 19 mpg. If 1099, these miles are worth FAR more as a deduction than they cost - see 'Tax Reserve'.
B19: Aroma Joe's | C19: =Inputs!$C$46 | D19: =C19*12 | E19: ="$6 x 4/wk" | F19: Variable | G19: Set your real visit count on Inputs. Every extra visit per week costs $312/yr.
B20: Car maintenance reserve | C20: =Inputs!$C$49 | D20: =C20*12 | E20: ="12k mi/yr" | F20: Variable | G20: NOT LISTED. Maine winter driving: tires, brakes, oil. Set it aside monthly so it is never a surprise.
B21: Groceries / eating out | C21: =Inputs!$C$47 | D21: =C21*12 | E21: ="lifestyle" | F21: Variable | G21: NOT LISTED. You live at home so this may be low - but client lunches and road food are real.
B22: Personal / entertainment | C22: =Inputs!$C$48 | D22: =C22*12 | E22: ="lifestyle" | F22: Variable | G22: NOT LISTED. Placeholder.
B23: TOTAL VARIABLE | C23: =SUM(C18:C22) | D23: =C23*12
A25: C. BUSINESS (only a personal cost if you are self-funding it)
B26: Line item | C26: Per month | D26: Per year | E26: Driver | F26: Type | G26: Notes
B27: Marketing | C27: =IF(Inputs!$C$19="Self-funded",Inputs!$C$34,0) | D27: =C27*12 | E27: =Inputs!$C$19 | F27: Business | G27: $0 here if the owner funds it. If it is a RECOVERABLE advance it is not a monthly bill - it is added to your advance balance on 'Draw Recovery' and repaid from commission.
A29: D. BOTTOM LINE
B30: TOTAL COST OF LIVING (fixed + variable) | C30: =C14+C23 | D30: =C30*12 | G30: This is your personal survival number. It does not include taxes or marketing.
B31: + Marketing (if self-funded) | C31: =C27 | D31: =C31*12
B32: =TOTAL MONTHLY CASH BURN | C32: =C14+C23+C27 | D32: =C32*12 | G32: Every dollar that must leave your accounts in an average month.
B33: Draw income (semi-monthly x 24/yr) | C33: =Inputs!$C$23 | D33: =C33*12 | G33: $1,231.58 x 24 / 12. This is the floor you can count on.
B34: SURPLUS / (SHORTFALL) on the draw alone | C34: =C33-C32 | D34: =C34*12 | G34: If negative, the draw alone does not cover your life and every month without a closing digs a hole.
B35: Commission needed to break even (per month) | C35: =MAX(0,C32-C33) | D35: =C35*12
B36: = loan volume needed | C36: =C35/Inputs!$C$15 | G36: At 75 bps.
B37: = loans per month | C37: =IFERROR(C36/Inputs!$C$94,0) | G37: At your average loan size.

Sheet Cash Flow
A1: 36-MONTH CASH FLOW — Sept 2026 through Aug 2029
A2: Past/current months use your Deal Log. Future months use the ACTIVE SCENARIO on Inputs. Logged pipeline always overrides the forecast for that month.
A4: Opening advance balance owed (recoverable case): | E4: =IF(Inputs!$C$17="Yes",MAX(0,Inputs!$C$24-SUMIFS('Deal Log'!$G$8:$G$257,'Deal Log'!$A$8:$A$257,"<="&Inputs!$C$7,'Deal Log'!$I$8:$I$257,"Funded")),0) | F4: =draws taken to date less commissions already credited. Zero if the draw is non-recoverable.
A5: Active scenario: | C5: =Inputs!$C$98 | D5: =Inputs!$C$99&" loans/mo x $"&TEXT(Inputs!$C$94,"#,##0")&" = "&TEXT(Inputs!$C$101,"$#,##0")&"/mo commission"
A8: Month | B8: Draws in mo | C8: Draw income | D8: Commission (actual/fcst) | E8: Opening advance | F8: Advance added | G8: Recapture | H8: Closing advance | I8: NET CASH INCOME | J8: Tax reserve | K8: After-tax cash in | L8: Fixed costs | M8: Variable costs | N8: Marketing | O8: TOTAL OUT | P8: NET SURPLUS | Q8: CUMULATIVE SURPLUS | R8: Cert auto transfer
A9: =EOMONTH(Inputs!$C$7,0) | B9: =COUNTIFS('Draw Recovery'!$B$9:$B$116,">="&EOMONTH(A9,-1)+1,'Draw Recovery'!$B$9:$B$116,"<="&A9) | C9: =B9*Inputs!$C$12 | D9: =IF(SUMIFS('Deal Log'!$G$8:$G$257,'Deal Log'!$L$8:$L$257,A9,'Deal Log'!$I$8:$I$257,"Funded")+SUMIFS('Deal Log'!$K$8:$K$257,'Deal Log'!$L$8:$L$257,A9,'Deal Log'!$I$8:$I$257,"Locked")+SUMIFS('Deal Log'!$K$8:$K$257,'Deal Log'!$L$8:$L$257,A9,'Deal Log'!$I$8:$I$257,"Pre-App")>0,SUMIFS('Deal Log'!$G$8:$G$257,'Deal Log'!$L$8:$L$257,A9,'Deal Log'!$I$8:$I$257,"Funded")+SUMIFS('Deal Log'!$K$8:$K$257,'Deal Log'!$L$8:$L$257,A9,'Deal Log'!$I$8:$I$257,"Locked")+SUMIFS('Deal Log'!$K$8:$K$257,'Deal Log'!$L$8:$L$257,A9,'Deal Log'!$I$8:$I$257,"Pre-App"),Inputs!$C$101) | E9: =$E$4 | F9: =IF(Inputs!$C$17="Yes",C9,0)+IF(Inputs!$C$19="Recoverable",Inputs!$C$34,0) | G9: =MIN(E9+F9,D9) | H9: =MAX(0,E9+F9-D9) | I9: =IF(Inputs!$C$17="Yes",C9+MAX(0,D9-(E9+F9)),IF(Inputs!$C$18="Stacked",C9+D9,MAX(C9,D9))) | J9: =IF(Inputs!$C$20="1099",I9*Inputs!$C$74,0) | K9: =I9-J9 | L9: ='Monthly Budget'!$C$14 | M9: ='Monthly Budget'!$C$23 | N9: ='Monthly Budget'!$C$27 | O9: =L9+M9+N9 | P9: =K9-O9 | Q9: =P9 | R9: =IF(COUNTIFS('Certificate Ladder'!$B$8:$B$40,">="&EOMONTH(A9,-1)+1,'Certificate Ladder'!$B$8:$B$40,"<="&A9)>0,Inputs!$C$59,0)
A10: =EOMONTH(A9,1) | B10: =COUNTIFS('Draw Recovery'!$B$9:$B$116,">="&EOMONTH(A10,-1)+1,'Draw Recovery'!$B$9:$B$116,"<="&A10) | C10: =B10*Inputs!$C$12 | D10: =IF(SUMIFS('Deal Log'!$G$8:$G$257,'Deal Log'!$L$8:$L$257,A10,'Deal Log'!$I$8:$I$257,"Funded")+SUMIFS('Deal Log'!$K$8:$K$257,'Deal Log'!$L$8:$L$257,A10,'Deal Log'!$I$8:$I$257,"Locked")+SUMIFS('Deal Log'!$K$8:$K$257,'Deal Log'!$L$8:$L$257,A10,'Deal Log'!$I$8:$I$257,"Pre-App")>0,SUMIFS('Deal Log'!$G$8:$G$257,'Deal Log'!$L$8:$L$257,A10,'Deal Log'!$I$8:$I$257,"Funded")+SUMIFS('Deal Log'!$K$8:$K$257,'Deal Log'!$L$8:$L$257,A10,'Deal Log'!$I$8:$I$257,"Locked")+SUMIFS('Deal Log'!$K$8:$K$257,'Deal Log'!$L$8:$L$257,A10,'Deal Log'!$I$8:$I$257,"Pre-App"),Inputs!$C$101) | E10: =H9 | F10: =IF(Inputs!$C$17="Yes",C10,0)+IF(Inputs!$C$19="Recoverable",Inputs!$C$34,0) | G10: =MIN(E10+F10,D10) | H10: =MAX(0,E10+F10-D10) | I10: =IF(Inputs!$C$17="Yes",C10+MAX(0,D10-(E10+F10)),IF(Inputs!$C$18="Stacked",C10+D10,MAX(C10,D10))) | J10: =IF(Inputs!$C$20="1099",I10*Inputs!$C$74,0) | K10: =I10-J10 | L10: ='Monthly Budget'!$C$14 | M10: ='Monthly Budget'!$C$23 | N10: ='Monthly Budget'!$C$27 | O10: =L10+M10+N10 | P10: =K10-O10 | Q10: =Q9+P10 | R10: =IF(COUNTIFS('Certificate Ladder'!$B$8:$B$40,">="&EOMONTH(A10,-1)+1,'Certificate Ladder'!$B$8:$B$40,"<="&A10)>0,Inputs!$C$59,0)
A11: =EOMONTH(A10,1) | B11: =COUNTIFS('Draw Recovery'!$B$9:$B$116,">="&EOMONTH(A11,-1)+1,'Draw Recovery'!$B$9:$B$116,"<="&A11) | C11: =B11*Inputs!$C$12 | D11: =IF(SUMIFS('Deal Log'!$G$8:$G$257,'Deal Log'!$L$8:$L$257,A11,'Deal Log'!$I$8:$I$257,"Funded")+SUMIFS('Deal Log'!$K$8:$K$257,'Deal Log'!$L$8:$L$257,A11,'Deal Log'!$I$8:$I$257,"Locked")+SUMIFS('Deal Log'!$K$8:$K$257,'Deal Log'!$L$8:$L$257,A11,'Deal Log'!$I$8:$I$257,"Pre-App")>0,SUMIFS('Deal Log'!$G$8:$G$257,'Deal Log'!$L$8:$L$257,A11,'Deal Log'!$I$8:$I$257,"Funded")+SUMIFS('Deal Log'!$K$8:$K$257,'Deal Log'!$L$8:$L$257,A11,'Deal Log'!$I$8:$I$257,"Locked")+SUMIFS('Deal Log'!$K$8:$K$257,'Deal Log'!$L$8:$L$257,A11,'Deal Log'!$I$8:$I$257,"Pre-App"),Inputs!$C$101) | E11: =H10 | F11: =IF(Inputs!$C$17="Yes",C11,0)+IF(Inputs!$C$19="Recoverable",Inputs!$C$34,0) | G11: =MIN(E11+F11,D11) | H11: =MAX(0,E11+F11-D11) | I11: =IF(Inputs!$C$17="Yes",C11+MAX(0,D11-(E11+F11)),IF(Inputs!$C$18="Stacked",C11+D11,MAX(C11,D11))) | J11: =IF(Inputs!$C$20="1099",I11*Inputs!$C$74,0) | K11: =I11-J11 | L11: ='Monthly Budget'!$C$14 | M11: ='Monthly Budget'!$C$23 | N11: ='Monthly Budget'!$C$27 | O11: =L11+M11+N11 | P11: =K11-O11 | Q11: =Q10+P11 | R11: =IF(COUNTIFS('Certificate Ladder'!$B$8:$B$40,">="&EOMONTH(A11,-1)+1,'Certificate Ladder'!$B$8:$B$40,"<="&A11)>0,Inputs!$C$59,0)
A12: =EOMONTH(A11,1) | B12: =COUNTIFS('Draw Recovery'!$B$9:$B$116,">="&EOMONTH(A12,-1)+1,'Draw Recovery'!$B$9:$B$116,"<="&A12) | C12: =B12*Inputs!$C$12 | D12: =IF(SUMIFS('Deal Log'!$G$8:$G$257,'Deal Log'!$L$8:$L$257,A12,'Deal Log'!$I$8:$I$257,"Funded")+SUMIFS('Deal Log'!$K$8:$K$257,'Deal Log'!$L$8:$L$257,A12,'Deal Log'!$I$8:$I$257,"Locked")+SUMIFS('Deal Log'!$K$8:$K$257,'Deal Log'!$L$8:$L$257,A12,'Deal Log'!$I$8:$I$257,"Pre-App")>0,SUMIFS('Deal Log'!$G$8:$G$257,'Deal Log'!$L$8:$L$257,A12,'Deal Log'!$I$8:$I$257,"Funded")+SUMIFS('Deal Log'!$K$8:$K$257,'Deal Log'!$L$8:$L$257,A12,'Deal Log'!$I$8:$I$257,"Locked")+SUMIFS('Deal Log'!$K$8:$K$257,'Deal Log'!$L$8:$L$257,A12,'Deal Log'!$I$8:$I$257,"Pre-App"),Inputs!$C$101) | E12: =H11 | F12: =IF(Inputs!$C$17="Yes",C12,0)+IF(Inputs!$C$19="Recoverable",Inputs!$C$34,0) | G12: =MIN(E12+F12,D12) | H12: =MAX(0,E12+F12-D12) | I12: =IF(Inputs!$C$17="Yes",C12+MAX(0,D12-(E12+F12)),IF(Inputs!$C$18="Stacked",C12+D12,MAX(C12,D12))) | J12: =IF(Inputs!$C$20="1099",I12*Inputs!$C$74,0) | K12: =I12-J12 | L12: ='Monthly Budget'!$C$14 | M12: ='Monthly Budget'!$C$23 | N12: ='Monthly Budget'!$C$27 | O12: =L12+M12+N12 | P12: =K12-O12 | Q12: =Q11+P12 | R12: =IF(COUNTIFS('Certificate Ladder'!$B$8:$B$40,">="&EOMONTH(A12,-1)+1,'Certificate Ladder'!$B$8:$B$40,"<="&A12)>0,Inputs!$C$59,0)
A13: =EOMONTH(A12,1) | B13: =COUNTIFS('Draw Recovery'!$B$9:$B$116,">="&EOMONTH(A13,-1)+1,'Draw Recovery'!$B$9:$B$116,"<="&A13) | C13: =B13*Inputs!$C$12 | D13: =IF(SUMIFS('Deal Log'!$G$8:$G$257,'Deal Log'!$L$8:$L$257,A13,'Deal Log'!$I$8:$I$257,"Funded")+SUMIFS('Deal Log'!$K$8:$K$257,'Deal Log'!$L$8:$L$257,A13,'Deal Log'!$I$8:$I$257,"Locked")+SUMIFS('Deal Log'!$K$8:$K$257,'Deal Log'!$L$8:$L$257,A13,'Deal Log'!$I$8:$I$257,"Pre-App")>0,SUMIFS('Deal Log'!$G$8:$G$257,'Deal Log'!$L$8:$L$257,A13,'Deal Log'!$I$8:$I$257,"Funded")+SUMIFS('Deal Log'!$K$8:$K$257,'Deal Log'!$L$8:$L$257,A13,'Deal Log'!$I$8:$I$257,"Locked")+SUMIFS('Deal Log'!$K$8:$K$257,'Deal Log'!$L$8:$L$257,A13,'Deal Log'!$I$8:$I$257,"Pre-App"),Inputs!$C$101) | E13: =H12 | F13: =IF(Inputs!$C$17="Yes",C13,0)+IF(Inputs!$C$19="Recoverable",Inputs!$C$34,0) | G13: =MIN(E13+F13,D13) | H13: =MAX(0,E13+F13-D13) | I13: =IF(Inputs!$C$17="Yes",C13+MAX(0,D13-(E13+F13)),IF(Inputs!$C$18="Stacked",C13+D13,MAX(C13,D13))) | J13: =IF(Inputs!$C$20="1099",I13*Inputs!$C$74,0) | K13: =I13-J13 | L13: ='Monthly Budget'!$C$14 | M13: ='Monthly Budget'!$C$23 | N13: ='Monthly Budget'!$C$27 | O13: =L13+M13+N13 | P13: =K13-O13 | Q13: =Q12+P13 | R13: =IF(COUNTIFS('Certificate Ladder'!$B$8:$B$40,">="&EOMONTH(A13,-1)+1,'Certificate Ladder'!$B$8:$B$40,"<="&A13)>0,Inputs!$C$59,0)
A14: =EOMONTH(A13,1) | B14: =COUNTIFS('Draw Recovery'!$B$9:$B$116,">="&EOMONTH(A14,-1)+1,'Draw Recovery'!$B$9:$B$116,"<="&A14) | C14: =B14*Inputs!$C$12 | D14: =IF(SUMIFS('Deal Log'!$G$8:$G$257,'Deal Log'!$L$8:$L$257,A14,'Deal Log'!$I$8:$I$257,"Funded")+SUMIFS('Deal Log'!$K$8:$K$257,'Deal Log'!$L$8:$L$257,A14,'Deal Log'!$I$8:$I$257,"Locked")+SUMIFS('Deal Log'!$K$8:$K$257,'Deal Log'!$L$8:$L$257,A14,'Deal Log'!$I$8:$I$257,"Pre-App")>0,SUMIFS('Deal Log'!$G$8:$G$257,'Deal Log'!$L$8:$L$257,A14,'Deal Log'!$I$8:$I$257,"Funded")+SUMIFS('Deal Log'!$K$8:$K$257,'Deal Log'!$L$8:$L$257,A14,'Deal Log'!$I$8:$I$257,"Locked")+SUMIFS('Deal Log'!$K$8:$K$257,'Deal Log'!$L$8:$L$257,A14,'Deal Log'!$I$8:$I$257,"Pre-App"),Inputs!$C$101) | E14: =H13 | F14: =IF(Inputs!$C$17="Yes",C14,0)+IF(Inputs!$C$19="Recoverable",Inputs!$C$34,0) | G14: =MIN(E14+F14,D14) | H14: =MAX(0,E14+F14-D14) | I14: =IF(Inputs!$C$17="Yes",C14+MAX(0,D14-(E14+F14)),IF(Inputs!$C$18="Stacked",C14+D14,MAX(C14,D14))) | J14: =IF(Inputs!$C$20="1099",I14*Inputs!$C$74,0) | K14: =I14-J14 | L14: ='Monthly Budget'!$C$14 | M14: ='Monthly Budget'!$C$23 | N14: ='Monthly Budget'!$C$27 | O14: =L14+M14+N14 | P14: =K14-O14 | Q14: =Q13+P14 | R14: =IF(COUNTIFS('Certificate Ladder'!$B$8:$B$40,">="&EOMONTH(A14,-1)+1,'Certificate Ladder'!$B$8:$B$40,"<="&A14)>0,Inputs!$C$59,0)
A15: =EOMONTH(A14,1) | B15: =COUNTIFS('Draw Recovery'!$B$9:$B$116,">="&EOMONTH(A15,-1)+1,'Draw Recovery'!$B$9:$B$116,"<="&A15) | C15: =B15*Inputs!$C$12 | D15: =IF(SUMIFS('Deal Log'!$G$8:$G$257,'Deal Log'!$L$8:$L$257,A15,'Deal Log'!$I$8:$I$257,"Funded")+SUMIFS('Deal Log'!$K$8:$K$257,'Deal Log'!$L$8:$L$257,A15,'Deal Log'!$I$8:$I$257,"Locked")+SUMIFS('Deal Log'!$K$8:$K$257,'Deal Log'!$L$8:$L$257,A15,'Deal Log'!$I$8:$I$257,"Pre-App")>0,SUMIFS('Deal Log'!$G$8:$G$257,'Deal Log'!$L$8:$L$257,A15,'Deal Log'!$I$8:$I$257,"Funded")+SUMIFS('Deal Log'!$K$8:$K$257,'Deal Log'!$L$8:$L$257,A15,'Deal Log'!$I$8:$I$257,"Locked")+SUMIFS('Deal Log'!$K$8:$K$257,'Deal Log'!$L$8:$L$257,A15,'Deal Log'!$I$8:$I$257,"Pre-App"),Inputs!$C$101) | E15: =H14 | F15: =IF(Inputs!$C$17="Yes",C15,0)+IF(Inputs!$C$19="Recoverable",Inputs!$C$34,0) | G15: =MIN(E15+F15,D15) | H15: =MAX(0,E15+F15-D15) | I15: =IF(Inputs!$C$17="Yes",C15+MAX(0,D15-(E15+F15)),IF(Inputs!$C$18="Stacked",C15+D15,MAX(C15,D15))) | J15: =IF(Inputs!$C$20="1099",I15*Inputs!$C$74,0) | K15: =I15-J15 | L15: ='Monthly Budget'!$C$14 | M15: ='Monthly Budget'!$C$23 | N15: ='Monthly Budget'!$C$27 | O15: =L15+M15+N15 | P15: =K15-O15 | Q15: =Q14+P15 | R15: =IF(COUNTIFS('Certificate Ladder'!$B$8:$B$40,">="&EOMONTH(A15,-1)+1,'Certificate Ladder'!$B$8:$B$40,"<="&A15)>0,Inputs!$C$59,0)
A16: =EOMONTH(A15,1) | B16: =COUNTIFS('Draw Recovery'!$B$9:$B$116,">="&EOMONTH(A16,-1)+1,'Draw Recovery'!$B$9:$B$116,"<="&A16) | C16: =B16*Inputs!$C$12 | D16: =IF(SUMIFS('Deal Log'!$G$8:$G$257,'Deal Log'!$L$8:$L$257,A16,'Deal Log'!$I$8:$I$257,"Funded")+SUMIFS('Deal Log'!$K$8:$K$257,'Deal Log'!$L$8:$L$257,A16,'Deal Log'!$I$8:$I$257,"Locked")+SUMIFS('Deal Log'!$K$8:$K$257,'Deal Log'!$L$8:$L$257,A16,'Deal Log'!$I$8:$I$257,"Pre-App")>0,SUMIFS('Deal Log'!$G$8:$G$257,'Deal Log'!$L$8:$L$257,A16,'Deal Log'!$I$8:$I$257,"Funded")+SUMIFS('Deal Log'!$K$8:$K$257,'Deal Log'!$L$8:$L$257,A16,'Deal Log'!$I$8:$I$257,"Locked")+SUMIFS('Deal Log'!$K$8:$K$257,'Deal Log'!$L$8:$L$257,A16,'Deal Log'!$I$8:$I$257,"Pre-App"),Inputs!$C$101) | E16: =H15 | F16: =IF(Inputs!$C$17="Yes",C16,0)+IF(Inputs!$C$19="Recoverable",Inputs!$C$34,0) | G16: =MIN(E16+F16,D16) | H16: =MAX(0,E16+F16-D16) | I16: =IF(Inputs!$C$17="Yes",C16+MAX(0,D16-(E16+F16)),IF(Inputs!$C$18="Stacked",C16+D16,MAX(C16,D16))) | J16: =IF(Inputs!$C$20="1099",I16*Inputs!$C$74,0) | K16: =I16-J16 | L16: ='Monthly Budget'!$C$14 | M16: ='Monthly Budget'!$C$23 | N16: ='Monthly Budget'!$C$27 | O16: =L16+M16+N16 | P16: =K16-O16 | Q16: =Q15+P16 | R16: =IF(COUNTIFS('Certificate Ladder'!$B$8:$B$40,">="&EOMONTH(A16,-1)+1,'Certificate Ladder'!$B$8:$B$40,"<="&A16)>0,Inputs!$C$59,0)
