Workbook

Sheet Start Here
A1: START HERE
A2: Derek Smith - Baxter Mortgage. Built September 2026.
A4: HOW THIS WORKS NOW THAT WE KNOW THE RULES
A5: The one rule that shapes everything | B5: 100% of your commission goes to the draw. So until the advance is gone, your take-home is the net draw and nothing else. Closing three loans in a month and closing none feel identical in your bank account. That is not a reason to slow down - it is the reason to speed up, because the only way out is through.
A6: Gross vs net | B6: The advance grows by the GROSS draw ($1,500 a check), not the $1,231.58 that reaches you. That is why you owe $16,500 after 11 draws, not $13,547. Confirm the $1,500 off a pay stub.
A7: THE SHEETS, IN THE ORDER YOU'LL USE THEM
A8: Roadmap | B8: Five phases and where you are in each. Start here every week.
A9: Deal Log | B9: The only sheet you must keep up with. One row per deal.
A10: Draw Payback | B10: 24 months. Shows exactly when the advance clears and your pay jumps.
A11: Dashboard | B11: The fifteen numbers, plus two charts.
A12: Budget / Cash Flow | B12: What life costs and what's left.
A13: Money Split | B13: What to do the day money lands - one plan for now, one for after the advance clears.
A14: Goals / Accounts | B14: Targets and where the money sits.
A15: Credit & Home | B15: Your card question answered, and what you'd qualify for.
A16: Savings & Retirement | B16: Is the certificate worth it, and what a Roth at 25 does.
A17: Car Loan | B17: Payoff schedule. Put the real APR on Inputs.
A18: COLOUR CODE
A19: Blue | B19: You type here.
A20: Yellow | B20: I guessed - please confirm.
A21: Green text | B21: Pulled from another sheet.
A22: Black | B22: A formula. Don't type over it.
A23: WHAT I HAD TO GUESS
A24: Confirm these | B24: Gross draw $1,500 (you said 'I think'), car insurance $165, phone $60, food $400, fun $250, car maintenance $90, savings APY 4.00%, credit limit $5,000, auto APR 7.49%, commission withholding 22%.
A25: The health insurance cliff | B25: Set to $0 because I assumed you're on a parent's plan. You age off at 26 - about a year away - and that's $350-500/mo landing in an already tight budget. Plan for it now.
A26: Not advice | B26: A planning model built from your numbers. Not tax, legal or investment advice. Confirm loan-program guidelines before acting on the housing section.

Sheet Roadmap
A1: YOUR ROADMAP — five phases, in order
A2: Everything here updates as you log deals. Phase 2 is the wall: until the advance is gone, closing more loans does not raise your pay by one dollar.
A4: WHERE YOU ARE TODAY: | C4: =IF(Inputs!$C$17>0,"PHASE 2 - digging out from under the advance","PHASE 3+ - the advance is clear") -> PHASE 2 - digging out from under the advance
B5: Phase | C5: Target | D5: Where you are | E5: % done | F5: Progress | G5: What it takes / why
B6: 1. Stop the advance growing | C6: =Inputs!$C$24 -> 1.3333333 | D6: =Inputs!$C$20 -> 2 | E6: =IFERROR(MIN(1,Inputs!$C$20/Inputs!$C$24),0) -> 1 | F6: =REPT("|",ROUND(E6*20,0))&REPT(".",20-ROUND(E6*20,0)) -> |||||||||||||||||||| | G6: At 1 loan/month the advance still GROWS by $750. You need 1.33 loans a month at $300k just to hold even. This is the first real milestone and it is lower than it feels.
B7: 2. Clear the advance | C7: =Inputs!$C$15 -> 16500 | D7: =Inputs!$C$16 -> 0 | E7: =IFERROR(MIN(1,Inputs!$C$16/Inputs!$C$15),0) -> 0 | F7: =REPT("|",ROUND(E7*20,0))&REPT(".",20-ROUND(E7*20,0)) -> .................... | G7: 100% of commission goes here. Until it hits zero your take-home is the net draw and nothing more. The Draw Payback tab dates this precisely.
B8: 3. Cushion + emergency fund | C8: =Inputs!$C$45+Inputs!$C$60*Budget!B17 -> 19036.757 | D8: =Inputs!$C$44+Inputs!$C$46 -> 8794.3 | E8: =IFERROR(MIN(1,(Inputs!$C$44+Inputs!$C$46)/(Inputs!$C$45+Inputs!$C$60*Budget!B17)),0) -> 0.46196419 | F8: =REPT("|",ROUND(E8*20,0))&REPT(".",20-ROUND(E8*20,0)) -> |||||||||........... | G8: $2,000 in checking plus 6 months of costs in savings. You are further along here than you think - the HYSA already does most of the work.
B9: 4. Roth IRA + ring | C9: =7000+Inputs!$C$61 -> 19000 | D9: =Inputs!$C$53+Inputs!$C$52 -> 0 | E9: =IFERROR(MIN(1,(Inputs!$C$53+Inputs!$C$52)/(7000+Inputs!$C$61)),0) -> 0 | F9: =REPT("|",ROUND(E9*20,0))&REPT(".",20-ROUND(E9*20,0)) -> .................... | G9: Neither account exists yet. Roth first - you are 25 and every year of delay is the most expensive one you will ever skip.
B10: 5. House | C10: =Inputs!$C$63*Inputs!$C$64+Inputs!$C$63*0.03 -> 32000 | D10: =0 -> 0 | E10: =0 -> 0 | F10: =REPT("|",ROUND(E10*20,0))&REPT(".",20-ROUND(E10*20,0)) -> .................... | G10: Down payment plus ~3% closing. But the real gate is income history, not cash - see 'Credit & Home'.
A12: THE TIMELINE (recalculates every time you log a deal)
B13: Advance clears | C13: ='Draw Payback'!D4 -> 11 months | G13: Then, and only then, commission starts reaching your bank.
B14: First commission above the draw | C14: ='Draw Payback'!H4 -> 46599 | G14: Your first genuinely bigger paycheck.
B15: Loans/month you need to stop digging | C15: =Inputs!$C$24 -> 1.3333333 | G15: The nearest-term target. Everything else waits on it.
B16: Loans/month you are planning | C16: =Inputs!$C$20 -> 2 | G16: Change this on Inputs and every date here moves.
B17: Proposal target | C17: =Inputs!$C$62 -> 46997 | G17: Roughly 2 years out.
B18: Home purchase target | C18: =Inputs!$C$65 -> 47178 | G18: Gated by a 2-year commission income history, not by savings.

Sheet Dashboard
A1: DASHBOARD — Derek Smith | Baxter Mortgage | NMLS 2810853
A2: ="Model date "&TEXT(Inputs!$C$59,"mmm d, yyyy")&" | Draw is RECOVERABLE, commission 100% recaptured | W-2, taxes withheld | Planning "&TEXT(Inputs!$C$20,"0.0")&" loans/month" -> Model date Sep 1, 2026 | Draw is RECOVERABLE, commission 100% recaptured | W-2, taxes withheld | Planning 2.0 loans/month
B4: THE NUMBERS THAT MATTER
B5: You owe on the draw | C5: =Inputs!$C$17 -> 16500 | E5: Loans/mo to stop digging | F5: =Inputs!$C$24 -> 1.3333333 | H5: Total saved today | I5: =Inputs!$C$44+Inputs!$C$46+Inputs!$C$48 -> 15317.01
B6: Commission credited so far | C6: ='Deal Log'!F4 -> 0 | E6: Loans/mo you're planning | F6: =Inputs!$C$20 -> 2 | H6: Emergency fund target | I6: =Inputs!$C$60*Budget!B17 -> 17036.757
B7: Advance clears in | C7: ='Draw Payback'!D4 -> 11 months | E7: Advance moves per month | F7: =Inputs!$C$22 -> 1500 | H7: Auto loan balance | I7: =Inputs!$C$56 -> 25092.02
B8: Your take-home / month | C8: =Inputs!$C$10 -> 2463.16 | E8: Monthly costs | F8: =Budget!B17 -> 2839.4595 | H8: Roth at 65 if you start now | I8: ='Savings & Retirement'!C14 -> 1813395.6
B9: Cash in checking | C9: =Inputs!$C$44 -> 395.4 | E9: Left over each month | F9: =Budget!B20 -> -376.29947 | H9: Months of runway | I9: =IFERROR((Inputs!$C$44+Inputs!$C$46)/Budget!B17,0) -> 3.097174
B11: DO THESE FIVE THINGS
B12: 1. Confirm the gross draw is $1,500 off a pay stub. Every number here scales off it.
B13: 2. Get checking to $2,000. You have $395.40 and $865.84 is due by 10/14.
B14: 3. Close 1.33 loans a month minimum - below that the advance grows even while you're producing.
B15: 4. Open the Roth IRA and the ring savings account. Both are $0 because neither exists.
B16: 5. Check your savings rate against the certificate's 3.687%. If savings wins, stop the auto-roll.

Sheet Inputs
A1: CONTROL PANEL
A2: Change BLUE cells. YELLOW means I had to guess - please confirm. Everything else calculates itself.
A4: 1. YOUR DRAW — gross is what hits the balance, net is what hits your bank
B5: Draw per paycheck - GROSS | C5: 1500 | D5: $ | E5: You said 'I think it's 1500'. CONFIRM off a pay stub - this is the number the advance grows by, so it drives everything.
B6: Draw per paycheck - NET to you | C6: 1231.58 | D6: $ | E6: What actually lands in your account.
B7: = withholding rate | C7: =1-C6/C5 -> 0.17894667 | E7: Taxes are being withheld, so you are W-2. That is settled - no quarterly estimates to worry about.
B8: Paychecks per year | C8: 24 | D8: /yr | E8: 24, not 26. Your dates (3/31, 4/15, 4/30, 5/15, 5/29, 6/15, 6/30, 7/16, 7/30, 8/14, 8/28) are the 15th and month-end.
B9: MONTHLY draw - gross | C9: =C5*C8/12 -> 3000 | D9: $/mo | E9: The advance grows by this every month.
B10: MONTHLY draw - NET to you | C10: =C6*C8/12 -> 2463.16 | D10: $/mo | E10: This is your entire income until the advance is cleared, no matter how much you close.
B11: Draws received so far | C11: 11 | D11: checks
B12: Your commission | C12: 0.0075 | D12: of loan | E12: 75 bps. Unchanged whether the company charges 275, 200 or 150.
B13: Withholding on commission payouts | C13: 0.22 | E13: Commission is usually withheld at the 22% federal supplemental rate plus state. Only matters once the advance clears.
A14: 2. THE ADVANCE — confirmed: 100% of your commission goes to the draw
B15: Advance from draws taken | C15: =C5*C11 -> 16500 | D15: $ | E15: 11 x $1,500 GROSS. Note this is $2,952.62 higher than a net-based figure - the company advanced the gross.
B16: Commission credited so far | C16: ='Deal Log'!$F$4 -> 0 | D16: $ | E16: Sums every Funded row on your Deal Log.
B17: YOU CURRENTLY OWE | C17: =MAX(0,C15-C16) -> 16500 | D17: $ | E17: Log deals and watch this fall.
A18: 3. DEAL ASSUMPTIONS (used to forecast months you have not logged yet)
B19: Average loan size | C19: 300000 | D19: $ | E19: Set from your real pipeline.
B20: Loans per month you PLAN to close | C20: 2 | D20: loans | E20: Change this and the whole roadmap re-times.
B21: = commission per month | C21: =C20*C19*C12 -> 4500 | D21: $/mo
B22: = pays down the advance by | C22: =C21-C9 -> 1500 | D22: $/mo | E22: Commission minus the new draw. If this is negative you are going backwards.
B23: BREAK-EVEN: commission needed just to STOP the balance growing | C23: =C9 -> 3000 | D23: $/mo | E23: Below this the advance gets BIGGER every month even though you are closing loans.
B24: = loans per month to stop digging | C24: =C23/C12/C19 -> 1.3333333 | D24: loans | E24: THE number that matters most right now. At 1 loan/month the advance still grows by $750 every month.
B25: Months to clear the advance at your planned pace | C25: =IF(C22<=0,"never at this pace",ROUNDUP(C17/C22,0)) -> 11 | D25: months | E25: Updates automatically as you log deals.
A26: 4. WHAT YOU SPEND
B27: Car payment | C27: 475.69 | D27: $/mo
B28: Car insurance | C28: 165 | D28: $/mo | E28: NOT LISTED but your lender requires it.
B29: Gym (x2 per month) | C29: 31.99 | D29: $/charge
B30: Amazon Prime | C30: 15 | D30: $/mo | E30: Annual plan is ~$11.58/mo.
B31: Phone | C31: 60 | D31: $/mo | E31: NOT LISTED. Zero it if you're on a family plan.
B32: Miles driven | C32: 1000 | D32: mi/mo
B33: Gas price | C33: 4.1 | D33: $/gal
B34: MPG | C34: 19 | D34: mpg
B35: = Fuel | C35: =C32/C34*C33 -> 215.78947 | D35: $/mo
B36: Aroma Joe's per visit | C36: 6 | D36: $
B37: visits per week | C37: 4 | D37: /wk | E37: 4/wk = $1,248/yr.
B38: = Coffee | C38: =C36*C37*52/12 -> 104 | D38: $/mo
B39: Food / eating out | C39: 400 | D39: $/mo | E39: NOT LISTED - you live at home so this may be lower.
B40: Personal / fun | C40: 250 | D40: $/mo | E40: NOT LISTED.
B41: Car maintenance set-aside | C41: 90 | D41: $/mo | E41: NOT LISTED. 12k Maine miles = tires and brakes.
...

Sheet Deal Log
A1: DEAL LOG — the only sheet you have to keep up with
A2: One row per deal. Fill in A-E and H. Your commission and everything downstream updates on its own.
A4: Funded volume | C4: =SUMIFS(C9:C208,$H$9:$H$208,"Funded") -> 0 | D4: YOUR COMMISSION (credited to the draw) | F4: =SUMIFS(F9:F208,$H$9:$H$208,"Funded") -> 0 | G4: =COUNTIFS($H$9:$H$208,"Funded")&" funded" -> 0 funded
A5: Still owed on the draw | C5: =Inputs!$C$17 -> 16500 | D5: ="Every dollar in the green box goes straight here until it reaches zero." -> Every dollar in the green box goes straight here until it reaches zero.
A6: Row 8 below is a greyed-out EXAMPLE showing the format. It is OUTSIDE every total, so it never affects your numbers - leave it or delete it, either is fine. Start typing on row 9.
A7: Date funded | B7: Client / deal | C7: Loan amount | D7: Broker check (company) | E7: Co. bps | F7: YOUR COMMISSION | G7: Applied to draw | H7: Status | I7: Month | J7: Referral source | K7: Notes
A8: 46287 | B8: <- EXAMPLE (not counted) | C8: 300000 | D8: 8250 | E8: 0.0275 | F8: 2250 | G8: 2250 | H8: Funded | I8: 46295 | J8: Realtor - J. Poulin | K8: $300k x 0.75% = $2,250 to you
F9: =IF($A9="","",$C9*Inputs!$C$12) | G9: =IF($A9="","",IF($H9="Funded",$F9,0)) | I9: =IF($A9="","",EOMONTH($A9,0))
F10: =IF($A10="","",$C10*Inputs!$C$12) | G10: =IF($A10="","",IF($H10="Funded",$F10,0)) | I10: =IF($A10="","",EOMONTH($A10,0))
F11: =IF($A11="","",$C11*Inputs!$C$12) | G11: =IF($A11="","",IF($H11="Funded",$F11,0)) | I11: =IF($A11="","",EOMONTH($A11,0))
F12: =IF($A12="","",$C12*Inputs!$C$12) | G12: =IF($A12="","",IF($H12="Funded",$F12,0)) | I12: =IF($A12="","",EOMONTH($A12,0))
F13: =IF($A13="","",$C13*Inputs!$C$12) | G13: =IF($A13="","",IF($H13="Funded",$F13,0)) | I13: =IF($A13="","",EOMONTH($A13,0))
F14: =IF($A14="","",$C14*Inputs!$C$12) | G14: =IF($A14="","",IF($H14="Funded",$F14,0)) | I14: =IF($A14="","",EOMONTH($A14,0))
F15: =IF($A15="","",$C15*Inputs!$C$12) | G15: =IF($A15="","",IF($H15="Funded",$F15,0)) | I15: =IF($A15="","",EOMONTH($A15,0))
F16: =IF($A16="","",$C16*Inputs!$C$12) | G16: =IF($A16="","",IF($H16="Funded",$F16,0)) | I16: =IF($A16="","",EOMONTH($A16,0))
F17: =IF($A17="","",$C17*Inputs!$C$12) | G17: =IF($A17="","",IF($H17="Funded",$F17,0)) | I17: =IF($A17="","",EOMONTH($A17,0))
F18: =IF($A18="","",$C18*Inputs!$C$12) | G18: =IF($A18="","",IF($H18="Funded",$F18,0)) | I18: =IF($A18="","",EOMONTH($A18,0))
F19: =IF($A19="","",$C19*Inputs!$C$12) | G19: =IF($A19="","",IF($H19="Funded",$F19,0)) | I19: =IF($A19="","",EOMONTH($A19,0))
F20: =IF($A20="","",$C20*Inputs!$C$12) | G20: =IF($A20="","",IF($H20="Funded",$F20,0)) | I20: =IF($A20="","",EOMONTH($A20,0))
... F208: =IF($A208="","",$C208*Inputs!$C$12) | G208: =IF($A208="","",IF($H208="Funded",$F208,0)) | I208: =IF($A208="","",EOMONTH($A208,0))

Sheet Draw Payback
A1: DRAW PAYBACK — 24 months, and exactly when you get your first real commission check
A2: Read column F: while it is above zero your take-home is frozen at the net draw. Column J is what actually lands in your bank.
A4: Advance today | B4: =Inputs!$C$17 -> 16500 | C4: Clears in | D4: =IFERROR(MATCH(0,F9:F32,0)&" months","not within 24 mo") -> 11 months | E4: First month you get paid above the draw | H4: =IFERROR(INDEX(A9:A32,MATCH(0,F9:F32,0)),"not within 24 months") -> 46599
A5: ="At your planned pace of "&TEXT(Inputs!$C$20,"0.0")&" loans/month you earn "&TEXT(Inputs!$C$21,"$#,##0")&" while the draw adds "&TEXT(Inputs!$C$9,"$#,##0")&" - so the balance moves "&TEXT(Inputs!$C$22,"$#,##0")&" a month." -> At your planned pace of 2.0 loans/month you earn $4,500 while the draw adds $3,000 - so the balance moves $1,500 a month.
A8: Month | B8: Opening advance | C8: Draw added (gross) | D8: Commission earned | E8: Applied to advance | F8: Closing advance | G8: Paid to you above draw | H8: Withheld | I8: Net draw to you | J8: CASH TO YOU this month | K8: What's happening
A9: =EOMONTH(Inputs!$C$59,0) -> 46295 | B9: =Inputs!$C$17 -> 16500 | C9: =Inputs!$C$9 -> 3000 | D9: =IF(SUMIFS('Deal Log'!$F$9:$F$208,'Deal Log'!$I$9:$I$208,A9,'Deal Log'!$H$9:$H$208,"Funded")>0,SUMIFS('Deal Log'!$F$9:$F$208,'Deal Log'!$I$9:$I$208,A9,'Deal Log'!$H$9:$H$208,"Funded"),Inputs!$C$21) -> 4500 | E9: =MIN(B9+C9,D9) -> 4500 | F9: =MAX(0,B9+C9-D9) -> 15000 | G9: =MAX(0,D9-(B9+C9)) -> 0 | H9: =G9*Inputs!$C$13 -> 0 | I9: =Inputs!$C$10 -> 2463.16 | J9: =I9+G9-H9 -> 2463.16 | K9: =IF(F9>B9,"Advance still growing",IF(F9>0,"Paying it down",IF(G9>0,"CLEARED - real income now","Cleared"))) -> Paying it down
A10: =EOMONTH(Inputs!$C$59,1) -> 46326 | B10: =F9 -> 15000 | C10: =Inputs!$C$9 -> 3000 | D10: =IF(SUMIFS('Deal Log'!$F$9:$F$208,'Deal Log'!$I$9:$I$208,A10,'Deal Log'!$H$9:$H$208,"Funded")>0,SUMIFS('Deal Log'!$F$9:$F$208,'Deal Log'!$I$9:$I$208,A10,'Deal Log'!$H$9:$H$208,"Funded"),Inputs!$C$21) -> 4500 | E10: =MIN(B10+C10,D10) -> 4500 | F10: =MAX(0,B10+C10-D10) -> 13500 | G10: =MAX(0,D10-(B10+C10)) -> 0 | H10: =G10*Inputs!$C$13 -> 0 | I10: =Inputs!$C$10 -> 2463.16 | J10: =I10+G10-H10 -> 2463.16 | K10: =IF(F10>B10,"Advance still growing",IF(F10>0,"Paying it down",IF(G10>0,"CLEARED - real income now","Cleared"))) -> Paying it down
A11: =EOMONTH(Inputs!$C$59,2) -> 46356 | B11: =F10 -> 13500 | C11: =Inputs!$C$9 -> 3000 | D11: =IF(SUMIFS('Deal Log'!$F$9:$F$208,'Deal Log'!$I$9:$I$208,A11,'Deal Log'!$H$9:$H$208,"Funded")>0,SUMIFS('Deal Log'!$F$9:$F$208,'Deal Log'!$I$9:$I$208,A11,'Deal Log'!$H$9:$H$208,"Funded"),Inputs!$C$21) -> 4500 | E11: =MIN(B11+C11,D11) -> 4500 | F11: =MAX(0,B11+C11-D11) -> 12000 | G11: =MAX(0,D11-(B11+C11)) -> 0 | H11: =G11*Inputs!$C$13 -> 0 | I11: =Inputs!$C$10 -> 2463.16 | J11: =I11+G11-H11 -> 2463.16 | K11: =IF(F11>B11,"Advance still growing",IF(F11>0,"Paying it down",IF(G11>0,"CLEARED - real income now","Cleared"))) -> Paying it down
A12: =EOMONTH(Inputs!$C$59,3) -> 46387 | B12: =F11 -> 12000 | C12: =Inputs!$C$9 -> 3000 | D12: =IF(SUMIFS('Deal Log'!$F$9:$F$208,'Deal Log'!$I$9:$I$208,A12,'Deal Log'!$H$9:$H$208,"Funded")>0,SUMIFS('Deal Log'!$F$9:$F$208,'Deal Log'!$I$9:$I$208,A12,'Deal Log'!$H$9:$H$208,"Funded"),Inputs!$C$21) -> 4500 | E12: =MIN(B12+C12,D12) -> 4500 | F12: =MAX(0,B12+C12-D12) -> 10500 | G12: =MAX(0,D12-(B12+C12)) -> 0 | H12: =G12*Inputs!$C$13 -> 0 | I12: =Inputs!$C$10 -> 2463.16 | J12: =I12+G12-H12 -> 2463.16 | K12: =IF(F12>B12,"Advance still growing",IF(F12>0,"Paying it down",IF(G12>0,"CLEARED - real income now","Cleared"))) -> Paying it down
A13: =EOMONTH(Inputs!$C$59,4) -> 46418 | B13: =F12 -> 10500 | C13: =Inputs!$C$9 -> 3000 | D13: =IF(SUMIFS('Deal Log'!$F$9:$F$208,'Deal Log'!$I$9:$I$208,A13,'Deal Log'!$H$9:$H$208,"Funded")>0,SUMIFS('Deal Log'!$F$9:$F$208,'Deal Log'!$I$9:$I$208,A13,'Deal Log'!$H$9:$H$208,"Funded"),Inputs!$C$21) -> 4500 | E13: =MIN(B13+C13,D13) -> 4500 | F13: =MAX(0,B13+C13-D13) -> 9000 | G13: =MAX(0,D13-(B13+C13)) -> 0 | H13: =G13*Inputs!$C$13 -> 0 | I13: =Inputs!$C$10 -> 2463.16 | J13: =I13+G13-H13 -> 2463.16 | K13: =IF(F13>B13,"Advance still growing",IF(F13>0,"Paying it down",IF(G13>0,"CLEARED - real income now","Cleared"))) -> Paying it down
A14: =EOMONTH(Inputs!$C$59,5) -> 46446 | B14: =F13 -> 9000 | C14: =Inputs!$C$9 -> 3000 | D14: =IF(SUMIFS('Deal Log'!$F$9:$F$208,'Deal Log'!$I$9:$I$208,A14,'Deal Log'!$H$9:$H$208,"Funded")>0,SUMIFS('Deal Log'!$F$9:$F$208,'Deal Log'!$I$9:$I$208,A14,'Deal Log'!$H$9:$H$208,"Funded"),Inputs!$C$21) -> 4500 | E14: =MIN(B14+C14,D14) -> 4500 | F14: =MAX(0,B14+C14-D14) -> 7500 | G14: =MAX(0,D14-(B14+C14)) -> 0 | H14: =G14*Inputs!$C$13 -> 0 | I14: =Inputs!$C$10 -> 2463.16 | J14: =I14+G14-H14 -> 2463.16 | K14: =IF(F14>B14,"Advance still growing",IF(F14>0,"Paying it down",IF(G14>0,"CLEARED - real income now","Cleared"))) -> Paying it down
A15: =EOMONTH(Inputs!$C$59,6) -> 46477 | B15: =F14 -> 7500 | C15: =Inputs!$C$9 -> 3000 | D15: =IF(SUMIFS('Deal Log'!$F$9:$F$208,'Deal Log'!$I$9:$I$208,A15,'Deal Log'!$H$9:$H$208,"Funded")>0,SUMIFS('Deal Log'!$F$9:$F$208,'Deal Log'!$I$9:$I$208,A15,'Deal Log'!$H$9:$H$208,"Funded"),Inputs!$C$21) -> 4500 | E15: =MIN(B15+C15,D15) -> 4500 | F15: =MAX(0,B15+C15-D15) -> 6000 | G15: =MAX(0,D15-(B15+C15)) -> 0 | H15: =G15*Inputs!$C$13 -> 0 | I15: =Inputs!$C$10 -> 2463.16 | J15: =I15+G15-H15 -> 2463.16 | K15: =IF(F15>B15,"Advance still growing",IF(F15>0,"Paying it down",IF(G15>0,"CLEARED - real income now","Cleared"))) -> Paying it down
A16: =EOMONTH(Inputs!$C$59,7) -> 46507 | B16: =F15 -> 6000 | C16: =Inputs!$C$9 -> 3000 | D16: =IF(SUMIFS('Deal Log'!$F$9:$F$208,'Deal Log'!$I$9:$I$208,A16,'Deal Log'!$H$9:$H$208,"Funded")>0,SUMIFS('Deal Log'!$F$9:$F$208,'Deal Log'!$I$9:$I$208,A16,'Deal Log'!$H$9:$H$208,"Funded"),Inputs!$C$21) -> 4500 | E16: =MIN(B16+C16,D16) -> 4500 | F16: =MAX(0,B16+C16-D16) -> 4500 | G16: =MAX(0,D16-(B16+C16)) -> 0 | H16: =G16*Inputs!$C$13 -> 0 | I16: =Inputs!$C$10 -> 2463.16 | J16: =I16+G16-H16 -> 2463.16 | K16: =IF(F16>B16,"Advance still growing",IF(F16>0,"Paying it down",IF(G16>0,"CLEARED - real income now","Cleared"))) -> Paying it down
A17: =EOMONTH(Inputs!$C$59,8) -> 46538 | B17: =F16 -> 4500 | C17: =Inputs!$C$9 -> 3000 | D17: =IF(SUMIFS('Deal Log'!$F$9:$F$208,'Deal Log'!$I$9:$I$208,A17,'Deal Log'!$H$9:$H$208,"Funded")>0,SUMIFS('Deal Log'!$F$9:$F$208,'Deal Log'!$I$9:$I$208,A17,'Deal Log'!$H$9:$H$208,"Funded"),Inputs!$C$21) -> 4500 | E17: =MIN(B17+C17,D17) -> 4500 | F17: =MAX(0,B17+C17-D17) -> 3000 | G17: =MAX(0,D17-(B17+C17)) -> 0 | H17: =G17*Inputs!$C$13 -> 0 | I17: =Inputs!$C$10 -> 2463.16 | J17: =I17+G17-H17 -> 2463.16 | K17: =IF(F17>B17,"Advance still growing",IF(F17>0,"Paying it down",IF(G17>0,"CLEARED - real income now","Cleared"))) -> Paying it down
A18: =EOMONTH(Inputs!$C$59,9) -> 46568 | B18: =F17 -> 3000 | C18: =Inputs!$C$9 -> 3000 | D18: =IF(SUMIFS('Deal Log'!$F$9:$F$208,'Deal Log'!$I$9:$I$208,A18,'Deal Log'!$H$9:$H$208,"Funded")>0,SUMIFS('Deal Log'!$F$9:$F$208,'Deal Log'!$I$9:$I$208,A18,'Deal Log'!$H$9:$H$208,"Funded"),Inputs!$C$21) -> 4500 | E18: =MIN(B18+C18,D18) -> 4500 | F18: =MAX(0,B18+C18-D18) -> 1500 | G18: =MAX(0,D18-(B18+C18)) -> 0 | H18: =G18*Inputs!$C$13 -> 0 | I18: =Inputs!$C$10 -> 2463.16 | J18: =I18+G18-H18 -> 2463.16 | K18: =IF(F18>B18,"Advance still growing",IF(F18>0,"Paying it down",IF(G18>0,"CLEARED - real income now","Cleared"))) -> Paying it down
A19: =EOMONTH(Inputs!$C$59,10) -> 46599 | B19: =F18 -> 1500 | C19: =Inputs!$C$9 -> 3000 | D19: =IF(SUMIFS('Deal Log'!$F$9:$F$208,'Deal Log'!$I$9:$I$208,A19,'Deal Log'!$H$9:$H$208,"Funded")>0,SUMIFS('Deal Log'!$F$9:$F$208,'Deal Log'!$I$9:$I$208,A19,'Deal Log'!$H$9:$H$208,"Funded"),Inputs!$C$21) -> 4500 | E19: =MIN(B19+C19,D19) -> 4500 | F19: =MAX(0,B19+C19-D19) -> 0 | G19: =MAX(0,D19-(B19+C19)) -> 0 | H19: =G19*Inputs!$C$13 -> 0 | I19: =Inputs!$C$10 -> 2463.16 | J19: =I19+G19-H19 -> 2463.16 | K19: =IF(F19>B19,"Advance still growing",IF(F19>0,"Paying it down",IF(G19>0,"CLEARED - real income now","Cleared"))) -> Cleared
A20: =EOMONTH(Inputs!$C$59,11) -> 46630 | B20: =F19 -> 0 | C20: =Inputs!$C$9 -> 3000 | D20: =IF(SUMIFS('Deal Log'!$F$9:$F$208,'Deal Log'!$I$9:$I$208,A20,'Deal Log'!$H$9:$H$208,"Funded")>0,SUMIFS('Deal Log'!$F$9:$F$208,'Deal Log'!$I$9:$I$208,A20,'Deal Log'!$H$9:$H$208,"Funded"),Inputs!$C$21) -> 4500 | E20: =MIN(B20+C20,D20) -> 3000 | F20: =MAX(0,B20+C20-D20) -> 0 | G20: =MAX(0,D20-(B20+C20)) -> 1500 | H20: =G20*Inputs!$C$13 -> 330 | I20: =Inputs!$C$10 -> 2463.16 | J20: =I20+G20-H20 -> 3633.16 | K20: =IF(F20>B20,"Advance still growing",IF(F20>0,"Paying it down",IF(G20>0,"CLEARED - real income now","Cleared"))) -> CLEARED - real income now
A21: =EOMONTH(Inputs!$C$59,12) -> 46660 | B21: =F20 -> 0 | C21: =Inputs!$C$9 -> 3000 | D21: =IF(SUMIFS('Deal Log'!$F$9:$F$208,'Deal Log'!$I$9:$I$208,A21,'Deal Log'!$H$9:$H$208,"Funded")>0,SUMIFS('Deal Log'!$F$9:$F$208,'Deal Log'!$I$9:$I$208,A21,'Deal Log'!$H$9:$H$208,"Funded"),Inputs!$C$21) -> 4500 | E21: =MIN(B21+C21,D21) -> 3000 | F21: =MAX(0,B21+C21-D21) -> 0 | G21: =MAX(0,D21-(B21+C21)) -> 1500 | H21: =G21*Inputs!$C$13 -> 330 | I21: =Inputs!$C$10 -> 2463.16 | J21: =I21+G21-H21 -> 3633.16 | K21: =IF(F21>B21,"Advance still growing",IF(F21>0,"Paying it down",IF(G21>0,"CLEARED - real income now","Cleared"))) -> CLEARED - real income now
A22: =EOMONTH(Inputs!$C$59,13) -> 46691 | B22: =F21 -> 0 | C22: =Inputs!$C$9 -> 3000 | D22: =IF(SUMIFS('Deal Log'!$F$9:$F$208,'Deal Log'!$I$9:$I$208,A22,'Deal Log'!$H$9:$H$208,"Funded")>0,SUMIFS('Deal Log'!$F$9:$F$208,'Deal Log'!$I$9:$I$208,A22,'Deal Log'!$H$9:$H$208,"Funded"),Inputs!$C$21) -> 4500 | E22: =MIN(B22+C22,D22) -> 3000 | F22: =MAX(0,B22+C22-D22) -> 0 | G22: =MAX(0,D22-(B22+C22)) -> 1500 | H22: =G22*Inputs!$C$13 -> 330 | I22: =Inputs!$C$10 -> 2463.16 | J22: =I22+G22-H22 -> 3633.16 | K22: =IF(F22>B22,"Advance still growing",IF(F22>0,"Paying it down",IF(G22>0,"CLEARED - real income now","Cleared"))) -> CLEARED - real income now
A23: =EOMONTH(Inputs!$C$59,14) -> 46721 | B23: =F22 -> 0 | C23: =Inputs!$C$9 -> 3000 | D23: =IF(SUMIFS('Deal Log'!$F$9:$F$208,'Deal Log'!$I$9:$I$208,A23,'Deal Log'!$H$9:$H$208,"Funded")>0,SUMIFS('Deal Log'!$F$9:$F$208,'Deal Log'!$I$9:$I$208,A23,'Deal Log'!$H$9:$H$208,"Funded"),Inputs!$C$21) -> 4500 | E23: =MIN(B23+C23,D23) -> 3000 | F23: =MAX(0,B23+C23-D23) -> 0 | G23: =MAX(0,D23-(B23+C23)) -> 1500 | H23: =G23*Inputs!$C$13 -> 330 | I23: =Inputs!$C$10 -> 2463.16 | J23: =I23+G23-H23 -> 3633.16 | K23: =IF(F23>B23,"Advance still growing",IF(F23>0,"Paying it down",IF(G23>0,"CLEARED - real income now","Cleared"))) -> CLEARED - real income now
A24: =EOMONTH(Inputs!$C$59,15) -> 46752 | B24: =F23 -> 0 | C24: =Inputs!$C$9 -> 3000 | D24: =IF(SUMIFS('Deal Log'!$F$9:$F$208,'Deal Log'!$I$9:$I$208,A24,'Deal Log'!$H$9:$H$208,"Funded")>0,SUMIFS('Deal Log'!$F$9:$F$208,'Deal Log'!$I$9:$I$208,A24,'Deal Log'!$H$9:$H$208,"Funded"),Inputs!$C$21) -> 4500 | E24: =MIN(B24+C24,D24) -> 3000 | F24: =MAX(0,B24+C24-D24) -> 0 | G24: =MAX(0,D24-(B24+C24)) -> 1500 | H24: =G24*Inputs!$C$13 -> 330 | I24: =Inputs!$C$10 -> 2463.16 | J24: =I24+G24-H24 -> 3633.16 | K24: =IF(F24>B24,"Advance still growing",IF(F24>0,"Paying it down",IF(G24>0,"CLEARED - real income now","Cleared"))) -> CLEARED - real income now
A25: =EOMONTH(Inputs!$C$59,16) -> 46783 | B25: =F24 -> 0 | C25: =Inputs!$C$9 -> 3000 | D25: =IF(SUMIFS('Deal Log'!$F$9:$F$208,'Deal Log'!$I$9:$I$208,A25,'Deal Log'!$H$9:$H$208,"Funded")>0,SUMIFS('Deal Log'!$F$9:$F$208,'Deal Log'!$I$9:$I$208,A25,'Deal Log'!$H$9:$H$208,"Funded"),Inputs!$C$21) -> 4500 | E25: =MIN(B25+C25,D25) -> 3000 | F25: =MAX(0,B25+C25-D25) -> 0 | G25: =MAX(0,D25-(B25+C25)) -> 1500 | H25: =G25*Inputs!$C$13 -> 330 | I25: =Inputs!$C$10 -> 2463.16 | J25: =I25+G25-H25 -> 3633.16 | K25: =IF(F25>B25,"Advance still growing",IF(F25>0,"Paying it down",IF(G25>0,"CLEARED - real income now","Cleared"))) -> CLEARED - real income now
A26: =EOMONTH(Inputs!$C$59,17) -> 46812 | B26: =F25 -> 0 | C26: =Inputs!$C$9 -> 3000 | D26: =IF(SUMIFS('Deal Log'!$F$9:$F$208,'Deal Log'!$I$9:$I$208,A26,'Deal Log'!$H$9:$H$208,"Funded")>0,SUMIFS('Deal Log'!$F$9:$F$208,'Deal Log'!$I$9:$I$208,A26,'Deal Log'!$H$9:$H$208,"Funded"),Inputs!$C$21) -> 4500 | E26: =MIN(B26+C26,D26) -> 3000 | F26: =MAX(0,B26+C26-D26) -> 0 | G26: =MAX(0,D26-(B26+C26)) -> 1500 | H26: =G26*Inputs!$C$13 -> 330 | I26: =Inputs!$C$10 -> 2463.16 | J26: =I26+G26-H26 -> 3633.16 | K26: =IF(F26>B26,"Advance still growing",IF(F26>0,"Paying it down",IF(G26>0,"CLEARED - real income now","Cleared"))) -> CLEARED - real income now
A27: =EOMONTH(Inputs!$C$59,18) -> 46843 | B27: =F26 -> 0 | C27: =Inputs!$C$9 -> 3000 | D27: =IF(SUMIFS('Deal Log'!$F$9:$F$208,'Deal Log'!$I$9:$I$208,A27,'Deal Log'!$H$9:$H$208,"Funded")>0,SUMIFS('Deal Log'!$F$9:$F$208,'Deal Log'!$I$9:$I$208,A27,'Deal Log'!$H$9:$H$208,"Funded"),Inputs!$C$21) -> 4500 | E27: =MIN(B27+C27,D27) -> 3000 | F27: =MAX(0,B27+C27-D27) -> 0 | G27: =MAX(0,D27-(B27+C27)) -> 1500 | H27: =G27*Inputs!$C$13 -> 330 | I27: =Inputs!$C$10 -> 2463.16 | J27: =I27+G27-H27 -> 3633.16 | K27: =IF(F27>B27,"Advance still growing",IF(F27>0,"Paying it down",IF(G27>0,"CLEARED - real income now","Cleared"))) -> CLEARED - real income now
A28: =EOMONTH(Inputs!$C$59,19) -> 46873 | B28: =F27 -> 0 | C28: =Inputs!$C$9 -> 3000 | D28: =IF(SUMIFS('Deal Log'!$F$9:$F$208,'Deal Log'!$I$9:$I$208,A28,'Deal Log'!$H$9:$H$208,"Funded")>0,SUMIFS('Deal Log'!$F$9:$F$208,'Deal Log'!$I$9:$I$208,A28,'Deal Log'!$H$9:$H$208,"Funded"),Inputs!$C$21) -> 4500 | E28: =MIN(B28+C28,D28) -> 3000 | F28: =MAX(0,B28+C28-D28) -> 0 | G28: =MAX(0,D28-(B28+C28)) -> 1500 | H28: =G28*Inputs!$C$13 -> 330 | I28: =Inputs!$C$10 -> 2463.16 | J28: =I28+G28-H28 -> 3633.16 | K28: =IF(F28>B28,"Advance still growing",IF(F28>0,"Paying it down",IF(G28>0,"CLEARED - real income now","Cleared"))) -> CLEARED - real income now
A29: =EOMONTH(Inputs!$C$59,20) -> 46904 | B29: =F28 -> 0 | C29: =Inputs!$C$9 -> 3000 | D29: =IF(SUMIFS('Deal Log'!$F$9:$F$208,'Deal Log'!$I$9:$I$208,A29,'Deal Log'!$H$9:$H$208,"Funded")>0,SUMIFS('Deal Log'!$F$9:$F$208,'Deal Log'!$I$9:$I$208,A29,'Deal Log'!$H$9:$H$208,"Funded"),Inputs!$C$21) -> 4500 | E29: =MIN(B29+C29,D29) -> 3000 | F29: =MAX(0,B29+C29-D29) -> 0 | G29: =MAX(0,D29-(B29+C29)) -> 1500 | H29: =G29*Inputs!$C$13 -> 330 | I29: =Inputs!$C$10 -> 2463.16 | J29: =I29+G29-H29 -> 3633.16 | K29: =IF(F29>B29,"Advance still growing",IF(F29>0,"Paying it down",IF(G29>0,"CLEARED - real income now","Cleared"))) -> CLEARED - real income now
A30: =EOMONTH(Inputs!$C$59,21) -> 46934 | B30: =F29 -> 0 | C30: =Inputs!$C$9 -> 3000 | D30: =IF(SUMIFS('Deal Log'!$F$9:$F$208,'Deal Log'!$I$9:$I$208,A30,'Deal Log'!$H$9:$H$208,"Funded")>0,SUMIFS('Deal Log'!$F$9:$F$208,'Deal Log'!$I$9:$I$208,A30,'Deal Log'!$H$9:$H$208,"Funded"),Inputs!$C$21) -> 4500 | E30: =MIN(B30+C30,D30) -> 3000 | F30: =MAX(0,B30+C30-D30) -> 0 | G30: =MAX(0,D30-(B30+C30)) -> 1500 | H30: =G30*Inputs!$C$13 -> 330 | I30: =Inputs!$C$10 -> 2463.16 | J30: =I30+G30-H30 -> 3633.16 | K30: =IF(F30>B30,"Advance still growing",IF(F30>0,"Paying it down",IF(G30>0,"CLEARED - real income now","Cleared"))) -> CLEARED - real income now
A31: =EOMONTH(Inputs!$C$59,22) -> 46965 | B31: =F30 -> 0 | C31: =Inputs!$C$9 -> 3000 | D31: =IF(SUMIFS('Deal Log'!$F$9:$F$208,'Deal Log'!$I$9:$I$208,A31,'Deal Log'!$H$9:$H$208,"Funded")>0,SUMIFS('Deal Log'!$F$9:$F$208,'Deal Log'!$I$9:$I$208,A31,'Deal Log'!$H$9:$H$208,"Funded"),Inputs!$C$21) -> 4500 | E31: =MIN(B31+C31,D31) -> 3000 | F31: =MAX(0,B31+C31-D31) -> 0 | G31: =MAX(0,D31-(B31+C31)) -> 1500 | H31: =G31*Inputs!$C$13 -> 330 | I31: =Inputs!$C$10 -> 2463.16 | J31: =I31+G31-H31 -> 3633.16 | K31: =IF(F31>B31,"Advance still growing",IF(F31>0,"Paying it down",IF(G31>0,"CLEARED - real income now","Cleared"))) -> CLEARED - real income now
A32: =EOMONTH(Inputs!$C$59,23) -> 46996 | B32: =F31 -> 0 | C32: =Inputs!$C$9 -> 3000 | D32: =IF(SUMIFS('Deal Log'!$F$9:$F$208,'Deal Log'!$I$9:$I$208,A32,'Deal Log'!$H$9:$H$208,"Funded")>0,SUMIFS('Deal Log'!$F$9:$F$208,'Deal Log'!$I$9:$I$208,A32,'Deal Log'!$H$9:$H$208,"Funded"),Inputs!$C$21) -> 4500 | E32: =MIN(B32+C32,D32) -> 3000 | F32: =MAX(0,B32+C32-D32) -> 0 | G32: =MAX(0,D32-(B32+C32)) -> 1500 | H32: =G32*Inputs!$C$13 -> 330 | I32: =Inputs!$C$10 -> 2463.16 | J32: =I32+G32-H32 -> 3633.16 | K32: =IF(F32>B32,"Advance still growing",IF(F32>0,"Paying it down",IF(G32>0,"CLEARED - real income now","Cleared"))) -> CLEARED - real income now
A33: 24-MONTH TOTAL | C33: =SUM(C9:C32) -> 72000 | D33: =SUM(D9:D32) -> 108000 | E33: =SUM(E9:E32) -> 88500 | G33: =SUM(G9:G32) -> 19500 | H33: =SUM(H9:H32) -> 4290 | I33: =SUM(I9:I32) -> 59115.84 | J33: =SUM(J9:J32) -> 74325.84

Sheet Budget
A1: BUDGET — what your life costs each month
A2: Pulled from Inputs. Change numbers there, not here.
A4: Line | B4: Per month | C4: Per year | D4: Note
A5: Car payment | B5: =Inputs!$C$27 -> 475.69 | C5: =B5*12 -> 5708.28
A6: Car insurance | B6: =Inputs!$C$28 -> 165 | C6: =B6*12 -> 1980 | D6: Estimated - confirm.
A7: Gym (x2/mo) | B7: =Inputs!$C$29*2 -> 63.98 | C7: =B7*12 -> 767.76 | D7: x2
A8: Amazon Prime | B8: =Inputs!$C$30 -> 15 | C8: =B8*12 -> 180 | D8: Annual plan saves ~$41/yr.
A9: Phone | B9: =Inputs!$C$31 -> 60 | C9: =B9*12 -> 720 | D9: Estimated.
A10: Fuel | B10: =Inputs!$C$35 -> 215.78947 | C10: =B10*12 -> 2589.4737 | D10: 1,000 mi at 19 mpg.
A11: Coffee | B11: =Inputs!$C$38 -> 104 | C11: =B11*12 -> 1248
A12: Food | B12: =Inputs!$C$39 -> 400 | C12: =B12*12 -> 4800 | D12: Estimated.
A13: Fun / personal | B13: =Inputs!$C$40 -> 250 | C13: =B13*12 -> 3000 | D13: Estimated.
A14: Car maintenance | B14: =Inputs!$C$41 -> 90 | C14: =B14*12 -> 1080 | D14: Estimated.
A15: LIVING COSTS | B15: =SUM(B5:B14) -> 1839.4595 | C15: =B15*12 -> 22073.514
A16: Marketing | B16: =Inputs!$C$42 -> 1000 | C16: =B16*12 -> 12000 | D16: Zero this if the company pays for it.
A17: TOTAL OUT EACH MONTH | B17: =B15+B16 -> 2839.4595 | C17: =B17*12 -> 34073.514
A19: Your income right now (net draw) | B19: =Inputs!$C$10 -> 2463.16 | C19: =B19*12 -> 29557.92 | D19: Fixed at this until the advance clears - closing more loans does not change it.
A20: LEFT OVER EACH MONTH | B20: =B19-B17 -> -376.29947 | C20: =B20*12 -> -4515.5937 | D20: Negative means the draw does not cover your life. Marketing is the swing factor.
A22: Without marketing, left over is | B22: =B19-B15 -> 623.70053 | D22: If Baxter funds marketing, this is your real monthly surplus.

Sheet Cash Flow
A1: CASH FLOW — what is left after the bills, month by month
A2: Income comes from 'Draw Payback'. Costs come from 'Budget'. Negative months are shaded red.
A4: Average monthly surplus, next 12 months | D4: =AVERAGE(F9:F20) -> -278.79947 | E4: Cash you will have built in 24 months | G4: =G32 -> 6178.8126
A8: Month | B8: Cash to you | C8: Living costs | D8: Marketing | E8: Total out | F8: SURPLUS | G8: Cumulative | H8: Cert transfer | I8: Note
A9: ='Draw Payback'!A9 -> 46295 | B9: ='Draw Payback'!J9 -> 2463.16 | C9: =Budget!$B$15 -> 1839.4595 | D9: =Budget!$B$16 -> 1000 | E9: =C9+D9 -> 2839.4595 | F9: =B9-E9 -> -376.29947 | G9: =F9 -> -376.29947 | H9: =IF(MOD(0,3)=0,Inputs!$C$51,0) -> 1250 | I9: =IF(F9<0,"short - dipping into savings","") -> short - dipping into savings
A10: ='Draw Payback'!A10 -> 46326 | B10: ='Draw Payback'!J10 -> 2463.16 | C10: =Budget!$B$15 -> 1839.4595 | D10: =Budget!$B$16 -> 1000 | E10: =C10+D10 -> 2839.4595 | F10: =B10-E10 -> -376.29947 | G10: =G9+F10 -> -752.59895 | H10: =IF(MOD(1,3)=0,Inputs!$C$51,0) -> 0 | I10: =IF(F10<0,"short - dipping into savings","") -> short - dipping into savings
A11: ='Draw Payback'!A11 -> 46356 | B11: ='Draw Payback'!J11 -> 2463.16 | C11: =Budget!$B$15 -> 1839.4595 | D11: =Budget!$B$16 -> 1000 | E11: =C11+D11 -> 2839.4595 | F11: =B11-E11 -> -376.29947 | G11: =G10+F11 -> -1128.8984 | H11: =IF(MOD(2,3)=0,Inputs!$C$51,0) -> 0 | I11: =IF(F11<0,"short - dipping into savings","") -> short - dipping into savings
A12: ='Draw Payback'!A12 -> 46387 | B12: ='Draw Payback'!J12 -> 2463.16 | C12: =Budget!$B$15 -> 1839.4595 | D12: =Budget!$B$16 -> 1000 | E12: =C12+D12 -> 2839.4595 | F12: =B12-E12 -> -376.29947 | G12: =G11+F12 -> -1505.1979 | H12: =IF(MOD(3,3)=0,Inputs!$C$51,0) -> 1250 | I12: =IF(F12<0,"short - dipping into savings","") -> short - dipping into savings
A13: ='Draw Payback'!A13 -> 46418 | B13: ='Draw Payback'!J13 -> 2463.16 | C13: =Budget!$B$15 -> 1839.4595 | D13: =Budget!$B$16 -> 1000 | E13: =C13+D13 -> 2839.4595 | F13: =B13-E13 -> -376.29947 | G13: =G12+F13 -> -1881.4974 | H13: =IF(MOD(4,3)=0,Inputs!$C$51,0) -> 0 | I13: =IF(F13<0,"short - dipping into savings","") -> short - dipping into savings
A14: ='Draw Payback'!A14 -> 46446 | B14: ='Draw Payback'!J14 -> 2463.16 | C14: =Budget!$B$15 -> 1839.4595 | D14: =Budget!$B$16 -> 1000 | E14: =C14+D14 -> 2839.4595 | F14: =B14-E14 -> -376.29947 | G14: =G13+F14 -> -2257.7968 | H14: =IF(MOD(5,3)=0,Inputs!$C$51,0) -> 0 | I14: =IF(F14<0,"short - dipping into savings","") -> short - dipping into savings
A15: ='Draw Payback'!A15 -> 46477 | B15: ='Draw Payback'!J15 -> 2463.16 | C15: =Budget!$B$15 -> 1839.4595 | D15: =Budget!$B$16 -> 1000 | E15: =C15+D15 -> 2839.4595 | F15: =B15-E15 -> -376.29947 | G15: =G14+F15 -> -2634.0963 | H15: =IF(MOD(6,3)=0,Inputs!$C$51,0) -> 1250 | I15: =IF(F15<0,"short - dipping into savings","") -> short - dipping into savings
A16: ='Draw Payback'!A16 -> 46507 | B16: ='Draw Payback'!J16 -> 2463.16 | C16: =Budget!$B$15 -> 1839.4595 | D16: =Budget!$B$16 -> 1000 | E16: =C16+D16 -> 2839.4595 | F16: =B16-E16 -> -376.29947 | G16: =G15+F16 -> -3010.3958 | H16: =IF(MOD(7,3)=0,Inputs!$C$51,0) -> 0 | I16: =IF(F16<0,"short - dipping into savings","") -> short - dipping into savings
A17: ='Draw Payback'!A17 -> 46538 | B17: ='Draw Payback'!J17 -> 2463.16 | C17: =Budget!$B$15 -> 1839.4595 | D17: =Budget!$B$16 -> 1000 | E17: =C17+D17 -> 2839.4595 | F17: =B17-E17 -> -376.29947 | G17: =G16+F17 -> -3386.6953 | H17: =IF(MOD(8,3)=0,Inputs!$C$51,0) -> 0 | I17: =IF(F17<0,"short - dipping into savings","") -> short - dipping into savings
A18: ='Draw Payback'!A18 -> 46568 | B18: ='Draw Payback'!J18 -> 2463.16 | C18: =Budget!$B$15 -> 1839.4595 | D18: =Budget!$B$16 -> 1000 | E18: =C18+D18 -> 2839.4595 | F18: =B18-E18 -> -376.29947 | G18: =G17+F18 -> -3762.9947 | H18: =IF(MOD(9,3)=0,Inputs!$C$51,0) -> 1250 | I18: =IF(F18<0,"short - dipping into savings","") -> short - dipping into savings
A19: ='Draw Payback'!A19 -> 46599 | B19: ='Draw Payback'!J19 -> 2463.16 | C19: =Budget!$B$15 -> 1839.4595 | D19: =Budget!$B$16 -> 1000 | E19: =C19+D19 -> 2839.4595 | F19: =B19-E19 -> -376.29947 | G19: =G18+F19 -> -4139.2942 | H19: =IF(MOD(10,3)=0,Inputs!$C$51,0) -> 0 | I19: =IF(F19<0,"short - dipping into savings","") -> short - dipping into savings
A20: ='Draw Payback'!A20 -> 46630 | B20: ='Draw Payback'!J20 -> 3633.16 | C20: =Budget!$B$15 -> 1839.4595 | D20: =Budget!$B$16 -> 1000 | E20: =C20+D20 -> 2839.4595 | F20: =B20-E20 -> 793.70053 | G20: =G19+F20 -> -3345.5937 | H20: =IF(MOD(11,3)=0,Inputs!$C$51,0) -> 0 | I20: =IF(F20<0,"short - dipping into savings","")
A21: ='Draw Payback'!A21 -> 46660 | B21: ='Draw Payback'!J21 -> 3633.16 | C21: =Budget!$B$15 -> 1839.4595 | D21: =Budget!$B$16 -> 1000 | E21: =C21+D21 -> 2839.4595 | F21: =B21-E21 -> 793.70053 | G21: =G20+F21 -> -2551.8932 | H21: =IF(MOD(12,3)=0,Inputs!$C$51,0) -> 1250 | I21: =IF(F21<0,"short - dipping into savings","")
A22: ='Draw Payback'!A22 -> 46691 | B22: ='Draw Payback'!J22 -> 3633.16 | C22: =Budget!$B$15 -> 1839.4595 | D22: =Budget!$B$16 -> 1000 | E22: =C22+D22 -> 2839.4595 | F22: =B22-E22 -> 793.70053 | G22: =G21+F22 -> -1758.1926 | H22: =IF(MOD(13,3)=0,Inputs!$C$51,0) -> 0 | I22: =IF(F22<0,"short - dipping into savings","")
A23: ='Draw Payback'!A23 -> 46721 | B23: ='Draw Payback'!J23 -> 3633.16 | C23: =Budget!$B$15 -> 1839.4595 | D23: =Budget!$B$16 -> 1000 | E23: =C23+D23 -> 2839.4595 | F23: =B23-E23 -> 793.70053 | G23: =G22+F23 -> -964.49211 | H23: =IF(MOD(14,3)=0,Inputs!$C$51,0) -> 0 | I23: =IF(F23<0,"short - dipping into savings","")
A24: ='Draw Payback'!A24 -> 46752 | B24: ='Draw Payback'!J24 -> 3633.16 | C24: =Budget!$B$15 -> 1839.4595 | D24: =Budget!$B$16 -> 1000 | E24: =C24+D24 -> 2839.4595 | F24: =B24-E24 -> 793.70053 | G24: =G23+F24 -> -170.79158 | H24: =IF(MOD(15,3)=0,Inputs!$C$51,0) -> 1250 | I24: =IF(F24<0,"short - dipping into savings","")
A25: ='Draw Payback'!A25 -> 46783 | B25: ='Draw Payback'!J25 -> 3633.16 | C25: =Budget!$B$15 -> 1839.4595 | D25: =Budget!$B$16 -> 1000 | E25: =C25+D25 -> 2839.4595 | F25: =B25-E25 -> 793.70053 | G25: =G24+F25 -> 622.90895 | H25: =IF(MOD(16,3)=0,Inputs!$C$51,0) -> 0 | I25: =IF(F25<0,"short - dipping into savings","")
A26: ='Draw Payback'!A26 -> 46812 | B26: ='Draw Payback'!J26 -> 3633.16 | C26: =Budget!$B$15 -> 1839.4595 | D26: =Budget!$B$16 -> 1000 | E26: =C26+D26 -> 2839.4595 | F26: =B26-E26 -> 793.70053 | G26: =G25+F26 -> 1416.6095 | H26: =IF(MOD(17,3)=0,Inputs!$C$51,0) -> 0 | I26: =IF(F26<0,"short - dipping into savings","")
A27: ='Draw Payback'!A27 -> 46843 | B27: ='Draw Payback'!J27 -> 3633.16 | C27: =Budget!$B$15 -> 1839.4595 | D27: =Budget!$B$16 -> 1000 | E27: =C27+D27 -> 2839.4595 | F27: =B27-E27 -> 793.70053 | G27: =G26+F27 -> 2210.31 | H27: =IF(MOD(18,3)=0,Inputs!$C$51,0) -> 1250 | I27: =IF(F27<0,"short - dipping into savings","")
A28: ='Draw Payback'!A28 -> 46873 | B28: ='Draw Payback'!J28 -> 3633.16 | C28: =Budget!$B$15 -> 1839.4595 | D28: =Budget!$B$16 -> 1000 | E28: =C28+D28 -> 2839.4595 | F28: =B28-E28 -> 793.70053 | G28: =G27+F28 -> 3004.0105 | H28: =IF(MOD(19,3)=0,Inputs!$C$51,0) -> 0 | I28: =IF(F28<0,"short - dipping into savings","")
A29: ='Draw Payback'!A29 -> 46904 | B29: ='Draw Payback'!J29 -> 3633.16 | C29: =Budget!$B$15 -> 1839.4595 | D29: =Budget!$B$16 -> 1000 | E29: =C29+D29 -> 2839.4595 | F29: =B29-E29 -> 793.70053 | G29: =G28+F29 -> 3797.7111 | H29: =IF(MOD(20,3)=0,Inputs!$C$51,0) -> 0 | I29: =IF(F29<0,"short - dipping into savings","")
A30: ='Draw Payback'!A30 -> 46934 | B30: ='Draw Payback'!J30 -> 3633.16 | C30: =Budget!$B$15 -> 1839.4595 | D30: =Budget!$B$16 -> 1000 | E30: =C30+D30 -> 2839.4595 | F30: =B30-E30 -> 793.70053 | G30: =G29+F30 -> 4591.4116 | H30: =IF(MOD(21,3)=0,Inputs!$C$51,0) -> 1250 | I30: =IF(F30<0,"short - dipping into savings","")
A31: ='Draw Payback'!A31 -> 46965 | B31: ='Draw Payback'!J31 -> 3633.16 | C31: =Budget!$B$15 -> 1839.4595 | D31: =Budget!$B$16 -> 1000 | E31: =C31+D31 -> 2839.4595 | F31: =B31-E31 -> 793.70053 | G31: =G30+F31 -> 5385.1121 | H31: =IF(MOD(22,3)=0,Inputs!$C$51,0) -> 0 | I31: =IF(F31<0,"short - dipping into savings","")
A32: ='Draw Payback'!A32 -> 46996 | B32: ='Draw Payback'!J32 -> 3633.16 | C32: =Budget!$B$15 -> 1839.4595 | D32: =Budget!$B$16 -> 1000 | E32: =C32+D32 -> 2839.4595 | F32: =B32-E32 -> 793.70053 | G32: =G31+F32 -> 6178.8126 | H32: =IF(MOD(23,3)=0,Inputs!$C$51,0) -> 0 | I32: =IF(F32<0,"short - dipping into savings","")
A33: 24-MONTH TOTAL | B33: =SUM(B9:B32) -> 74325.84 | C33: =SUM(C9:C32) -> 44147.027 | D33: =SUM(D9:D32) -> 24000 | E33: =SUM(E9:E32) -> 68147.027 | F33: =SUM(F9:F32) -> 6178.8126

Sheet Accounts
A1: ACCOUNTS — where the money sits and how it grows
A2: Surplus flows in via the waterfall: checking cushion first, then emergency fund, then the split on 'Money Split'.
A4: Emergency fund target | B4: =Inputs!$C$60*Budget!B17 -> 17036.757 | C4: =Inputs!$C$60&" months of total costs" -> 6 months of total costs
A8: Month | B8: Surplus | C8: Checking | D8: HYSA / emergency | E8: Certificate | F8: Ring / travel | G8: Roth IRA | H8: Auto loan | I8: TOTAL SAVED | J8: NET WORTH
A9: ='Cash Flow'!A9 -> 46295 | B9: ='Cash Flow'!F9 -> -376.29947 | C9: =Inputs!$C$44+IF(B9<0,B9,MIN(B9,Inputs!$C$45-Inputs!$C$44)) -> 19.100526 | D9: =Inputs!$C$46*(1+Inputs!$C$47/12)+IF(Inputs!$C$46<Inputs!$C$60*Budget!B17,MAX(0,B9-(C9-Inputs!$C$44)),MAX(0,B9-(C9-Inputs!$C$44))*0.30)-'Cash Flow'!H9 -> 7176.8963 | E9: =Inputs!$C$48*(1+Inputs!$C$49/12)+'Cash Flow'!H9 -> 7792.751 | F9: =Inputs!$C$52+IF(Inputs!$C$46>=Inputs!$C$60*Budget!B17,MAX(0,B9-(C9-Inputs!$C$44))*0.25,0) -> 0 | G9: =Inputs!$C$53+IF(Inputs!$C$46>=Inputs!$C$60*Budget!B17,MAX(0,B9-(C9-Inputs!$C$44))*0.25,0) -> 0 | H9: ='Car Loan'!F9 -> 24772.946 | I9: =C9+D9+E9+F9+G9 -> 14988.748 | J9: =I9-H9 -> -9784.1981
A10: ='Cash Flow'!A10 -> 46326 | B10: ='Cash Flow'!F10 -> -376.29947 | C10: =C9+IF(B10<0,B10,MIN(B10,Inputs!$C$45-C9)) -> -357.19895 | D10: =D9*(1+Inputs!$C$47/12)+IF(D9<Inputs!$C$60*Budget!B17,MAX(0,B10-(C10-C9)),MAX(0,B10-(C10-C9))*0.30)-'Cash Flow'!H10 -> 7200.8193 | E10: =E9*(1+Inputs!$C$49/12)+'Cash Flow'!H10 -> 7816.6943 | F10: =F9+IF(D9>=Inputs!$C$60*Budget!B17,MAX(0,B10-(C10-C9))*0.25,0) -> 0 | G10: =G9*(1+0.08/12)+IF(D9>=Inputs!$C$60*Budget!B17,MAX(0,B10-(C10-C9))*0.25,0) -> 0 | H10: ='Car Loan'!F10 -> 24451.88 | I10: =C10+D10+E10+F10+G10 -> 14660.315 | J10: =I10-H10 -> -9791.5659
A11: ='Cash Flow'!A11 -> 46356 | B11: ='Cash Flow'!F11 -> -376.29947 | C11: =C10+IF(B11<0,B11,MIN(B11,Inputs!$C$45-C10)) -> -733.49842 | D11: =D10*(1+Inputs!$C$47/12)+IF(D10<Inputs!$C$60*Budget!B17,MAX(0,B11-(C11-C10)),MAX(0,B11-(C11-C10))*0.30)-'Cash Flow'!H11 -> 7224.8221 | E11: =E10*(1+Inputs!$C$49/12)+'Cash Flow'!H11 -> 7840.711 | F11: =F10+IF(D10>=Inputs!$C$60*Budget!B17,MAX(0,B11-(C11-C10))*0.25,0) -> 0 | G11: =G10*(1+0.08/12)+IF(D10>=Inputs!$C$60*Budget!B17,MAX(0,B11-(C11-C10))*0.25,0) -> 0 | H11: ='Car Loan'!F11 -> 24128.811 | I11: =C11+D11+E11+F11+G11 -> 14332.035 | J11: =I11-H11 -> -9796.7763
A12: ='Cash Flow'!A12 -> 46387 | B12: ='Cash Flow'!F12 -> -376.29947 | C12: =C11+IF(B12<0,B12,MIN(B12,Inputs!$C$45-C11)) -> -1109.7979 | D12: =D11*(1+Inputs!$C$47/12)+IF(D11<Inputs!$C$60*Budget!B17,MAX(0,B12-(C12-C11)),MAX(0,B12-(C12-C11))*0.30)-'Cash Flow'!H12 -> 5998.9048 | E12: =E11*(1+Inputs!$C$49/12)+'Cash Flow'!H12 -> 9114.8016 | F12: =F11+IF(D11>=Inputs!$C$60*Budget!B17,MAX(0,B12-(C12-C11))*0.25,0) -> 0 | G12: =G11*(1+0.08/12)+IF(D11>=Inputs!$C$60*Budget!B17,MAX(0,B12-(C12-C11))*0.25,0) -> 0 | H12: ='Car Loan'!F12 -> 23803.725 | I12: =C12+D12+E12+F12+G12 -> 14003.909 | J12: =I12-H12 -> -9799.8164
A13: ='Cash Flow'!A13 -> 46418 | B13: ='Cash Flow'!F13 -> -376.29947 | C13: =C12+IF(B13<0,B13,MIN(B13,Inputs!$C$45-C12)) -> -1486.0974 | D13: =D12*(1+Inputs!$C$47/12)+IF(D12<Inputs!$C$60*Budget!B17,MAX(0,B13-(C13-C12)),MAX(0,B13-(C13-C12))*0.30)-'Cash Flow'!H13 -> 6018.9011 | E13: =E12*(1+Inputs!$C$49/12)+'Cash Flow'!H13 -> 9142.8069 | F13: =F12+IF(D12>=Inputs!$C$60*Budget!B17,MAX(0,B13-(C13-C12))*0.25,0) -> 0 | G13: =G12*(1+0.08/12)+IF(D12>=Inputs!$C$60*Budget!B17,MAX(0,B13-(C13-C12))*0.25,0) -> 0 | H13: ='Car Loan'!F13 -> 23476.61 | I13: =C13+D13+E13+F13+G13 -> 13675.611 | J13: =I13-H13 -> -9800.9993
A14: ='Cash Flow'!A14 -> 46446 | B14: ='Cash Flow'!F14 -> -376.29947 | C14: =C13+IF(B14<0,B14,MIN(B14,Inputs!$C$45-C13)) -> -1862.3968 | D14: =D13*(1+Inputs!$C$47/12)+IF(D13<Inputs!$C$60*Budget!B17,MAX(0,B14-(C14-C13)),MAX(0,B14-(C14-C13))*0.30)-'Cash Flow'!H14 -> 6038.9641 | E14: =E13*(1+Inputs!$C$49/12)+'Cash Flow'!H14 -> 9170.8981 | F14: =F13+IF(D13>=Inputs!$C$60*Budget!B17,MAX(0,B14-(C14-C13))*0.25,0) -> 0 | G14: =G13*(1+0.08/12)+IF(D13>=Inputs!$C$60*Budget!B17,MAX(0,B14-(C14-C13))*0.25,0) -> 0 | H14: ='Car Loan'!F14 -> 23147.453 | I14: =C14+D14+E14+F14+G14 -> 13347.465 | J14: =I14-H14 -> -9799.9876
A15: ='Cash Flow'!A15 -> 46477 | B15: ='Cash Flow'!F15 -> -376.29947 | C15: =C14+IF(B15<0,B15,MIN(B15,Inputs!$C$45-C14)) -> -2238.6963 | D15: =D14*(1+Inputs!$C$47/12)+IF(D14<Inputs!$C$60*Budget!B17,MAX(0,B15-(C15-C14)),MAX(0,B15-(C15-C14))*0.30)-'Cash Flow'!H15 -> 4809.094 | E15: =E14*(1+Inputs!$C$49/12)+'Cash Flow'!H15 -> 10449.076 | F15: =F14+IF(D14>=Inputs!$C$60*Budget!B17,MAX(0,B15-(C15-C14))*0.25,0) -> 0 | G15: =G14*(1+0.08/12)+IF(D14>=Inputs!$C$60*Budget!B17,MAX(0,B15-(C15-C14))*0.25,0) -> 0 | H15: ='Car Loan'!F15 -> 22816.242 | I15: =C15+D15+E15+F15+G15 -> 13019.473 | J15: =I15-H15 -> -9796.7683
A16: ='Cash Flow'!A16 -> 46507 | B16: ='Cash Flow'!F16 -> -376.29947 | C16: =C15+IF(B16<0,B16,MIN(B16,Inputs!$C$45-C15)) -> -2614.9958 | D16: =D15*(1+Inputs!$C$47/12)+IF(D15<Inputs!$C$60*Budget!B17,MAX(0,B16-(C16-C15)),MAX(0,B16-(C16-C15))*0.30)-'Cash Flow'!H16 -> 4825.1243 | E16: =E15*(1+Inputs!$C$49/12)+'Cash Flow'!H16 -> 10481.181 | F16: =F15+IF(D15>=Inputs!$C$60*Budget!B17,MAX(0,B16-(C16-C15))*0.25,0) -> 0 | G16: =G15*(1+0.08/12)+IF(D15>=Inputs!$C$60*Budget!B17,MAX(0,B16-(C16-C15))*0.25,0) -> 0 | H16: ='Car Loan'!F16 -> 22482.963 | I16: =C16+D16+E16+F16+G16 -> 12691.309 | J16: =I16-H16 -> -9791.6541
A17: ='Cash Flow'!A17 -> 46538 | B17: ='Cash Flow'!F17 -> -376.29947 | C17: =C16+IF(B17<0,B17,MIN(B17,Inputs!$C$45-C16)) -> -2991.2953 | D17: =D16*(1+Inputs!$C$47/12)+IF(D16<Inputs!$C$60*Budget!B17,MAX(0,B17-(C17-C16)),MAX(0,B17-(C17-C16))*0.30)-'Cash Flow'!H17 -> 4841.2081 | E17: =E16*(1+Inputs!$C$49/12)+'Cash Flow'!H17 -> 10513.384 | F17: =F16+IF(D16>=Inputs!$C$60*Budget!B17,MAX(0,B17-(C17-C16))*0.25,0) -> 0 | G17: =G16*(1+0.08/12)+IF(D16>=Inputs!$C$60*Budget!B17,MAX(0,B17-(C17-C16))*0.25,0) -> 0 | H17: ='Car Loan'!F17 -> 22147.604 | I17: =C17+D17+E17+F17+G17 -> 12363.297 | J17: =I17-H17 -> -9784.3075
A18: ='Cash Flow'!A18 -> 46568 | B18: ='Cash Flow'!F18 -> -376.29947 | C18: =C17+IF(B18<0,B18,MIN(B18,Inputs!$C$45-C17)) -> -3367.5947 | D18: =D17*(1+Inputs!$C$47/12)+IF(D17<Inputs!$C$60*Budget!B17,MAX(0,B18-(C18-C17)),MAX(0,B18-(C18-C17))*0.30)-'Cash Flow'!H18 -> 3607.3454 | E18: =E17*(1+Inputs!$C$49/12)+'Cash Flow'!H18 -> 11795.686 | F18: =F17+IF(D17>=Inputs!$C$60*Budget!B17,MAX(0,B18-(C18-C17))*0.25,0) -> 0 | G18: =G17*(1+0.08/12)+IF(D17>=Inputs!$C$60*Budget!B17,MAX(0,B18-(C18-C17))*0.25,0) -> 0 | H18: ='Car Loan'!F18 -> 21810.152 | I18: =C18+D18+E18+F18+G18 -> 12035.437 | J18: =I18-H18 -> -9774.7152
A19: ='Cash Flow'!A19 -> 46599 | B19: ='Cash Flow'!F19 -> -376.29947 | C19: =C18+IF(B19<0,B19,MIN(B19,Inputs!$C$45-C18)) -> -3743.8942 | D19: =D18*(1+Inputs!$C$47/12)+IF(D18<Inputs!$C$60*Budget!B17,MAX(0,B19-(C19-C18)),MAX(0,B19-(C19-C18))*0.30)-'Cash Flow'!H19 -> 3619.3699 | E19: =E18*(1+Inputs!$C$49/12)+'Cash Flow'!H19 -> 11831.929 | F19: =F18+IF(D18>=Inputs!$C$60*Budget!B17,MAX(0,B19-(C19-C18))*0.25,0) -> 0 | G19: =G18*(1+0.08/12)+IF(D18>=Inputs!$C$60*Budget!B17,MAX(0,B19-(C19-C18))*0.25,0) -> 0 | H19: ='Car Loan'!F19 -> 21470.594 | I19: =C19+D19+E19+F19+G19 -> 11707.404 | J19: =I19-H19 -> -9763.1897
A20: ='Cash Flow'!A20 -> 46630 | B20: ='Cash Flow'!F20 -> 793.70053 | C20: =C19+IF(B20<0,B20,MIN(B20,Inputs!$C$45-C19)) -> -2950.1937 | D20: =D19*(1+Inputs!$C$47/12)+IF(D19<Inputs!$C$60*Budget!B17,MAX(0,B20-(C20-C19)),MAX(0,B20-(C20-C19))*0.30)-'Cash Flow'!H20 -> 3631.4345 | E20: =E19*(1+Inputs!$C$49/12)+'Cash Flow'!H20 -> 11868.282 | F20: =F19+IF(D19>=Inputs!$C$60*Budget!B17,MAX(0,B20-(C20-C19))*0.25,0) -> 0 | G20: =G19*(1+0.08/12)+IF(D19>=Inputs!$C$60*Budget!B17,MAX(0,B20-(C20-C19))*0.25,0) -> 0 | H20: ='Car Loan'!F20 -> 21128.916 | I20: =C20+D20+E20+F20+G20 -> 12549.523 | J20: =I20-H20 -> -8579.3933
A21: ='Cash Flow'!A21 -> 46660 | B21: ='Cash Flow'!F21 -> 793.70053 | C21: =C20+IF(B21<0,B21,MIN(B21,Inputs!$C$45-C20)) -> -2156.4932 | D21: =D20*(1+Inputs!$C$47/12)+IF(D20<Inputs!$C$60*Budget!B17,MAX(0,B21-(C21-C20)),MAX(0,B21-(C21-C20))*0.30)-'Cash Flow'!H21 -> 2393.5393 | E21: =E20*(1+Inputs!$C$49/12)+'Cash Flow'!H21 -> 13154.747 | F21: =F20+IF(D20>=Inputs!$C$60*Budget!B17,MAX(0,B21-(C21-C20))*0.25,0) -> 0 | G21: =G20*(1+0.08/12)+IF(D20>=Inputs!$C$60*Budget!B17,MAX(0,B21-(C21-C20))*0.25,0) -> 0 | H21: ='Car Loan'!F21 -> 20785.106 | I21: =C21+D21+E21+F21+G21 -> 13391.794 | J21: =I21-H21 -> -7393.3123
A22: ='Cash Flow'!A22 -> 46691 | B22: ='Cash Flow'!F22 -> 793.70053 | C22: =C21+IF(B22<0,B22,MIN(B22,Inputs!$C$45-C21)) -> -1362.7926 | D22: =D21*(1+Inputs!$C$47/12)+IF(D21<Inputs!$C$60*Budget!B17,MAX(0,B22-(C22-C21)),MAX(0,B22-(C22-C21))*0.30)-'Cash Flow'!H22 -> 2401.5177 | E22: =E21*(1+Inputs!$C$49/12)+'Cash Flow'!H22 -> 13195.165 | F22: =F21+IF(D21>=Inputs!$C$60*Budget!B17,MAX(0,B22-(C22-C21))*0.25,0) -> 0 | G22: =G21*(1+0.08/12)+IF(D21>=Inputs!$C$60*Budget!B17,MAX(0,B22-(C22-C21))*0.25,0) -> 0 | H22: ='Car Loan'!F22 -> 20439.15 | I22: =C22+D22+E22+F22+G22 -> 14233.891 | J22: =I22-H22 -> -6205.2591
A23: ='Cash Flow'!A23 -> 46721 | B23: ='Cash Flow'!F23 -> 793.70053 | C23: =C22+IF(B23<0,B23,MIN(B23,Inputs!$C$45-C22)) -> -569.09211 | D23: =D22*(1+Inputs!$C$47/12)+IF(D22<Inputs!$C$60*Budget!B17,MAX(0,B23-(C23-C22)),MAX(0,B23-(C23-C22))*0.30)-'Cash Flow'!H23 -> 2409.5228 | E23: =E22*(1+Inputs!$C$49/12)+'Cash Flow'!H23 -> 13235.708 | F23: =F22+IF(D22>=Inputs!$C$60*Budget!B17,MAX(0,B23-(C23-C22))*0.25,0) -> 0 | G23: =G22*(1+0.08/12)+IF(D22>=Inputs!$C$60*Budget!B17,MAX(0,B23-(C23-C22))*0.25,0) -> 0 | H23: ='Car Loan'!F23 -> 20091.034 | I23: =C23+D23+E23+F23+G23 -> 15076.138 | J23: =I23-H23 -> -5014.8957
A24: ='Cash Flow'!A24 -> 46752 | B24: ='Cash Flow'!F24 -> 793.70053 | C24: =C23+IF(B24<0,B24,MIN(B24,Inputs!$C$45-C23)) -> 224.60842 | D24: =D23*(1+Inputs!$C$47/12)+IF(D23<Inputs!$C$60*Budget!B17,MAX(0,B24-(C24-C23)),MAX(0,B24-(C24-C23))*0.30)-'Cash Flow'!H24 -> 1167.5545 | E24: =E23*(1+Inputs!$C$49/12)+'Cash Flow'!H24 -> 14526.374 | F24: =F23+IF(D23>=Inputs!$C$60*Budget!B17,MAX(0,B24-(C24-C23))*0.25,0) -> 0 | G24: =G23*(1+0.08/12)+IF(D23>=Inputs!$C$60*Budget!B17,MAX(0,B24-(C24-C23))*0.25,0) -> 0 | H24: ='Car Loan'!F24 -> 19740.745 | I24: =C24+D24+E24+F24+G24 -> 15918.537 | J24: =I24-H24 -> -3822.2083
A25: ='Cash Flow'!A25 -> 46783 | B25: ='Cash Flow'!F25 -> 793.70053 | C25: =C24+IF(B25<0,B25,MIN(B25,Inputs!$C$45-C24)) -> 1018.3089 | D25: =D24*(1+Inputs!$C$47/12)+IF(D24<Inputs!$C$60*Budget!B17,MAX(0,B25-(C25-C24)),MAX(0,B25-(C25-C24))*0.30)-'Cash Flow'!H25 -> 1171.4464 | E25: =E24*(1+Inputs!$C$49/12)+'Cash Flow'!H25 -> 14571.007 | F25: =F24+IF(D24>=Inputs!$C$60*Budget!B17,MAX(0,B25-(C25-C24))*0.25,0) -> 0 | G25: =G24*(1+0.08/12)+IF(D24>=Inputs!$C$60*Budget!B17,MAX(0,B25-(C25-C24))*0.25,0) -> 0 | H25: ='Car Loan'!F25 -> 19388.271 | I25: =C25+D25+E25+F25+G25 -> 16760.762 | J25: =I25-H25 -> -2627.5088
A26: ='Cash Flow'!A26 -> 46812 | B26: ='Cash Flow'!F26 -> 793.70053 | C26: =C25+IF(B26<0,B26,MIN(B26,Inputs!$C$45-C25)) -> 1812.0095 | D26: =D25*(1+Inputs!$C$47/12)+IF(D25<Inputs!$C$60*Budget!B17,MAX(0,B26-(C26-C25)),MAX(0,B26-(C26-C25))*0.30)-'Cash Flow'!H26 -> 1175.3512 | E26: =E25*(1+Inputs!$C$49/12)+'Cash Flow'!H26 -> 14615.776 | F26: =F25+IF(D25>=Inputs!$C$60*Budget!B17,MAX(0,B26-(C26-C25))*0.25,0) -> 0 | G26: =G25*(1+0.08/12)+IF(D25>=Inputs!$C$60*Budget!B17,MAX(0,B26-(C26-C25))*0.25,0) -> 0 | H26: ='Car Loan'!F26 -> 19033.596 | I26: =C26+D26+E26+F26+G26 -> 17603.137 | J26: =I26-H26 -> -1430.4591
A27: ='Cash Flow'!A27 -> 46843 | B27: ='Cash Flow'!F27 -> 793.70053 | C27: =C26+IF(B27<0,B27,MIN(B27,Inputs!$C$45-C26)) -> 2000 | D27: =D26*(1+Inputs!$C$47/12)+IF(D26<Inputs!$C$60*Budget!B17,MAX(0,B27-(C27-C26)),MAX(0,B27-(C27-C26))*0.30)-'Cash Flow'!H27 -> 534.97905 | E27: =E26*(1+Inputs!$C$49/12)+'Cash Flow'!H27 -> 15910.683 | F27: =F26+IF(D26>=Inputs!$C$60*Budget!B17,MAX(0,B27-(C27-C26))*0.25,0) -> 0 | G27: =G26*(1+0.08/12)+IF(D26>=Inputs!$C$60*Budget!B17,MAX(0,B27-(C27-C26))*0.25,0) -> 0 | H27: ='Car Loan'!F27 -> 18676.707 | I27: =C27+D27+E27+F27+G27 -> 18445.662 | J27: =I27-H27 -> -231.04514
A28: ='Cash Flow'!A28 -> 46873 | B28: ='Cash Flow'!F28 -> 793.70053 | C28: =C27+IF(B28<0,B28,MIN(B28,Inputs!$C$45-C27)) -> 2000 | D28: =D27*(1+Inputs!$C$47/12)+IF(D27<Inputs!$C$60*Budget!B17,MAX(0,B28-(C28-C27)),MAX(0,B28-(C28-C27))*0.30)-'Cash Flow'!H28 -> 1330.4628 | E28: =E27*(1+Inputs!$C$49/12)+'Cash Flow'!H28 -> 15959.569 | F28: =F27+IF(D27>=Inputs!$C$60*Budget!B17,MAX(0,B28-(C28-C27))*0.25,0) -> 0 | G28: =G27*(1+0.08/12)+IF(D27>=Inputs!$C$60*Budget!B17,MAX(0,B28-(C28-C27))*0.25,0) -> 0 | H28: ='Car Loan'!F28 -> 18317.591 | I28: =C28+D28+E28+F28+G28 -> 19290.031 | J28: =I28-H28 -> 972.44044
A29: ='Cash Flow'!A29 -> 46904 | B29: ='Cash Flow'!F29 -> 793.70053 | C29: =C28+IF(B29<0,B29,MIN(B29,Inputs!$C$45-C28)) -> 2000 | D29: =D28*(1+Inputs!$C$47/12)+IF(D28<Inputs!$C$60*Budget!B17,MAX(0,B29-(C29-C28)),MAX(0,B29-(C29-C28))*0.30)-'Cash Flow'!H29 -> 2128.5982 | E29: =E28*(1+Inputs!$C$49/12)+'Cash Flow'!H29 -> 16008.604 | F29: =F28+IF(D28>=Inputs!$C$60*Budget!B17,MAX(0,B29-(C29-C28))*0.25,0) -> 0 | G29: =G28*(1+0.08/12)+IF(D28>=Inputs!$C$60*Budget!B17,MAX(0,B29-(C29-C28))*0.25,0) -> 0 | H29: ='Car Loan'!F29 -> 17956.233 | I29: =C29+D29+E29+F29+G29 -> 20137.203 | J29: =I29-H29 -> 2180.9693
A30: ='Cash Flow'!A30 -> 46934 | B30: ='Cash Flow'!F30 -> 793.70053 | C30: =C29+IF(B30<0,B30,MIN(B30,Inputs!$C$45-C29)) -> 2000 | D30: =D29*(1+Inputs!$C$47/12)+IF(D29<Inputs!$C$60*Budget!B17,MAX(0,B30-(C30-C29)),MAX(0,B30-(C30-C29))*0.30)-'Cash Flow'!H30 -> 1679.3941 | E30: =E29*(1+Inputs!$C$49/12)+'Cash Flow'!H30 -> 17307.791 | F30: =F29+IF(D29>=Inputs!$C$60*Budget!B17,MAX(0,B30-(C30-C29))*0.25,0) -> 0 | G30: =G29*(1+0.08/12)+IF(D29>=Inputs!$C$60*Budget!B17,MAX(0,B30-(C30-C29))*0.25,0) -> 0 | H30: ='Car Loan'!F30 -> 17592.62 | I30: =C30+D30+E30+F30+G30 -> 20987.185 | J30: =I30-H30 -> 3394.5648
A31: ='Cash Flow'!A31 -> 46965 | B31: ='Cash Flow'!F31 -> 793.70053 | C31: =C30+IF(B31<0,B31,MIN(B31,Inputs!$C$45-C30)) -> 2000 | D31: =D30*(1+Inputs!$C$47/12)+IF(D30<Inputs!$C$60*Budget!B17,MAX(0,B31-(C31-C30)),MAX(0,B31-(C31-C30))*0.30)-'Cash Flow'!H31 -> 2478.6926 | E31: =E30*(1+Inputs!$C$49/12)+'Cash Flow'!H31 -> 17360.969 | F31: =F30+IF(D30>=Inputs!$C$60*Budget!B17,MAX(0,B31-(C31-C30))*0.25,0) -> 0 | G31: =G30*(1+0.08/12)+IF(D30>=Inputs!$C$60*Budget!B17,MAX(0,B31-(C31-C30))*0.25,0) -> 0 | H31: ='Car Loan'!F31 -> 17226.737 | I31: =C31+D31+E31+F31+G31 -> 21839.662 | J31: =I31-H31 -> 4612.9242
A32: ='Cash Flow'!A32 -> 46996 | B32: ='Cash Flow'!F32 -> 793.70053 | C32: =C31+IF(B32<0,B32,MIN(B32,Inputs!$C$45-C31)) -> 2000 | D32: =D31*(1+Inputs!$C$47/12)+IF(D31<Inputs!$C$60*Budget!B17,MAX(0,B32-(C32-C31)),MAX(0,B32-(C32-C31))*0.30)-'Cash Flow'!H32 -> 3280.6554 | E32: =E31*(1+Inputs!$C$49/12)+'Cash Flow'!H32 -> 17414.31 | F32: =F31+IF(D31>=Inputs!$C$60*Budget!B17,MAX(0,B32-(C32-C31))*0.25,0) -> 0 | G32: =G31*(1+0.08/12)+IF(D31>=Inputs!$C$60*Budget!B17,MAX(0,B32-(C32-C31))*0.25,0) -> 0 | H32: ='Car Loan'!F32 -> 16858.571 | I32: =C32+D32+E32+F32+G32 -> 22694.966 | J32: =I32-H32 -> 5836.3951

Sheet Money Split
A1: MONEY SPLIT — what to do the day money lands
A2: Two situations: while the advance is outstanding, and after it clears. Right now you are in the first one.
A4: WHILE THE ADVANCE IS OUTSTANDING
A5: ="Your paycheck is "&TEXT(Inputs!$C$10,"$#,##0.00")&" a month, every month, no matter what closes. Commission never touches your bank - it goes straight to the balance. So the only lever you have right now is spending, and the plan is simple:" -> Your paycheck is $2,463.16 a month, every month, no matter what closes. Commission never touches your bank - it goes straight to the balance. So the only lever you have right now is spending, and the plan is simple:
A6: 1. Checking to $2,000 | B6: =MAX(0,Inputs!$C$45-Inputs!$C$44) -> 1604.6 | E6: You're at $395.40 with $865.84 due by 10/14. Nothing else matters until this is fixed.
A7: 2. Everything spare to the emergency fund | B7: =MAX(0,Budget!B20) -> 0 | E7: Whatever the budget leaves over. If that is negative, cut marketing first - it is the only truly optional line.
A8: 3. Open the Roth and the ring account now | B8: =0 -> 0 | E8: Even at $25/month. Opening them is the hard part; funding them is easy later.
A10: AFTER THE ADVANCE CLEARS — when a real commission check arrives
A11: Commission check (gross) | B11: 4500 | C11: <- type it here
A12: Step | B12: Amount | C12: Running left | E12: Why
A13: Withholding (taken before you see it) | B13: =$B$11*Inputs!$C$13 -> 990 | C13: =$B$11-B13 -> 3510 | E13: 22% federal supplemental plus state. Already gone - just don't count it as yours.
A14: 1. Top checking back to the cushion | B14: =MIN(C13,MAX(0,Inputs!$C$45-Inputs!$C$44)) -> 1604.6 | C14: =C13-B14 -> 1905.4 | E14: Every single time. It is the buffer that stops a slow month becoming credit card debt.
A15: 2. Emergency fund until full | B15: =MIN(C14,MAX(0,Accounts!$B$4-Inputs!$C$46)) -> 1905.4 | C15: =C14-B15 -> 0 | E15: 6 months of costs. Your income has no floor above the draw, so this is your only shock absorber.
A16: 3. Roth IRA | B16: =C15*0.30 -> 0 | C16: =C15-B16 -> 0 | E16: You're 25 with $0 invested. $7,000/yr at 8% to age 65 is about $1.8M. One year of delay costs roughly $145,000.
A17: 4. Ring / travel | B17: =C16*0.30 -> 0 | C17: =C16-B17 -> 0 | E17: Dated goal ~2 years out. Cash only - never invest money you need inside three years.
A18: 5. House fund | B18: =C17*0.25 -> 0 | C18: =C17-B18 -> 0 | E18: Separate account so you can watch both clocks.
A19: 6. Guilt-free | B19: =C18*1.00 -> 0 | C19: =C18-B19 -> 0 | E19: Non-negotiable. A budget with no fun in it gets abandoned in about six weeks.

Sheet Goals
A1: GOALS
A2: Set the target and the date; it tells you the monthly cost. The GAP row is the honest bit.
A5: Goal | B5: Target | C5: By when | D5: Months | E5: Have now | F5: Need/month | G5: Note
A6: Clear the draw advance | B6: =Inputs!$C$17 -> 16500 | C6: =EDATE(Inputs!$C$59,12) -> 46640 | D6: =MAX(1,ROUND((C6-Inputs!$C$59)/30.44,0)) -> 12 | E6: =0 -> 0 | F6: =MAX(0,B6-E6)/D6 -> 1375 | G6: Comes out of commission, not out of your budget. It is the gate on everything else.
A7: Checking cushion | B7: =Inputs!$C$45 -> 2000 | C7: =EDATE(Inputs!$C$59,2) -> 46336 | D7: =MAX(1,ROUND((C7-Inputs!$C$59)/30.44,0)) -> 2 | E7: =Inputs!$C$44 -> 395.4 | F7: =MAX(0,B7-E7)/D7 -> 802.3 | G7: Most urgent thing on this page.
A8: Emergency fund | B8: =Inputs!$C$60*Budget!B17 -> 17036.757 | C8: =EDATE(Inputs!$C$59,18) -> 46822 | D8: =MAX(1,ROUND((C8-Inputs!$C$59)/30.44,0)) -> 18 | E8: =Inputs!$C$46 -> 8398.9 | F8: =MAX(0,B8-E8)/D8 -> 479.88094 | G8: Your HYSA already covers a lot of this.
