Workbook

Sheet Start Here
A1: START HERE
A2: Derek Smith · Baxter Mortgage · built September 2026
A4: HOW TO USE IT
A5: Inputs | B5: Fix every YELLOW cell — those are numbers I had to guess. Blue cells are yours to change.
A6: Budget | B6: What the draw covers and what it doesn't. Right now this is your whole financial picture.
A7: Deal Log | B7: One row per closing. Your 75 bps calculates itself. Delete the example row first.
A8: Scenarios | B8: What take-home looks like at 0-6 loans a month, under each comp structure.
A9: Goals | B9: Set targets and dates; it tells you the monthly cost.
A10: Money Split | B10: A check landed — type the amount, follow the steps.
A11: THE FIVE THINGS THAT MATTER
A12: 1. Ask the owner three questions | B12: In writing: (a) Is the draw recoverable? (b) Am I W-2 or 1099? (c) If recoverable, does the WHOLE commission go to the advance or only part? You raised (c) yourself and it's the right question — it's the 'recapture %' dial on Inputs. Nothing else in this file is reliable until you have all three answers.
A13: 2. You get 24 paychecks a year, not 26 | B13: Your dates are the 15th and month-end — semi-monthly. That's $29,557.92/yr, not $32,021.08. If you'd been planning on 26 you were overstating your income by about $2,463 a year.
A14: 3. Fix checking first | B14: $395.40 on hand, $390.15 due 10/7 and $475.69 due 10/14. That's an overdraft risk in the next month, and a late payment now would undo a lot of credit work.
A15: 4. One loan a month doesn't move the needle | B15: A $300k loan pays you $2,250. Your monthly draw is $2,463.16. Under a 'greater of' structure, closing one loan in a month is worth literally nothing extra. You need roughly 1.1 loans a month before commission beats the draw at all — and more than that before it beats your costs.
A16: 5. Open the two accounts that don't exist yet | B16: A Roth IRA and a separate named savings account for the ring. Both show $0 because neither exists. Being 25 with $0 invested is the one thing here that gets more expensive every month you wait.
A17: ON YOUR CREDIT CARD QUESTION
A18: Pay in full — but pay twice | B18: Carrying a balance does NOT build credit; it just costs you interest. But your card reports the balance on the STATEMENT CLOSING date, not the due date. So pay it down to about 5% of your limit a few days before the statement closes, let that small balance report, then pay the rest by the 7th. Zero interest, near-perfect utilization. You have only 2 credit lines — also ask a parent to add you as an authorized user on their oldest card, and request a limit increase. Then stop opening things 12 months before you apply for a mortgage.
A19: WHAT I GUESSED
A20: Confirm these | B20: Car insurance $165, phone $60, food $400, fun $250, car maintenance $90, savings rate 4.00%, credit limit $5,000. Also: health insurance is set to $0 because I assumed you're on a parent's plan — you age off at 26, which is about a year away, and that's $350-500/mo landing in an already-tight budget.
A21: Not advice | B21: A planning model built from the numbers you gave me. Not tax, legal or investment advice — confirm your comp structure with the owner and your tax status with a CPA.

Sheet Inputs
A1: YOUR NUMBERS
A2: Edit the BLUE cells. YELLOW = I guessed, please confirm.
A4: WHAT YOU MAKE RIGHT NOW
A5: Draw per paycheck | B5: 1231.58 | C5: $
A6: Paychecks per year | B6: 24 | C6: /yr | D6: 24, not 26. Your dates (3/31, 4/15, 4/30, 5/15, 5/29, 6/15, 6/30, 7/16, 7/30, 8/14, 8/28) are the 15th + month-end. Semi-monthly.
A7: MONTHLY INCOME (draw only) | B7: =B5*B6/12 | C7: $/mo | D7: This is all you're making until commissions start landing.
A8: Annual draw | B8: =B5*B6 | C8: $/yr
A9: Draws received so far | B9: 11 | C9: checks
A10: Draw dollars taken to date | B10: =B5*B9 | C10: $ | D10: If the draw is RECOVERABLE, this is what you owe back before commission reaches you.
A11: Is the draw recoverable? | B11: Yes | C11: Yes/No | D11: ASK THE OWNER IN WRITING. Yes = you repay it from commissions. No = it's yours.
A12: Your commission | B12: 0.0075 | C12: of loan | D12: 75 bps. Doesn't change whether the company charges 275, 200 or 150.
A13: WHAT YOU SPEND
A14: Car payment | B14: 475.69 | C14: $/mo | D14: Due the 14th.
A15: Gym (per charge x2/mo) | B15: 31.99 | C15: $/charge | D15: Mid-month + last day = 24/yr.
A16: Amazon Prime | B16: 15 | C16: $/mo | D16: Annual plan is ~$11.58/mo. Saves $41/yr.
A17: Car insurance | B17: 165 | C17: $/mo | D17: YOU DIDN'T LIST THIS but your lender requires it. Put your real premium in.
A18: Phone | B18: 60 | C18: $/mo | D18: NOT LISTED. Set to 0 if you're on a family plan.
A19: Miles driven | B19: 1000 | C19: mi/mo
A20: Gas price | B20: 4.1 | C20: $/gal
A21: MPG | B21: 19 | C21: mpg | D21: Middle of the 18-20 you gave.
A22: = Fuel | B22: =B19/B21*B20 | C22: $/mo
A23: Aroma Joes per visit | B23: 6 | C23: $
A24: visits per week | B24: 4 | C24: /wk | D24: 4/wk = $1,248/yr. Just so you can see it.
A25: = Coffee | B25: =B23*B24*52/12 | C25: $/mo
A26: Food / eating out | B26: 400 | C26: $/mo | D26: NOT LISTED. You live at home so this may be lower.
A27: Personal / fun | B27: 250 | C27: $/mo | D27: NOT LISTED.
A28: Car maintenance set-aside | B28: 90 | C28: $/mo | D28: NOT LISTED. 12k miles of Maine driving = tires and brakes.
A29: Marketing | B29: 1000 | C29: $/mo | D29: Set to 0 if the company pays for it.
A30: WHAT YOU HAVE
A31: Checking | B31: 395.4 | C31: $
A32: High-yield savings | B32: 8398.9 | C32: $
A33: savings rate | B33: 0.04 | C33: APY | D33: CONFIRM. If it beats 3.687%, your certificate is the worse account.
A34: Shared certificate | B34: 6522.71 | C34: $
A35: certificate rate | B35: 0.03687 | C35: APY
A36: auto-transfer each roll | B36: 1250 | C36: $/3mo | D36: =$416.67/mo leaving your savings automatically.
A37: Credit card balance | B37: 390.15 | C37: $ | D37: Due the 7th.
A38: credit limit | B38: 5000 | C38: $ | D38: CONFIRM - drives your utilization %.
A39: Car loan balance | B39: 25092.02 | C39: $
A40: Tax set-aside % | B40: 0.3 | C40: of income | D40: If you're 1099, move 30% of every check to a separate account the day it lands. If W-2, set to 0.
A42: HOW THE DRAW GETS PAID BACK (you weren't sure — so make it a dial)
...

Sheet Budget
A1: MONTHLY BUDGET — living on the draw alone
A2: Right now this is the whole picture. Commissions come in on the next tab.
A4: Line | B4: Per month | C4: Per year | D4: Note
A5: Car payment | B5: =Inputs!$B$14 | C5: =B5*12
A6: Car insurance | B6: =Inputs!$B$17 | C6: =B6*12 | D6: Estimated - confirm.
A7: Gym | B7: =Inputs!$B$15*2 | C7: =B7*12
A8: Amazon Prime | B8: =Inputs!$B$16 | C8: =B8*12
A9: Phone | B9: =Inputs!$B$18 | C9: =B9*12 | D9: Estimated.
A10: Fuel | B10: =Inputs!$B$22 | C10: =B10*12 | D10: 1,000 mi at 19 mpg.
A11: Coffee | B11: =Inputs!$B$25 | C11: =B11*12
A12: Food | B12: =Inputs!$B$26 | C12: =B12*12 | D12: Estimated.
A13: Fun / personal | B13: =Inputs!$B$27 | C13: =B13*12 | D13: Estimated.
A14: Car maintenance | B14: =Inputs!$B$28 | C14: =B14*12 | D14: Estimated.
A15: LIVING COSTS | B15: =SUM(B5:B14) | C15: =B15*12
A16: Marketing | B16: =Inputs!$B$29 | C16: =B16*12 | D16: Zero this out if the company pays.
A17: TOTAL GOING OUT | B17: =B15+B16 | C17: =B17*12
A19: Draw income | B19: =Inputs!$B$7 | C19: =B19*12 | D19: $1,231.58 x 24 / 12.
A20: LEFT OVER EACH MONTH | B20: =B19-B17 | C20: =B20*12 | D20: If this is negative, the draw alone doesn't cover your life — every month without a closing digs a hole.
A22: HOW MUCH DO YOU HAVE TO CLOSE TO COVER YOUR COSTS?
A23: Comp structure | B23: Commission needed per month | C23: Loans/mo (at $300k) | D23: What it means
A24: Recoverable draw | B24: =IF(Inputs!$B$43>=1,"",MAX(0,(B17-B19)/(1-Inputs!$B$43))) | C24: =IF(B24="","n/a",B24/Inputs!$B$12/300000) | D24: At 100% recapture the answer is NONE OF THEM — every commission dollar goes to the advance, so your take-home stays pinned at the draw no matter how much you close, until the $13,547 clears. Lower the recapture % and this becomes a real number.
A25: Non-recoverable, greater of | B25: =B17 | C25: =IF(B25="","n/a",B25/Inputs!$B$12/300000) | D25: Commission REPLACES the draw, it doesn't add to it. So you need commission to cover your whole cost of living on its own — the draw stops helping the moment commission passes it.
A26: Non-recoverable, stacked | B26: =MAX(0,B17-B19) | C26: =IF(B26="","n/a",B26/Inputs!$B$12/300000) | D26: Draw is base pay and commission sits on top, so you only need to cover the gap. Much the easiest — and the rarest.
A27: Until you know which row you're on, plan against the GREATER-OF row — it's the most likely and the least forgiving of the two non-recoverable versions.

Sheet Deal Log
A1: DEAL LOG — log every closing here
A2: Fill in A-E. Column F is your commission and it calculates itself.
A4: Total funded volume: | C4: =SUMIFS(C7:C106,E7:E106,"Funded") | D4: Your commission: | F4: =SUMIFS(F7:F106,E7:E106,"Funded") | G4: =COUNTIFS(E7:E106,"Funded")&" loans"
A5: Row 7 is an EXAMPLE — delete it.
A6: Date | B6: Client | C6: Loan amount | D6: Company bps | E6: Status | F6: YOUR COMMISSION | G6: Month | H6: Notes
A7: 46287 | B7: EXAMPLE - delete me | C7: 300000 | D7: 0.0275 | E7: Funded | F7: =IF(A7="","",C7*Inputs!$B$12) | G7: =IF(A7="","",EOMONTH(A7,0))
F8: =IF(A8="","",C8*Inputs!$B$12) | G8: =IF(A8="","",EOMONTH(A8,0))
F9: =IF(A9="","",C9*Inputs!$B$12) | G9: =IF(A9="","",EOMONTH(A9,0))
F10: =IF(A10="","",C10*Inputs!$B$12) | G10: =IF(A10="","",EOMONTH(A10,0))
F11: =IF(A11="","",C11*Inputs!$B$12) | G11: =IF(A11="","",EOMONTH(A11,0))
F12: =IF(A12="","",C12*Inputs!$B$12) | G12: =IF(A12="","",EOMONTH(A12,0))
F13: =IF(A13="","",C13*Inputs!$B$12) | G13: =IF(A13="","",EOMONTH(A13,0))
F14: =IF(A14="","",C14*Inputs!$B$12) | G14: =IF(A14="","",EOMONTH(A14,0))
F15: =IF(A15="","",C15*Inputs!$B$12) | G15: =IF(A15="","",EOMONTH(A15,0))
F16: =IF(A16="","",C16*Inputs!$B$12) | G16: =IF(A16="","",EOMONTH(A16,0))
F17: =IF(A17="","",C17*Inputs!$B$12) | G17: =IF(A17="","",EOMONTH(A17,0))
F18: =IF(A18="","",C18*Inputs!$B$12) | G18: =IF(A18="","",EOMONTH(A18,0))
F19: =IF(A19="","",C19*Inputs!$B$12) | G19: =IF(A19="","",EOMONTH(A19,0))
... F106: =IF(A106="","",C106*Inputs!$B$12) | G106: =IF(A106="","",EOMONTH(A106,0))

Sheet Scenarios
A1: SCENARIOS — what happens when you start closing loans
A2: Same deals, three different comp structures. Until you know which one you're on, look at all three.
A4: Average loan size | B4: 300000 | C4: <- change this
A5: Advance balance owed now | B5: =IF(Inputs!$B$11="Yes",MAX(0,Inputs!$B$10-'Deal Log'!F4),0) | C5: =draws taken so far, less commission already earned. $0 if the draw isn't recoverable.
A6: Your monthly costs | B6: =Budget!B17
A8: Loans per month | B8: Loan volume | C8: Your commission | D8: TAKE-HOME Recoverable | E8: TAKE-HOME Non-rec (greater of) | F8: TAKE-HOME Non-rec (stacked) | G8: Left over (your structure) | H8: Months to clear the advance
A9: 0 | B9: =A9*$B$4 | C9: =B9*Inputs!$B$12 | D9: =Inputs!$B$7+C9*(1-Inputs!$B$43) | E9: =MAX(Inputs!$B$7,C9) | F9: =Inputs!$B$7+C9 | G9: =IF(Inputs!$B$11="Yes",D9,IF(Inputs!$B$44="Stacked",F9,E9))-$B$6 | H9: =IF(OR(Inputs!$B$11<>"Yes",C9*Inputs!$B$43<=0),"n/a",ROUNDUP($B$5/(C9*Inputs!$B$43),0))
A10: 1 | B10: =A10*$B$4 | C10: =B10*Inputs!$B$12 | D10: =Inputs!$B$7+C10*(1-Inputs!$B$43) | E10: =MAX(Inputs!$B$7,C10) | F10: =Inputs!$B$7+C10 | G10: =IF(Inputs!$B$11="Yes",D10,IF(Inputs!$B$44="Stacked",F10,E10))-$B$6 | H10: =IF(OR(Inputs!$B$11<>"Yes",C10*Inputs!$B$43<=0),"n/a",ROUNDUP($B$5/(C10*Inputs!$B$43),0))
A11: 2 | B11: =A11*$B$4 | C11: =B11*Inputs!$B$12 | D11: =Inputs!$B$7+C11*(1-Inputs!$B$43) | E11: =MAX(Inputs!$B$7,C11) | F11: =Inputs!$B$7+C11 | G11: =IF(Inputs!$B$11="Yes",D11,IF(Inputs!$B$44="Stacked",F11,E11))-$B$6 | H11: =IF(OR(Inputs!$B$11<>"Yes",C11*Inputs!$B$43<=0),"n/a",ROUNDUP($B$5/(C11*Inputs!$B$43),0))
A12: 3 | B12: =A12*$B$4 | C12: =B12*Inputs!$B$12 | D12: =Inputs!$B$7+C12*(1-Inputs!$B$43) | E12: =MAX(Inputs!$B$7,C12) | F12: =Inputs!$B$7+C12 | G12: =IF(Inputs!$B$11="Yes",D12,IF(Inputs!$B$44="Stacked",F12,E12))-$B$6 | H12: =IF(OR(Inputs!$B$11<>"Yes",C12*Inputs!$B$43<=0),"n/a",ROUNDUP($B$5/(C12*Inputs!$B$43),0))
A13: 4 | B13: =A13*$B$4 | C13: =B13*Inputs!$B$12 | D13: =Inputs!$B$7+C13*(1-Inputs!$B$43) | E13: =MAX(Inputs!$B$7,C13) | F13: =Inputs!$B$7+C13 | G13: =IF(Inputs!$B$11="Yes",D13,IF(Inputs!$B$44="Stacked",F13,E13))-$B$6 | H13: =IF(OR(Inputs!$B$11<>"Yes",C13*Inputs!$B$43<=0),"n/a",ROUNDUP($B$5/(C13*Inputs!$B$43),0))
A14: 5 | B14: =A14*$B$4 | C14: =B14*Inputs!$B$12 | D14: =Inputs!$B$7+C14*(1-Inputs!$B$43) | E14: =MAX(Inputs!$B$7,C14) | F14: =Inputs!$B$7+C14 | G14: =IF(Inputs!$B$11="Yes",D14,IF(Inputs!$B$44="Stacked",F14,E14))-$B$6 | H14: =IF(OR(Inputs!$B$11<>"Yes",C14*Inputs!$B$43<=0),"n/a",ROUNDUP($B$5/(C14*Inputs!$B$43),0))
A15: 6 | B15: =A15*$B$4 | C15: =B15*Inputs!$B$12 | D15: =Inputs!$B$7+C15*(1-Inputs!$B$43) | E15: =MAX(Inputs!$B$7,C15) | F15: =Inputs!$B$7+C15 | G15: =IF(Inputs!$B$11="Yes",D15,IF(Inputs!$B$44="Stacked",F15,E15))-$B$6 | H15: =IF(OR(Inputs!$B$11<>"Yes",C15*Inputs!$B$43<=0),"n/a",ROUNDUP($B$5/(C15*Inputs!$B$43),0))
A17: Read it like this:
A18: Column D (recoverable): the recapture dial on Inputs decides this. At 100%, every commission dollar goes to the advance and you take home exactly the draw no matter how much you close — until the balance hits zero.
A19: Column E (greater of): the draw is a floor, not a bonus. One $300k loan pays $2,250, which is LESS than your monthly draw — so a single closing in a month changes nothing. It takes about 1.1 loans a month before commission beats the draw at all.
A20: Column F (stacked): draw is base pay, commission on top. Best case. If your agreement reads this way, get it in writing.
A21: Column H: how many months of that pace to clear what you owe. 'n/a' means either the draw isn't recoverable or you're not closing anything.

Sheet Goals
A1: GOALS — what you're saving for
A2: Set the target and the date. The sheet tells you what it costs per month.
A4: Today | B4: 46275
A5: Goal | B5: Target $ | C5: By when | D5: Months left | E5: Have now | F5: Need per month | G5: Note
A6: Emergency fund | B6: =Budget!B17*6 | C6: 46631 | D6: =MAX(1,ROUND((C6-$B$4)/30.44,0)) | E6: =Inputs!$B$32 | F6: =MAX(0,B6-E6)/D6 | G6: 6 months of costs. Fund this FIRST — commission income is lumpy and if the draw is recoverable you have less cushion than you think.
A7: Ring + proposal | B7: 12000 | C7: 46997 | D7: =MAX(1,ROUND((C7-$B$4)/30.44,0)) | E7: 0 | F7: =MAX(0,B7-E7)/D7 | G7: Placeholder — put your real number in. Keep it in cash, not invested; never invest money you need inside 3 years.
A8: Roth IRA (this year) | B8: 7000 | C8: 46492 | D8: =MAX(1,ROUND((C8-$B$4)/30.44,0)) | E8: 0 | F8: =MAX(0,B8-E8)/D8 | G8: Verify the 2026 limit. You're 25 with $0 invested — $7,000/yr at 8% until 65 is roughly $1.8M. Waiting one year costs about $145,000.
A9: House down payment | B9: 32000 | C9: 47178 | D9: =MAX(1,ROUND((C9-$B$4)/30.44,0)) | E9: 0 | F9: =MAX(0,B9-E9)/D9 | G9: 8% of $400k (5% down + 3% costs). FHA at 3.5% down cuts this a lot.
A10: Travel | B10: 3000 | C10: 46631 | D10: =MAX(1,ROUND((C10-$B$4)/30.44,0)) | E10: 0 | F10: =MAX(0,B10-E10)/D10 | G10: Shares the special-savings account with the ring.
A11: TOTAL NEEDED PER MONTH | F11: =SUM(F6:F10)
A12: You have left over each month | F12: =Budget!B20
A13: GAP | F13: =F12-F11 | G13: If this is negative, these goals don't all fit on the draw alone. That's not a budgeting failure — it's the sheet telling you how many loans you need to close. Check 'Scenarios'.

Sheet Money Split
A1: MONEY SPLIT — a commission just landed. Where does it go?
A2: Type the commission amount in the blue box. Follow the list top to bottom.
A4: COMMISSION RECEIVED | B4: 2250 | C4: <- type it here | E4: A $300,000 loan at 75 bps.
A6: Step | B6: Amount | C6: Running left | E6: Why
A7: 1. Taxes — move it the same day | B7: =$B$4*Inputs!$B$40 | C7: =$B$4-B7 | E7: If you're 1099 nothing is withheld. This money was never yours. Separate account, same day, before you look at the balance.
A8: 2. Draw repayment (if recoverable) | B8: =IF(Inputs!$B$11="Yes",MIN(C7,MIN($B$4*Inputs!$B$43,Scenarios!$B$5)),0) | C8: =C7-B8 | E8: The owner may take this before you ever see it. Shown here so the deposit isn't a surprise.
A9: 3. Top checking up to $2,000 | B9: =MIN(C8,MAX(0,2000-Inputs!$B$31)) | C9: =C8-B9 | E9: You're at $395.40 with $865.84 due by 10/14. Fix this every single time before anything else.
A10: 4. Emergency fund until it's full | B10: =MIN(C9,MAX(0,Goals!B6-Goals!E6)) | C10: =C9-B10 | E10: 6 months of costs. Nothing below this line gets funded until this is done.
A11: 5. Roth IRA | B11: =C10*0.30 | C11: =C10-B11 | E11: You're 25 with $0 invested. This is the highest-value habit on the page.
A12: 6. Ring / special savings | B12: =C11*0.40 | C12: =C11-B12 | E12: Dated goal. Cash only.
A13: 7. House fund | B13: =C12*0.20 | C13: =C12-B13 | E13: Separate account so you can see both clocks.
A14: 8. Guilt-free spending | B14: =C13*1.00 | C14: =C13-B14 | E14: Non-negotiable. A budget with no fun in it gets abandoned in about six weeks.
A15: Steps 5-8 split whatever is left after the emergency fund is full: 30% Roth, 40% ring, 20% house, 10% fun. Change those percentages right in the formulas if your priorities shift.
